Workbook
Name \A: #REF!
Name \D: #REF!
Name \E: #REF!
Name \G: '[1]Company Related Premises'!#REF!
Name \H: '[1]Company Related Premises'!#REF!
Name \L: '[1]Company Related Premises'!#REF!
Name \M: '[1]Company Related Premises'!#REF!
Name \N: #REF!
Name \O: #REF!
Name \P: #REF!
Name \Q: #REF!
Name \R: #REF!
Name \S: #REF!
Name \T: #REF!
Name \U: #REF!
Name \V: #REF!
Name \W: #REF!
Name \X: #REF!
Name \xy: #REF!
Name \Y: #REF!
Name \Z: #REF!
Name __PR1: [2]Sheet!#REF!
Name __SR1: #REF!
Name __SR2: #REF!
Name _PR1: [2]Sheet!#REF!
Name _SR1: #REF!
Name _SR2: #REF!
Name aa: #REF!
Name aaa: #REF!
Name abcd: #REF!
Name All: #REF!
Name ANLAGE_III: [3]Anlagevermögen!$A$1:$Z$29
Name data84: '[4]Purchase Order'!$E$40
Name dflt3: '[4]Customize Your Purchase Order'!$F$24
Name dflt4: '[4]Customize Your Purchase Order'!$E$25
Name DRPAUSE: #REF!
Name DSCTEMP: [5]DSCTEMP!$A$1:$B$65536
Name FTBSch: [2]Sheet!#REF!
Name hh: [2]Sheet!#REF!
Name is: '[6]Company Related Premises'!#REF!
Name jngiüorajg: #REF!
Name ll: #REF!
Name new: #REF!
Name PeriodsInYear: #REF!
Name PrintArea: #REF!
Name qqqqqqqqqqqqqqqqqqqqq: #REF!
Name RANDO: #REF!
Name RANDU: #REF!
Name re: [7]Sheet!#REF!
Name Report: #REF!
Name Sale: #REF!
Name SalSch: #REF!
Name Seite1: #REF!
Name Seite2: #REF!
Name Seite3: #REF!
Name Spec: #REF!
Name SR: #REF!
Name SRC: #REF!
Name tes: [2]Sheet!#REF!
Name Test: [2]Sheet!#REF!

Sheet Company information
B2: COMPANY NAME (KHMER) | D2: វីអ៊ីស៊ិន (ខេមបូឌា) អ៊ិនដាសស្ទ្រី ឯ.ក | F2: AUDIT TIMELINE
B3: COMPANY NAME (ENGLISH) | D3: Viiition (Cambodia)
B4: VAT NUMBER | D4: L001-901905215 | F4: MOC NUMBER
B5: BUSINESS ACTIVITY | D5: កម្មន្តសាលសម្លៀកបំពាក់ (លើកលែងជាសម្លៀកបំពាក់ស្រាប់ឬកាត់) ( ) រោងចក្រកាត់ដេរសម្លៀកបំពាក់ | F5: MOC DATE OF ISSUE
B6: ADDRESS NAME | D6: ផ្ទះលេខ ​ ផ្លូវ ​ ភូមិស្រង់ ឃុំស្រង់ ស្រុកគងពិសី ខេត្តកំពង់ស្ពឺ | F6: PATENT ISSUE DATE | I6: PATENT AMOUNT | K6: ០ ៛
B7: REQUEST PERIOD | F7: VAT CERTIFICATE ISSUE DATE
B8: AUDITOR NAME | F8: REQUEST DATE
F9: AMOUNT OF REQUEST | H9: 0
B10: PHONE NUMBER | D10: 011777957
B11: BANK ACCOUNT NUMBER TO REFUND | D11: 38800502883099
B12: BANK NAME: | D12: ធនាគារ អេស៊ីលីដាACLEDA Bank Plc.
B13: PERSON TO CONTACT
B14: POSITION

Sheet Annex I-IM State Charge
A1: តារាងឧបសម្ព័ន្ធ I
A2: បញ្ជាក់អំពីអាករលើធាតុចូលដែលមិនអាចស្នើសុំជាឥណទាន
A3: ( ការនាំចូលជាបន្ទុករបស់រដ្ឋ )
A4: ក្រុមហ៊ុន៖ | B4: ='Company information'!D2 | G4: សវនករពន្ធដារ៖ | H4: ='Company information'!D8
A5: លេខ អតប៖ | B5: ='Company information'!D4 | H5: ='Company information'!E8
A6: ='Company information'!H8 | G6: ទឹកប្រាក់ស្នើសុំបង្វិលសងចំនួន៖ | H6: ='Company information'!H9
A7: ល.រ | B7: បរិយាយ | C7: ប្រតិវេទន៍គយនាំចូល/វិក្កយបត្រ | E7: បង្កាន់ដៃទទួលប្រាក់ | G7: ប្រាក់អាករ (រៀល) | H7: ផ្សេងៗ
C8: លេខ | D8: ចុះថ្ងៃទី ខែ ឆ្នាំ | E8: លេខ | F8: ថ្ងៃ ខែ ឆ្នាំ
A10: 1 | C10: I821 | D10: 43857 | G10: 5671447
A11: 2 | C11: I820 | D11: 43857 | G11: 3115425
A12: 3 | C12: I608 | D12: 43850 | G12: 10824695
A13: 4 | C13: I609 | D13: 43843 | G13: 5811817
A14: 5 | C14: I459 | D14: 43845 | G14: 7391034
A15: 6 | B15: COMPUTER | C15: I292 | D15: 44207 | G15: 216700
A16: 7 | B16: AWNING ADAPTER METAL PRODUCTS PAPER SLIPSHEET PLASTIC ACCESSORIE A LIGHT BULB | C16: I291 | D16: 44207 | G16: 31606500
A17: 8 | B17: BATTERY COPPER PRODUCTS LED COPPER WIRE LAMPE LIGHT BULB METAL PRODUCTS PLASTIC ACCESSORIE A PLASTIC TUBE PRINTED CIRUIT BOARD ASSEMBLY SCREW SOLAR PANEL WIRE | C17: I242 | D17: 44204 | G17: 15832100
A18: 9 | B18: METAL PRODUCTS WOOD PRODUCTS | C18: I235 | D18: 44204 | G18: 5990300
A19: 10 | C19: I236 | D19: 44204 | G19: 13990100
A20: 11 | C20: I237 | D20: 44204 | G20: 6094100
A21: 12 | C21: I688 | D21: 44215 | G21: 120512600
A22: 13 | C22: I1016 | D22: 44222 | G22: 5723300
A23: 14 | C23: I961 | D23: 44221 | G23: 31514400
A24: 15 | C24: I1010 | D24: 44222 | G24: 82195100
A25: 16 | C25: I1183 | D25: 44224 | G25: 649700
A26: 17 | C26: I468 | D26: 44209 | G26: 18227300
A27: 18 | C27: I544 | D27: 44211 | G27: 55579000
A28: 19 | C28: I466 | D28: 44209 | G28: 688200
A29: 20 | C29: I707 | D29: 44215 | G29: 45324500
A30: 21 | C30: I240 | D30: 44204 | G30: 65935300
A31: 22 | B31: Import Raw Material | C31: I15369 | D31: 44562 | G31: 73348100
A32: 23 | B32: Import Raw Material | C32: I15321 | D32: 44562 | G32: 113862800
A33: 24 | B33: Import Raw Material | C33: I15323 | D33: 44562 | G33: 72377500
A34: 25 | B34: PLASTIC INJECTTION PRODUCTS,PRINTED CIRCUIT BOARD ASSEMBLY ,LIGHT BULB ... | C34: I1157 | D34: 44952 | G34: 39785000
A35: 26 | B35: PAPER BOARD ,COLOR BOX | C35: I1168 | D35: 44952 | G35: 4580700
A36: 27 | B36: IRON SHEET FRAME,PRINTED CIRCUIT BOARD ASSEMBLY ... | C36: I1166 | D36: 44952 | G36: 8832200
A37: 28 | B37: PRINTED CIRCUIT BOARD ASSEMBLY ,PLASTIC SPRAYING POWER (9),IRON WIRE (10)... | C37: I1162 | D37: 44952 | G37: 15314800
A38: 29 | B38: MOLD (INJECTION),IRON TUBE FRAME ,STRECH FILM | C38: I792 | D38: 44945 | G38: 8562800
A39: 30 | B39: IRON SHEET FRAME | C39: I791 | D39: 44945 | G39: 6542700
A40: 31 | B40: PLASTIC TUBE ,SOLAR PANELS (7),PLASTIC (BLOWN, INJECTION )PRODUCTS... | C40: I772 | D40: 44944 | G40: 10671300
A41: 32 | B41: SCREW (11),PRINTED CIRCUIT BOARD ASSEMBLY ,PLASTIC SPRAYING POWER (9)... | C41: I716 | D41: 44944 | G41: 13793200
...

Sheet Annex II-IM Non-State Charge
A1: តារាងឧបសម្ព័ន្ធ II
A2: តារាងផ្ទៀងផ្ទាត់បញ្ជាក់អំពីអាករលើធាតុចូលដែលអាចស្នើសុំជាឥណទាន
A3: ( ការនាំចូល ឬ អាករគិតជំនួស(Reverse Charge))
A4: ក្រុមហ៊ុន៖ | B4: ='Company information'!D2 | G4: សវនករពន្ធដារ៖ | H4: ='Company information'!D8
A5: លេខ អតប៖ | B5: ='Company information'!D4 | H5: ='Company information'!E8
A6: ='Company information'!H8 | G6: ទឹកប្រាក់ស្នើសុំបង្វិលសងចំនួន៖ | H6: ='Company information'!H9
A7: ល.រ | B7: បរិយាយ | C7: ប្រតិវេទន៍គយនាំចូល/ វិក្កយបត្រ | E7: បង្កាន់ដៃទទួលប្រាក់ | G7: ប្រាក់អាករ (រៀល) | H7: លទ្ធផលផ្ទៀងផ្ទាត់ជាមួយទិន្នន័យពីអគ្គនាយកដ្ឋានគយ/ ឬ អាករគិតជំនួស(Reverse Charge) | I7: ទឹកប្រាក់អនុញ្ញាត
C8: លេខ | D8: ចុះថ្ងៃទី ខែ ឆ្នាំ | E8: លេខ | F8: ថ្ងៃ ខែ ឆ្នាំ
J9: ខ្វះ | K9: សម្គាល់
A10: I. ការនាំចូល
A11: 1 | C11: I2933 | D11: 43910 | G11: 86294 | I11: 0 | J11: =G11-I11
A12: 2 | B12: Stretch Film | C12: I3963 | D12: 44287 | G12: 4225100 | I12: 0 | J12: =G12-I12
A13: 3 | B13: COB Light board | C13: I5395 | D13: 44337 | G13: 229500 | I13: 0 | J13: =G13-I13
A14: 4 | B14: Lamp holder | C14: I5399 | D14: 44337 | G14: 495400 | I14: 0 | J14: =G14-I14
A15: 5 | B15: ELECTRODE SLICE | C15: I8833 | D15: 44743 | G15: 3300 | I15: 0 | J15: =G15-I15
A16: 6 | B16: Industrial glasses | C16: I8938. | D16: 44414 | G16: 44200 | I16: 0 | J16: =G16-I16
A17: 7 | B17: Industrial glover | C17: I8938 | D17: 44414 | G17: 16300 | I17: 0 | J17: =G17-I17
A18: 8 | B18: Iron stand | C18: I9185 | D18: 44420 | G18: 258400 | I18: 0 | J18: =G18-I18
A19: 9 | B19: Iron tube | C19: I9187 | D19: 44420 | G19: 3710600 | I19: 0 | J19: =G19-I19
A20: 10 | B20: IRON STAND | C20: I10359. | D20: 44446 | G20: 518400 | I20: 0 | J20: =G20-I20
A21: 11 | B21: Import Raw Material | C21: I10761 | D21: 44455 | G21: 65700 | I21: 0 | J21: =G21-I21
A22: 12 | C22: I9794 | D22: 44110 | G22: 1047700 | I22: 0 | J22: =G22-I22
A23: 13 | C23: I12103 | D23: 43810 | G23: 248568 | I23: 0 | J23: =G23-I23
A24: II. អាករលើតម្លៃបន្ថែមតាមវិធីគិតអាករជំនួស(Reverse Charge)
A25: 1 | B25: Online serivce | C25: 01-02-2024 | D25: 19108.4 | G25: 19108.4 | H25: អនុញ្ញាត (បានប្រកាស) | I25: =G25 | J25: =G25-I25
A26: 2 | B26: Online service | C26: 01-02-2024 | D26: 19042.9 | G26: 19042.9 | H26: អនុញ្ញាត (បានប្រកាស) | I26: =G26 | J26: =G26-I26
A27: 3 | B27: Software License | C27: 26-02-2024 | D27: 203450 | G27: 203450 | H27: អនុញ្ញាត (បានប្រកាស) | I27: =G27 | J27: =G27-I27
A28: 4 | B28: Online Service | C28: 01-03-2024 | D28: 18911.9 | G28: 18911.9 | H28: អនុញ្ញាត (បានប្រកាស) | I28: =G28 | J28: =G28-I28
A29: 5 | B29: Online Service | C29: 01-05-2024 | D29: 19155.2 | G29: 19155.2 | H29: អនុញ្ញាត (បានប្រកាស) | I29: =G29 | J29: =G29-I29
A30: 6 | B30: Online Service | C30: 01-06-2024 | D30: 19234.8 | G30: 19234.8 | H30: អនុញ្ញាត (បានប្រកាស) | I30: =G30 | J30: =G30-I30
A31: 7 | B31: Online Service | C31: 01-07-2024 | D31: 19225.4 | G31: 19225.4 | H31: អនុញ្ញាត (បានប្រកាស) | I31: =G31 | J31: =G31-I31
A32: 8 | B32: Online Services | C32: 01-08-2024 | D32: 18986.8 | G32: 18986.8 | H32: អនុញ្ញាត (បានប្រកាស) | I32: =G32 | J32: =G32-I32
A33: 9 | B33: Online Services | C33: 28-09-2024 | D33: 19005.5 | G33: 19005.5 | H33: អនុញ្ញាត (បានប្រកាស) | I33: =G33 | J33: =G33-I33
A34: 10 | B34: Online Services | C34: 01-09-2024 | D34: 19005.5 | G34: 19005.5 | H34: អនុញ្ញាត (បានប្រកាស) | I34: =G34 | J34: =G34-I34
A35: 11 | B35: Online Services | C35: 28-10-2024 | D35: 19014.8 | G35: 19014.8 | H35: អនុញ្ញាត (បានប្រកាស) | I35: =G35 | J35: =G35-I35
A36: 12 | B36: Online Service | C36: 28-11-2024 | D36: 18851 | G36: 18851 | H36: អនុញ្ញាត (បានប្រកាស) | I36: =G36 | J36: =G36-I36
A37: 13 | B37: Online Services | C37: 28-12-2024 | D37: 18837 | G37: 18837 | H37: អនុញ្ញាត (បានប្រកាស) | I37: =G37 | J37: =G37-I37
A38: សរុបអាករលើការនាំចូល ឬ អាករលើតម្លៃបន្ថែមតាមវិធីគិតអាករជំនួស(Reverse Charge) | G38: =SUM(G11:G37) | H38: សរុបទឺកប្រាក់អនុញ្ញាត | I38: =SUM(I11:I37) | J38: =SUM(J11:J37)
A40: សេចក្តីធានាអះអាងរបស់មន្ត្រីសវនករទទួលបន្ទុក៖ លទ្ធផលផ្ទៀងផ្ទាត់ឥណទានអាករ ចំពោះការនាំចូល ឬ/និង អាករលើតម្លៃបន្ថែមតាមវិធីគិតអាករជំនួស(Reverse Charge)ខាងលើពិតជាត្រឹមត្រូវតាមរបាយការណ៍លម្អិតដែលបានទាញទិន្នន័យពីអគ្គនាយកដ្ឋានគយ/ប្រព័ន្ធE-Filing ពិតប្រាកដមែន។
E43: រាជធានីភ្នំពេញ.ថ្ងៃទី ខែ ឆ្នាំ
...

Sheet AnnexIII-Local Pur
A1: តារាងឧបសម្ព័ន្ធ III
A2: តារាងផ្ទៀងផ្ទាត់បញ្ជាក់អំពីអាករលើធាតុចូលដែលអាចស្នើសុំជាឥណទាន
A3: (ការទិញក្នុងស្រុក)
A4: ក្រុមហ៊ុន៖ | B4: ='Company information'!D2 | I4: សវនករពន្ធដារ៖ | J4: ='Company information'!D8
A5: លេខ អតប៖ | B5: ='Company information'!D4 | J5: ='Company information'!E8 | O5: FOR REPORT | W5: សម្គាល់ផ្សេងៗ | Y5: បញ្ចូលទិន្នន័យ
A6: ='Company information'!H8 | I6: ទឹកប្រាក់ស្នើសុំបង្វិលសងចំនួន៖ | J6: ='Company information'!H9
A7: ល.រ | B7: បរិយាយ | C7: អ្នកផ្គត់ផ្គង់ | D7: លេខ អតប | E7: វិក្កយបត្រ | G7: ទឹកប្រាក់អាករ | J7: ស្ថានភាព | K7: ស្ថានភាពប្រព័ន្ធ | L7: ស្ថានភាពអ្នកប្រើប្រាស់ | M7: មតិអ្នកប្រើប្រាស់ | N7: ផ្សេង (សម្គាល់) | R7: PURCHASE | S7: SUPPLIER | T7: VAR INVOICE T/F | U7: VAR. DATE T/F | V7: VAR. SUPPLIER & PUCHASER | W7: តេស្តទឹកប្រាក់លម្អៀង | X7: សម្កាល់ | Y7: កាលបរិច្ឆេទ | Z7: លេខវិក្កយបត្រ ឬប្រតិវេទគយ | AA7: លេខលិខិតជូនដំណឹងឥណទាន | AB7: អ្នកទិញ | AE7: តម្លៃសរុបលើវិក្កយបត្រ | AF7: តម្លៃ​​មិន​រួមអតប និងមិនជាប់​អតប​ | AH7: អាករលើតម្លៃបន្ថែមអត្រា ០% | AI7: អាករលើតម្លៃបន្ថែម | AK7: អាករលើតម្លៃបន្ថែម(បន្ទុករដ្ឋ) | AL7: អតប កាត់ទុកដោយរតនាគារជាតិ | AM7: អាករបំភ្លឺសាធារណៈ | AN7: អាករពិសេសលើទំនិញមួយចំនួន | AO7: អាករពិសេសលើសេវាមួយចំនួន | AP7: អាករលើការស្នាក់នៅ | AQ7: អត្រាប្រាក់រំដោះពន្ធលើប្រាក់ចំណូល | AR7: កំណត់សម្គាល់ | AS7: បរិយាយ | AT7: ស្ថានភាពប្រកាសពន្ធ
E8: លេខ | F8: ថ្ងៃ ខែ ឆ្នាំ | G8: ជាដុល្លារអាមេរិក | H8: អត្រា | I8: ជារៀល | O8: បានប្រកាស | P8: នៅខ្វះ | Q8: ស្ថានភាពត្រួតពិនិត្យ | AB8: ប្រភេទ | AC8: លេខសម្គាល់ចុះបញ្ជីពន្ធដា | AD8: ឈ្មោះ | AF8: តម្លៃមិនរួមអតប | AG8: ការលក់មិនជាប់អតប | AI8: ការលក់ក្នុងស្រុក | AJ8: អតបលើការនាំចេញ
A10: 1 | C10: អ៊ីជីអេហ្វ ឡូជីស្ទីក ខូ អិលធីឌី | D10: L001-901501877 | E10: 2001007 | F10: 43861 | G10: 279450 | I10: 279450 | J10: =IF(L10<>"",L10,K10) | K10: =IF(AND(T10=TRUE, U10=TRUE, V10=TRUE), IF(W10<-0.05, "អនុញ្ញាត (អ្នកផ្គត់ផ្គង់ប្រកាសខ្វះ)", "បានប្រកាស (អនុញ្ញាត)"), IF(AND(T10=FALSE, U10=FALSE, V10=FALSE), "ព្យួរទុក (មិនមានទិន្នន័យ)", "ប្រកាសខុស (ព្យួរទុក)")) | L10: ប្រកាសខុស (ព្យួរទុក) | O10: =IF(W10<0,AI10,I10) | P10: =I10-O10 | R10: 2001007 | T10: =R10=S10 | U10: =AND(MONTH(F10)=MONTH(Y10), YEAR(F10)=YEAR(Y10)) | V10: =AND(AC10<>"", 'Company information'!D$4<>"", RIGHT(SUBSTITUTE(AC10,"-",""),9)=RIGHT(SUBSTITUTE('Company information'!D$4,"-",""),9)) | W10: =AI10-I10
A11: 2 | C11: អិនខេ ត្រេឌីង (ខេមបូឌា) ឯ.ក | D11: K009-901700707 | E11: NK00006 | F11: 43844 | G11: 406000 | I11: 406000 | J11: =IF(L11<>"",L11,K11) | K11: =IF(AND(T11=TRUE, U11=TRUE, V11=TRUE), IF(W11<-0.05, "អនុញ្ញាត (អ្នកផ្គត់ផ្គង់ប្រកាសខ្វះ)", "បានប្រកាស (អនុញ្ញាត)"), IF(AND(T11=FALSE, U11=FALSE, V11=FALSE), "ព្យួរទុក (មិនមានទិន្នន័យ)", "ប្រកាសខុស (ព្យួរទុក)")) | L11: បានប្រកាស (អនុញ្ញាត) | O11: =IF(W11<0,AI11,I11) | P11: =I11-O11 | R11: NK00006 | T11: =R11=S11 | U11: =AND(MONTH(F11)=MONTH(Y11), YEAR(F11)=YEAR(Y11)) | V11: =AND(AC11<>"", 'Company information'!D$4<>"", RIGHT(SUBSTITUTE(AC11,"-",""),9)=RIGHT(SUBSTITUTE('Company information'!D$4,"-",""),9)) | W11: =AI11-I11
A12: 3 | C12: ថេកអេស៊ីស៊ី ផេភើរ សឺវីស ខនសាល់ធេន ឯ.ក | D12: K004-901801112 | E12: 000013 | F12: 43840 | G12: 162800 | I12: 162800 | J12: =IF(L12<>"",L12,K12) | K12: =IF(AND(T12=TRUE, U12=TRUE, V12=TRUE), IF(W12<-0.05, "អនុញ្ញាត (អ្នកផ្គត់ផ្គង់ប្រកាសខ្វះ)", "បានប្រកាស (អនុញ្ញាត)"), IF(AND(T12=FALSE, U12=FALSE, V12=FALSE), "ព្យួរទុក (មិនមានទិន្នន័យ)", "ប្រកាសខុស (ព្យួរទុក)")) | L12: ព្យួរទុក (មិនមានឯកសារគាំទ្រ) | O12: =IF(W12<0,AI12,I12) | P12: =I12-O12 | R12: 000013 | T12: =R12=S12 | U12: =AND(MONTH(F12)=MONTH(Y12), YEAR(F12)=YEAR(Y12)) | V12: =AND(AC12<>"", 'Company information'!D$4<>"", RIGHT(SUBSTITUTE(AC12,"-",""),9)=RIGHT(SUBSTITUTE('Company information'!D$4,"-",""),9)) | W12: =AI12-I12
A13: 4 | C13: ប្យួរ៉ូ វេរីតាស (ខេមបូឌា) លីមីធីត | D13: L001-107024462 | E13: 59006679 | F13: 43861 | G13: 67073 | I13: 67073 | J13: =IF(L13<>"",L13,K13) | K13: =IF(AND(T13=TRUE, U13=TRUE, V13=TRUE), IF(W13<-0.05, "អនុញ្ញាត (អ្នកផ្គត់ផ្គង់ប្រកាសខ្វះ)", "បានប្រកាស (អនុញ្ញាត)"), IF(AND(T13=FALSE, U13=FALSE, V13=FALSE), "ព្យួរទុក (មិនមានទិន្នន័យ)", "ប្រកាសខុស (ព្យួរទុក)")) | L13: ព្យួរទុក (ខុសវិធានវិក្កយបត្រអាករ) | O13: =IF(W13<0,AI13,I13) | P13: =I13-O13 | R13: 59006679 | T13: =R13=S13 | U13: =AND(MONTH(F13)=MONTH(Y13), YEAR(F13)=YEAR(Y13)) | V13: =AND(AC13<>"", 'Company information'!D$4<>"", RIGHT(SUBSTITUTE(AC13,"-",""),9)=RIGHT(SUBSTITUTE('Company information'!D$4,"-",""),9)) | W13: =AI13-I13
A14: 5 | C14: ប្យួរ៉ូ វេរីតាស (ខេមបូឌា) លីមីធីត | D14: L001-107024462 | E14: 59006668 | F14: 43861 | G14: 102845 | I14: 102845 | J14: =IF(L14<>"",L14,K14) | K14: =IF(AND(T14=TRUE, U14=TRUE, V14=TRUE), IF(W14<-0.05, "អនុញ្ញាត (អ្នកផ្គត់ផ្គង់ប្រកាសខ្វះ)", "បានប្រកាស (អនុញ្ញាត)"), IF(AND(T14=FALSE, U14=FALSE, V14=FALSE), "ព្យួរទុក (មិនមានទិន្នន័យ)", "ប្រកាសខុស (ព្យួរទុក)")) | L14: អនុញ្ញាត (អ្នកផ្គត់ផ្គង់ប្រកាសខ្វះ) | O14: =IF(W14<0,AI14,I14) | P14: =I14-O14 | R14: 59006668 | T14: =R14=S14 | U14: =AND(MONTH(F14)=MONTH(Y14), YEAR(F14)=YEAR(Y14)) | V14: =AND(AC14<>"", 'Company information'!D$4<>"", RIGHT(SUBSTITUTE(AC14,"-",""),9)=RIGHT(SUBSTITUTE('Company information'!D$4,"-",""),9)) | W14: =AI14-I14
A15: 6 | C15: ប្យួរ៉ូ វេរីតាស (ខេមបូឌា) លីមីធីត | D15: L001-107024462 | E15: 59006650 | F15: 43860 | G15: 134145 | I15: 134145 | J15: =IF(L15<>"",L15,K15) | K15: =IF(AND(T15=TRUE, U15=TRUE, V15=TRUE), IF(W15<-0.05, "អនុញ្ញាត (អ្នកផ្គត់ផ្គង់ប្រកាសខ្វះ)", "បានប្រកាស (អនុញ្ញាត)"), IF(AND(T15=FALSE, U15=FALSE, V15=FALSE), "ព្យួរទុក (មិនមានទិន្នន័យ)", "ប្រកាសខុស (ព្យួរទុក)")) | O15: =IF(W15<0,AI15,I15) | P15: =I15-O15 | R15: 59006650 | T15: =R15=S15 | U15: =AND(MONTH(F15)=MONTH(Y15), YEAR(F15)=YEAR(Y15)) | V15: =AND(AC15<>"", 'Company information'!D$4<>"", RIGHT(SUBSTITUTE(AC15,"-",""),9)=RIGHT(SUBSTITUTE('Company information'!D$4,"-",""),9)) | W15: =AI15-I15
A16: 7 | C16: ប្យួរ៉ូ វេរីតាស (ខេមបូឌា) លីមីធីត | D16: L001-107024462 | E16: 59006649 | F16: 43860 | G16: 67073 | I16: 67073 | J16: =IF(L16<>"",L16,K16) | K16: =IF(AND(T16=TRUE, U16=TRUE, V16=TRUE), IF(W16<-0.05, "អនុញ្ញាត (អ្នកផ្គត់ផ្គង់ប្រកាសខ្វះ)", "បានប្រកាស (អនុញ្ញាត)"), IF(AND(T16=FALSE, U16=FALSE, V16=FALSE), "ព្យួរទុក (មិនមានទិន្នន័យ)", "ប្រកាសខុស (ព្យួរទុក)")) | O16: =IF(W16<0,AI16,I16) | P16: =I16-O16 | R16: 59006649 | T16: =R16=S16 | U16: =AND(MONTH(F16)=MONTH(Y16), YEAR(F16)=YEAR(Y16)) | V16: =AND(AC16<>"", 'Company information'!D$4<>"", RIGHT(SUBSTITUTE(AC16,"-",""),9)=RIGHT(SUBSTITUTE('Company information'!D$4,"-",""),9)) | W16: =AI16-I16
A17: 8 | C17: ប្យួរ៉ូ វេរីតាស (ខេមបូឌា) លីមីធីត | D17: L001-107024462 | E17: 59006619 | F17: 43850 | G17: 399590 | I17: 399590 | J17: =IF(L17<>"",L17,K17) | K17: =IF(AND(T17=TRUE, U17=TRUE, V17=TRUE), IF(W17<-0.05, "អនុញ្ញាត (អ្នកផ្គត់ផ្គង់ប្រកាសខ្វះ)", "បានប្រកាស (អនុញ្ញាត)"), IF(AND(T17=FALSE, U17=FALSE, V17=FALSE), "ព្យួរទុក (មិនមានទិន្នន័យ)", "ប្រកាសខុស (ព្យួរទុក)")) | O17: =IF(W17<0,AI17,I17) | P17: =I17-O17 | R17: 59006619 | T17: =R17=S17 | U17: =AND(MONTH(F17)=MONTH(Y17), YEAR(F17)=YEAR(Y17)) | V17: =AND(AC17<>"", 'Company information'!D$4<>"", RIGHT(SUBSTITUTE(AC17,"-",""),9)=RIGHT(SUBSTITUTE('Company information'!D$4,"-",""),9)) | W17: =AI17-I17
A18: 9 | C18: ប្យួរ៉ូ វេរីតាស (ខេមបូឌា) លីមីធីត | D18: L001-107024462 | E18: 59006612 | F18: 43848 | G18: 67073 | I18: 67073 | J18: =IF(L18<>"",L18,K18) | K18: =IF(AND(T18=TRUE, U18=TRUE, V18=TRUE), IF(W18<-0.05, "អនុញ្ញាត (អ្នកផ្គត់ផ្គង់ប្រកាសខ្វះ)", "បានប្រកាស (អនុញ្ញាត)"), IF(AND(T18=FALSE, U18=FALSE, V18=FALSE), "ព្យួរទុក (មិនមានទិន្នន័យ)", "ប្រកាសខុស (ព្យួរទុក)")) | O18: =IF(W18<0,AI18,I18) | P18: =I18-O18 | R18: 59006612 | T18: =R18=S18 | U18: =AND(MONTH(F18)=MONTH(Y18), YEAR(F18)=YEAR(Y18)) | V18: =AND(AC18<>"", 'Company information'!D$4<>"", RIGHT(SUBSTITUTE(AC18,"-",""),9)=RIGHT(SUBSTITUTE('Company information'!D$4,"-",""),9)) | W18: =AI18-I18
A19: 10 | C19: ប្យួរ៉ូ វេរីតាស (ខេមបូឌា) លីមីធីត | D19: L001-107024462 | E19: 59006582 | F19: 43847 | G19: 134145 | I19: 134145 | J19: =IF(L19<>"",L19,K19) | K19: =IF(AND(T19=TRUE, U19=TRUE, V19=TRUE), IF(W19<-0.05, "អនុញ្ញាត (អ្នកផ្គត់ផ្គង់ប្រកាសខ្វះ)", "បានប្រកាស (អនុញ្ញាត)"), IF(AND(T19=FALSE, U19=FALSE, V19=FALSE), "ព្យួរទុក (មិនមានទិន្នន័យ)", "ប្រកាសខុស (ព្យួរទុក)")) | O19: =IF(W19<0,AI19,I19) | P19: =I19-O19 | R19: 59006582 | T19: =R19=S19 | U19: =AND(MONTH(F19)=MONTH(Y19), YEAR(F19)=YEAR(Y19)) | V19: =AND(AC19<>"", 'Company information'!D$4<>"", RIGHT(SUBSTITUTE(AC19,"-",""),9)=RIGHT(SUBSTITUTE('Company information'!D$4,"-",""),9)) | W19: =AI19-I19
A20: 11 | C20: ប្យួរ៉ូ វេរីតាស (ខេមបូឌា) លីមីធីត | D20: L001-107024462 | E20: 59006581 | F20: 43847 | G20: 134145 | I20: 134145 | J20: =IF(L20<>"",L20,K20) | K20: =IF(AND(T20=TRUE, U20=TRUE, V20=TRUE), IF(W20<-0.05, "អនុញ្ញាត (អ្នកផ្គត់ផ្គង់ប្រកាសខ្វះ)", "បានប្រកាស (អនុញ្ញាត)"), IF(AND(T20=FALSE, U20=FALSE, V20=FALSE), "ព្យួរទុក (មិនមានទិន្នន័យ)", "ប្រកាសខុស (ព្យួរទុក)")) | O20: =IF(W20<0,AI20,I20) | P20: =I20-O20 | R20: 59006581 | T20: =R20=S20 | U20: =AND(MONTH(F20)=MONTH(Y20), YEAR(F20)=YEAR(Y20)) | V20: =AND(AC20<>"", 'Company information'!D$4<>"", RIGHT(SUBSTITUTE(AC20,"-",""),9)=RIGHT(SUBSTITUTE('Company information'!D$4,"-",""),9)) | W20: =AI20-I20
A21: 12 | C21: ប្យួរ៉ូ វេរីតាស (ខេមបូឌា) លីមីធីត | D21: L001-107024462 | E21: 59006580 | F21: 43847 | G21: 67073 | I21: 67073 | J21: =IF(L21<>"",L21,K21) | K21: =IF(AND(T21=TRUE, U21=TRUE, V21=TRUE), IF(W21<-0.05, "អនុញ្ញាត (អ្នកផ្គត់ផ្គង់ប្រកាសខ្វះ)", "បានប្រកាស (អនុញ្ញាត)"), IF(AND(T21=FALSE, U21=FALSE, V21=FALSE), "ព្យួរទុក (មិនមានទិន្នន័យ)", "ប្រកាសខុស (ព្យួរទុក)")) | O21: =IF(W21<0,AI21,I21) | P21: =I21-O21 | R21: 59006580 | T21: =R21=S21 | U21: =AND(MONTH(F21)=MONTH(Y21), YEAR(F21)=YEAR(Y21)) | V21: =AND(AC21<>"", 'Company information'!D$4<>"", RIGHT(SUBSTITUTE(AC21,"-",""),9)=RIGHT(SUBSTITUTE('Company information'!D$4,"-",""),9)) | W21: =AI21-I21
A22: 13 | C22: ប្យួរ៉ូ វេរីតាស (ខេមបូឌា) លីមីធីត | D22: L001-107024462 | E22: 59006451 | F22: 43846 | G22: 67073 | I22: 67073 | J22: =IF(L22<>"",L22,K22) | K22: =IF(AND(T22=TRUE, U22=TRUE, V22=TRUE), IF(W22<-0.05, "អនុញ្ញាត (អ្នកផ្គត់ផ្គង់ប្រកាសខ្វះ)", "បានប្រកាស (អនុញ្ញាត)"), IF(AND(T22=FALSE, U22=FALSE, V22=FALSE), "ព្យួរទុក (មិនមានទិន្នន័យ)", "ប្រកាសខុស (ព្យួរទុក)")) | O22: =IF(W22<0,AI22,I22) | P22: =I22-O22 | R22: 59006451 | T22: =R22=S22 | U22: =AND(MONTH(F22)=MONTH(Y22), YEAR(F22)=YEAR(Y22)) | V22: =AND(AC22<>"", 'Company information'!D$4<>"", RIGHT(SUBSTITUTE(AC22,"-",""),9)=RIGHT(SUBSTITUTE('Company information'!D$4,"-",""),9)) | W22: =AI22-I22
A23: 14 | C23: ប្យួរ៉ូ វេរីតាស (ខេមបូឌា) លីមីធីត | D23: L001-107024462 | E23: 59006450 | F23: 43843 | G23: 229673 | I23: 229673 | J23: =IF(L23<>"",L23,K23) | K23: =IF(AND(T23=TRUE, U23=TRUE, V23=TRUE), IF(W23<-0.05, "អនុញ្ញាត (អ្នកផ្គត់ផ្គង់ប្រកាសខ្វះ)", "បានប្រកាស (អនុញ្ញាត)"), IF(AND(T23=FALSE, U23=FALSE, V23=FALSE), "ព្យួរទុក (មិនមានទិន្នន័យ)", "ប្រកាសខុស (ព្យួរទុក)")) | O23: =IF(W23<0,AI23,I23) | P23: =I23-O23 | R23: 59006450 | T23: =R23=S23 | U23: =AND(MONTH(F23)=MONTH(Y23), YEAR(F23)=YEAR(Y23)) | V23: =AND(AC23<>"", 'Company information'!D$4<>"", RIGHT(SUBSTITUTE(AC23,"-",""),9)=RIGHT(SUBSTITUTE('Company information'!D$4,"-",""),9)) | W23: =AI23-I23
A24: 15 | C24: ប្យួរ៉ូ វេរីតាស (ខេមបូឌា) លីមីធីត | D24: L001-107024462 | E24: 59006449 | F24: 43843 | G24: 229673 | I24: 229673 | J24: =IF(L24<>"",L24,K24) | K24: =IF(AND(T24=TRUE, U24=TRUE, V24=TRUE), IF(W24<-0.05, "អនុញ្ញាត (អ្នកផ្គត់ផ្គង់ប្រកាសខ្វះ)", "បានប្រកាស (អនុញ្ញាត)"), IF(AND(T24=FALSE, U24=FALSE, V24=FALSE), "ព្យួរទុក (មិនមានទិន្នន័យ)", "ប្រកាសខុស (ព្យួរទុក)")) | O24: =IF(W24<0,AI24,I24) | P24: =I24-O24 | R24: 59006449 | T24: =R24=S24 | U24: =AND(MONTH(F24)=MONTH(Y24), YEAR(F24)=YEAR(Y24)) | V24: =AND(AC24<>"", 'Company information'!D$4<>"", RIGHT(SUBSTITUTE(AC24,"-",""),9)=RIGHT(SUBSTITUTE('Company information'!D$4,"-",""),9)) | W24: =AI24-I24
A25: 16 | C25: ប្យួរ៉ូ វេរីតាស (ខេមបូឌា) លីមីធីត | D25: L001-107024462 | E25: 59006446 | F25: 44105 | G25: 67073 | I25: 67073 | J25: =IF(L25<>"",L25,K25) | K25: =IF(AND(T25=TRUE, U25=TRUE, V25=TRUE), IF(W25<-0.05, "អនុញ្ញាត (អ្នកផ្គត់ផ្គង់ប្រកាសខ្វះ)", "បានប្រកាស (អនុញ្ញាត)"), IF(AND(T25=FALSE, U25=FALSE, V25=FALSE), "ព្យួរទុក (មិនមានទិន្នន័យ)", "ប្រកាសខុស (ព្យួរទុក)")) | O25: =IF(W25<0,AI25,I25) | P25: =I25-O25 | R25: 59006446 | T25: =R25=S25 | U25: =AND(MONTH(F25)=MONTH(Y25), YEAR(F25)=YEAR(Y25)) | V25: =AND(AC25<>"", 'Company information'!D$4<>"", RIGHT(SUBSTITUTE(AC25,"-",""),9)=RIGHT(SUBSTITUTE('Company information'!D$4,"-",""),9)) | W25: =AI25-I25
A26: 17 | C26: ប្យួរ៉ូ វេរីតាស (ខេមបូឌា) លីមីធីត | D26: L001-107024462 | E26: 59006444 | F26: 44105 | G26: 256095 | I26: 256095 | J26: =IF(L26<>"",L26,K26) | K26: =IF(AND(T26=TRUE, U26=TRUE, V26=TRUE), IF(W26<-0.05, "អនុញ្ញាត (អ្នកផ្គត់ផ្គង់ប្រកាសខ្វះ)", "បានប្រកាស (អនុញ្ញាត)"), IF(AND(T26=FALSE, U26=FALSE, V26=FALSE), "ព្យួរទុក (មិនមានទិន្នន័យ)", "ប្រកាសខុស (ព្យួរទុក)")) | O26: =IF(W26<0,AI26,I26) | P26: =I26-O26 | R26: 59006444 | T26: =R26=S26 | U26: =AND(MONTH(F26)=MONTH(Y26), YEAR(F26)=YEAR(Y26)) | V26: =AND(AC26<>"", 'Company information'!D$4<>"", RIGHT(SUBSTITUTE(AC26,"-",""),9)=RIGHT(SUBSTITUTE('Company information'!D$4,"-",""),9)) | W26: =AI26-I26
... A133: 124 | C133: កំពង់ផែស្វយ័តភ្នំពេញ "ក.ស.ភ" | D133: L001-100044999 | E133: INV2020259406 | F133: 44197 | G133: 28890 | I133: 28890 | J133: =IF(L133<>"",L133,K133) | K133: =IF(AND(T133=TRUE, U133=TRUE, V133=TRUE), IF(W133<-0.05, "អនុញ្ញាត (អ្នកផ្គត់ផ្គង់ប្រកាសខ្វះ)", "បានប្រកាស (អនុញ្ញាត)"), IF(AND(T133=FALSE, U133=FALSE, V133=FALSE), "ព្យួរទុក (មិនមានទិន្នន័យ)", "ប្រកាសខុស (ព្យួរទុក)")) | O133: =IF(W133<0,AI133,I133) | P133: =I133-O133 | R133: INV2020259406 | T133: =R133=S133 | U133: =AND(MONTH(F133)=MONTH(Y133), YEAR(F133)=YEAR(Y133)) | V133: =AND(AC133<>"", 'Company information'!D$4<>"", RIGHT(SUBSTITUTE(AC133,"-",""),9)=RIGHT(SUBSTITUTE('Company information'!D$4,"-",""),9)) | W133: =AI133-I133
A134: 125 | C134: អូរៀនថល ឡូជីស្ទីក & ឌីស្ទ្រីប៊្យូសិន (ខេមបូឌា) | D134: L001-103007369 | F134: 44211 | G134: 6038159 | I134: 6038159 | J134: =IF(L134<>"",L134,K134) | K134: =IF(AND(T134=TRUE, U134=TRUE, V134=TRUE), IF(W134<-0.05, "អនុញ្ញាត (អ្នកផ្គត់ផ្គង់ប្រកាសខ្វះ)", "បានប្រកាស (អនុញ្ញាត)"), IF(AND(T134=FALSE, U134=FALSE, V134=FALSE), "ព្យួរទុក (មិនមានទិន្នន័យ)", "ប្រកាសខុស (ព្យួរទុក)")) | O134: =IF(W134<0,AI134,I134) | P134: =I134-O134 | T134: =R134=S134 | U134: =AND(MONTH(F134)=MONTH(Y134), YEAR(F134)=YEAR(Y134)) | V134: =AND(AC134<>"", 'Company information'!D$4<>"", RIGHT(SUBSTITUTE(AC134,"-",""),9)=RIGHT(SUBSTITUTE('Company information'!D$4,"-",""),9)) | W134: =AI134-I134
A135: 126 | C135: មើស្គ (ខេមបូឌា) | D135: L001-100045200 | E135: 5995868698 | F135: 44211 | G135: 311676 | I135: 311676 | J135: =IF(L135<>"",L135,K135) | K135: =IF(AND(T135=TRUE, U135=TRUE, V135=TRUE), IF(W135<-0.05, "អនុញ្ញាត (អ្នកផ្គត់ផ្គង់ប្រកាសខ្វះ)", "បានប្រកាស (អនុញ្ញាត)"), IF(AND(T135=FALSE, U135=FALSE, V135=FALSE), "ព្យួរទុក (មិនមានទិន្នន័យ)", "ប្រកាសខុស (ព្យួរទុក)")) | O135: =IF(W135<0,AI135,I135) | P135: =I135-O135 | R135: 5995868698 | T135: =R135=S135 | U135: =AND(MONTH(F135)=MONTH(Y135), YEAR(F135)=YEAR(Y135)) | V135: =AND(AC135<>"", 'Company information'!D$4<>"", RIGHT(SUBSTITUTE(AC135,"-",""),9)=RIGHT(SUBSTITUTE('Company information'!D$4,"-",""),9)) | W135: =AI135-I135
A136: 127 | C136: ហុង ឡេង ហួរ | D136: L001-100068901 | E136: DPS19152500 | F136: 44197 | G136: 7342 | I136: 7342 | J136: =IF(L136<>"",L136,K136) | K136: =IF(AND(T136=TRUE, U136=TRUE, V136=TRUE), IF(W136<-0.05, "អនុញ្ញាត (អ្នកផ្គត់ផ្គង់ប្រកាសខ្វះ)", "បានប្រកាស (អនុញ្ញាត)"), IF(AND(T136=FALSE, U136=FALSE, V136=FALSE), "ព្យួរទុក (មិនមានទិន្នន័យ)", "ប្រកាសខុស (ព្យួរទុក)")) | O136: =IF(W136<0,AI136,I136) | P136: =I136-O136 | R136: DPS19152500 | T136: =R136=S136 | U136: =AND(MONTH(F136)=MONTH(Y136), YEAR(F136)=YEAR(Y136)) | V136: =AND(AC136<>"", 'Company information'!D$4<>"", RIGHT(SUBSTITUTE(AC136,"-",""),9)=RIGHT(SUBSTITUTE('Company information'!D$4,"-",""),9)) | W136: =AI136-I136
A137: 128 | C137: ហុង ឡេង ហួរ | D137: L001-100068901 | E137: DPS19152476 | F137: 44197 | G137: 7342 | I137: 7342 | J137: =IF(L137<>"",L137,K137) | K137: =IF(AND(T137=TRUE, U137=TRUE, V137=TRUE), IF(W137<-0.05, "អនុញ្ញាត (អ្នកផ្គត់ផ្គង់ប្រកាសខ្វះ)", "បានប្រកាស (អនុញ្ញាត)"), IF(AND(T137=FALSE, U137=FALSE, V137=FALSE), "ព្យួរទុក (មិនមានទិន្នន័យ)", "ប្រកាសខុស (ព្យួរទុក)")) | O137: =IF(W137<0,AI137,I137) | P137: =I137-O137 | R137: DPS19152476 | T137: =R137=S137 | U137: =AND(MONTH(F137)=MONTH(Y137), YEAR(F137)=YEAR(Y137)) | V137: =AND(AC137<>"", 'Company information'!D$4<>"", RIGHT(SUBSTITUTE(AC137,"-",""),9)=RIGHT(SUBSTITUTE('Company information'!D$4,"-",""),9)) | W137: =AI137-I137
A138: 129 | C138: ហុង ឡេង ហួរ | D138: L001-100068901 | E138: DPS19152454 | F138: 44197 | G138: 7345 | I138: 7345 | J138: =IF(L138<>"",L138,K138) | K138: =IF(AND(T138=TRUE, U138=TRUE, V138=TRUE), IF(W138<-0.05, "អនុញ្ញាត (អ្នកផ្គត់ផ្គង់ប្រកាសខ្វះ)", "បានប្រកាស (អនុញ្ញាត)"), IF(AND(T138=FALSE, U138=FALSE, V138=FALSE), "ព្យួរទុក (មិនមានទិន្នន័យ)", "ប្រកាសខុស (ព្យួរទុក)")) | O138: =IF(W138<0,AI138,I138) | P138: =I138-O138 | R138: DPS19152454 | T138: =R138=S138 | U138: =AND(MONTH(F138)=MONTH(Y138), YEAR(F138)=YEAR(Y138)) | V138: =AND(AC138<>"", 'Company information'!D$4<>"", RIGHT(SUBSTITUTE(AC138,"-",""),9)=RIGHT(SUBSTITUTE('Company information'!D$4,"-",""),9)) | W138: =AI138-I138
A139: 130 | C139: ហុង ឡេង ហួរ | D139: L001-100068901 | E139: DPS19152455 | F139: 44197 | G139: 7345 | I139: 7345 | J139: =IF(L139<>"",L139,K139) | K139: =IF(AND(T139=TRUE, U139=TRUE, V139=TRUE), IF(W139<-0.05, "អនុញ្ញាត (អ្នកផ្គត់ផ្គង់ប្រកាសខ្វះ)", "បានប្រកាស (អនុញ្ញាត)"), IF(AND(T139=FALSE, U139=FALSE, V139=FALSE), "ព្យួរទុក (មិនមានទិន្នន័យ)", "ប្រកាសខុស (ព្យួរទុក)")) | O139: =IF(W139<0,AI139,I139) | P139: =I139-O139 | R139: DPS19152455 | T139: =R139=S139 | U139: =AND(MONTH(F139)=MONTH(Y139), YEAR(F139)=YEAR(Y139)) | V139: =AND(AC139<>"", 'Company information'!D$4<>"", RIGHT(SUBSTITUTE(AC139,"-",""),9)=RIGHT(SUBSTITUTE('Company information'!D$4,"-",""),9)) | W139: =AI139-I139
A140: 131 | C140: ហុង ឡេង ហួរ | D140: L001-100068901 | E140: DPS19153187 | F140: 44197 | G140: 7324 | I140: 7324 | J140: =IF(L140<>"",L140,K140) | K140: =IF(AND(T140=TRUE, U140=TRUE, V140=TRUE), IF(W140<-0.05, "អនុញ្ញាត (អ្នកផ្គត់ផ្គង់ប្រកាសខ្វះ)", "បានប្រកាស (អនុញ្ញាត)"), IF(AND(T140=FALSE, U140=FALSE, V140=FALSE), "ព្យួរទុក (មិនមានទិន្នន័យ)", "ប្រកាសខុស (ព្យួរទុក)")) | O140: =IF(W140<0,AI140,I140) | P140: =I140-O140 | R140: DPS19153187 | T140: =R140=S140 | U140: =AND(MONTH(F140)=MONTH(Y140), YEAR(F140)=YEAR(Y140)) | V140: =AND(AC140<>"", 'Company information'!D$4<>"", RIGHT(SUBSTITUTE(AC140,"-",""),9)=RIGHT(SUBSTITUTE('Company information'!D$4,"-",""),9)) | W140: =AI140-I140
A141: 132 | C141: ហុង ឡេង ហួរ | D141: L001-100068901 | E141: DPS19 | F141: 44197 | G141: 7342 | I141: 7342 | J141: =IF(L141<>"",L141,K141) | K141: =IF(AND(T141=TRUE, U141=TRUE, V141=TRUE), IF(W141<-0.05, "អនុញ្ញាត (អ្នកផ្គត់ផ្គង់ប្រកាសខ្វះ)", "បានប្រកាស (អនុញ្ញាត)"), IF(AND(T141=FALSE, U141=FALSE, V141=FALSE), "ព្យួរទុក (មិនមានទិន្នន័យ)", "ប្រកាសខុស (ព្យួរទុក)")) | O141: =IF(W141<0,AI141,I141) | P141: =I141-O141 | R141: DPS19 | T141: =R141=S141 | U141: =AND(MONTH(F141)=MONTH(Y141), YEAR(F141)=YEAR(Y141)) | V141: =AND(AC141<>"", 'Company information'!D$4<>"", RIGHT(SUBSTITUTE(AC141,"-",""),9)=RIGHT(SUBSTITUTE('Company information'!D$4,"-",""),9)) | W141: =AI141-I141
A142: 133 | C142: ហេលមេន វើលវ៉ាយដ៍ ឡូជីស្ទីក (ខេមបូឌា) អិលអិលស៊ី | D142: L001-106002481 | E142: Thwl21000174 | F142: 44197 | G142: 36955 | I142: 36955 | J142: =IF(L142<>"",L142,K142) | K142: =IF(AND(T142=TRUE, U142=TRUE, V142=TRUE), IF(W142<-0.05, "អនុញ្ញាត (អ្នកផ្គត់ផ្គង់ប្រកាសខ្វះ)", "បានប្រកាស (អនុញ្ញាត)"), IF(AND(T142=FALSE, U142=FALSE, V142=FALSE), "ព្យួរទុក (មិនមានទិន្នន័យ)", "ប្រកាសខុស (ព្យួរទុក)")) | O142: =IF(W142<0,AI142,I142) | P142: =I142-O142 | R142: Thwl21000174 | T142: =R142=S142 | U142: =AND(MONTH(F142)=MONTH(Y142), YEAR(F142)=YEAR(Y142)) | V142: =AND(AC142<>"", 'Company information'!D$4<>"", RIGHT(SUBSTITUTE(AC142,"-",""),9)=RIGHT(SUBSTITUTE('Company information'!D$4,"-",""),9)) | W142: =AI142-I142
A143: 134 | C143: ហេលមេន វើលវ៉ាយដ៍ ឡូជីស្ទីក (ខេមបូឌា) អិលអិលស៊ី | D143: L001-106002481 | E143: Thl2100168 | F143: 44197 | G143: 36955 | I143: 36955 | J143: =IF(L143<>"",L143,K143) | K143: =IF(AND(T143=TRUE, U143=TRUE, V143=TRUE), IF(W143<-0.05, "អនុញ្ញាត (អ្នកផ្គត់ផ្គង់ប្រកាសខ្វះ)", "បានប្រកាស (អនុញ្ញាត)"), IF(AND(T143=FALSE, U143=FALSE, V143=FALSE), "ព្យួរទុក (មិនមានទិន្នន័យ)", "ប្រកាសខុស (ព្យួរទុក)")) | O143: =IF(W143<0,AI143,I143) | P143: =I143-O143 | R143: Thl2100168 | T143: =R143=S143 | U143: =AND(MONTH(F143)=MONTH(Y143), YEAR(F143)=YEAR(Y143)) | V143: =AND(AC143<>"", 'Company information'!D$4<>"", RIGHT(SUBSTITUTE(AC143,"-",""),9)=RIGHT(SUBSTITUTE('Company information'!D$4,"-",""),9)) | W143: =AI143-I143
A144: 135 | C144: ហេលមេន វើលវ៉ាយដ៍ ឡូជីស្ទីក (ខេមបូឌា) អិលអិលស៊ី | D144: L001-106002481 | E144: Thl21000173 | F144: 44197 | G144: 36955 | I144: 36955 | J144: =IF(L144<>"",L144,K144) | K144: =IF(AND(T144=TRUE, U144=TRUE, V144=TRUE), IF(W144<-0.05, "អនុញ្ញាត (អ្នកផ្គត់ផ្គង់ប្រកាសខ្វះ)", "បានប្រកាស (អនុញ្ញាត)"), IF(AND(T144=FALSE, U144=FALSE, V144=FALSE), "ព្យួរទុក (មិនមានទិន្នន័យ)", "ប្រកាសខុស (ព្យួរទុក)")) | O144: =IF(W144<0,AI144,I144) | P144: =I144-O144 | R144: Thl21000173 | T144: =R144=S144 | U144: =AND(MONTH(F144)=MONTH(Y144), YEAR(F144)=YEAR(Y144)) | V144: =AND(AC144<>"", 'Company information'!D$4<>"", RIGHT(SUBSTITUTE(AC144,"-",""),9)=RIGHT(SUBSTITUTE('Company information'!D$4,"-",""),9)) | W144: =AI144-I144
A145: 136 | C145: ហ្គោមី រីសាយឃល110 | D145: K010-901503890 | E145: GRIN031 | F145: 44225 | G145: 16260 | I145: 16260 | J145: =IF(L145<>"",L145,K145) | K145: =IF(AND(T145=TRUE, U145=TRUE, V145=TRUE), IF(W145<-0.05, "អនុញ្ញាត (អ្នកផ្គត់ផ្គង់ប្រកាសខ្វះ)", "បានប្រកាស (អនុញ្ញាត)"), IF(AND(T145=FALSE, U145=FALSE, V145=FALSE), "ព្យួរទុក (មិនមានទិន្នន័យ)", "ប្រកាសខុស (ព្យួរទុក)")) | O145: =IF(W145<0,AI145,I145) | P145: =I145-O145 | R145: GRIN031 | T145: =R145=S145 | U145: =AND(MONTH(F145)=MONTH(Y145), YEAR(F145)=YEAR(Y145)) | V145: =AND(AC145<>"", 'Company information'!D$4<>"", RIGHT(SUBSTITUTE(AC145,"-",""),9)=RIGHT(SUBSTITUTE('Company information'!D$4,"-",""),9)) | W145: =AI145-I145
A146: 137 | C146: អ៊ិចស្ពែឌីធ័រ ខេមបូឌា អិលធីឌី | D146: L001-100045898 | E146: TI0192435 | F146: 44222 | G146: 123485 | I146: 123485 | J146: =IF(L146<>"",L146,K146) | K146: =IF(AND(T146=TRUE, U146=TRUE, V146=TRUE), IF(W146<-0.05, "អនុញ្ញាត (អ្នកផ្គត់ផ្គង់ប្រកាសខ្វះ)", "បានប្រកាស (អនុញ្ញាត)"), IF(AND(T146=FALSE, U146=FALSE, V146=FALSE), "ព្យួរទុក (មិនមានទិន្នន័យ)", "ប្រកាសខុស (ព្យួរទុក)")) | O146: =IF(W146<0,AI146,I146) | P146: =I146-O146 | R146: TI0192435 | T146: =R146=S146 | U146: =AND(MONTH(F146)=MONTH(Y146), YEAR(F146)=YEAR(Y146)) | V146: =AND(AC146<>"", 'Company information'!D$4<>"", RIGHT(SUBSTITUTE(AC146,"-",""),9)=RIGHT(SUBSTITUTE('Company information'!D$4,"-",""),9)) | W146: =AI146-I146
... A259: 250 | C259: 56ប៊ី-លីង សឹបផ្លាយ ឆេន មេនេចម៉ិន ឯ.ក | D259: K004-902004795 | E259: IN202101-0019 | F259: 44225 | G259: 691050 | I259: 691050 | J259: =IF(L259<>"",L259,K259) | K259: =IF(AND(T259=TRUE, U259=TRUE, V259=TRUE), IF(W259<-0.05, "អនុញ្ញាត (អ្នកផ្គត់ផ្គង់ប្រកាសខ្វះ)", "បានប្រកាស (អនុញ្ញាត)"), IF(AND(T259=FALSE, U259=FALSE, V259=FALSE), "ព្យួរទុក (មិនមានទិន្នន័យ)", "ប្រកាសខុស (ព្យួរទុក)")) | O259: =IF(W259<0,AI259,I259) | P259: =I259-O259 | R259: IN202101-0019 | T259: =R259=S259 | U259: =AND(MONTH(F259)=MONTH(Y259), YEAR(F259)=YEAR(Y259)) | V259: =AND(AC259<>"", 'Company information'!D$4<>"", RIGHT(SUBSTITUTE(AC259,"-",""),9)=RIGHT(SUBSTITUTE('Company information'!D$4,"-",""),9)) | W259: =AI259-I259
...

Sheet Annex IV-EX
A1: តារាងឧបសម្ព័ន្ធ IV
A2: បញ្ជាក់អំពីការលក់
A3: (ការនាំចេញ/លក់បន្ទុករដ្ឋ/លក់តាមអត្រា០%)
A4: ក្រុមហ៊ុន៖ | B4: ='Company information'!D2 | D4: សវនករពន្ធដារ៖ | E4: ='Company information'!D8
A5: លេខ អតប ៖ | B5: ='Company information'!D4 | E5: ='Company information'!E8
A6: ='Company information'!H8 | D6: ទឹកប្រាក់ស្នើសុំបង្វិលសងចំនួន៖ | E6: ='Company information'!H9
A7: ល.រ | B7: បរិយាយ | C7: ប្រតិវេទន៍គយនាំចេញ/វិក្កយបត្រ | E7: តម្លៃជារៀល
C8: លេខ | D8: ចុះថ្ងៃទី ខែ ឆ្នាំ
A10: 1 | B10: សេវាកម្មកាត់ដេរ Garment Service | C10: ACL-20230004 | D10: 45291 | E10: 581845
A11: 2 | B11: នាំចេញសំលៀកបំពាក់ | C11: PFA240512 | D11: 45407 | E11: 74373
A12: 3 | B12: នាំចេញសំលៀកបំពាក់ | C12: PFA240425 | D12: 45385 | E12: 581845
A13: 4 | B13: សេវាកម្មកាត់ដេរ | C13: ACLCMT-20240009 | D13: 45412 | E13: 581845
A14: 5 | B14: សេវាកម្មកាត់ដេរ | C14: ACLCMT-20240007 | D14: 45412 | E14: 99936
A15: 6 | B15: សេវាកម្មកាត់ដេរ | C15: ACLCMT-20240048 | D15: 45443 | E15: 74982
A16: 7 | B16: នាំចេញសំលៀកបំពាក់ | C16: E15445 | D16: 45442 | E16: 74982
A17: 8 | B17: សេវាកម្មកាត់ដេរ | C17: ACLCMT-20240068 | D17: 45471 | E17: 74982
A18: 9 | B18: នាំចេញសំលៀកបំពាក់ | C18: E103463 | D18: 45451 | E18: 74982
A19: 10 | B19: នាំចេញសំលៀកបំពាក់ | C19: E97797 | D19: 45444 | E19: 74982
A20: 11 | B20: សេវាកម្មកាត់ដេរ | C20: ACLCMT-20240168 | D20: 45504 | E20: 74982
A21: 12 | B21: សេវាកម្មកាត់ដេរ | C21: ACLCMT-20240121 | D21: 45504 | E21: 117455
... A23: 14 | B23: នាំចេញសំលៀកបំពាក់ | C23: E139173 | D23: 45495 | E23: 117455
A24: សរុបការនាំចេញ | E24: =SUM(E10:E23)
D26: រាជធានីភ្នំពេញ.ថ្ងៃទី ខែ ឆ្នាំ
D27: មន្ត្រីសវនកម្ម
D29: ='Company information'!D9 | E29: ='Company information'!E9

Sheet Annex V-Local Sale
A1: តារាងឧបសម្ព័ន្ធ V
A2: បញ្ជាក់អំពីអាករលើធាតុចេញ
A3: ( ការលក់ក្នុងស្រុក )
A4: ក្រុមហ៊ុន៖ | B4: ='Company information'!D2 | G4: សវនករពន្ធដារ៖ | H4: ='Company information'!D8
A5: លេខ អតប ៖ | B5: ='Company information'!D4 | H5: ='Company information'!E8
A6: ='Company information'!H8 | F6: ទឹកប្រាក់ស្នើសុំបង្វិលសងចំនួន៖ | H6: ='Company information'!H9
A7: ល.រ | B7: បរិយាយ | C7: វិក្កយបត្រ | E7: អាករតម្លៃ (ដុល្លា) | F7: អត្រាប្តូរប្រាក់ | G7: អាករតម្លៃ (រៀល) | H7: ផ្សេងៗ
C8: លេខ | D8: ថ្ងៃ ខែ ឆ្នាំ
A10: 1 | B10: លក់កាកសំណល់អេតចាយ - Sale Scrap | C10: ACL-20240002 | D10: 45314 | G10: 581845
A11: 2 | B11: លក់កាកសំណល់អេតចាយ - Sale Scrap | C11: ACL-20240001 | D11: 45314 | G11: 100136
A12: 3 | B12: លក់កាកសំណល់អេតចាយ - Sale Scrap | C12: ACL-20240004 | D12: 45341 | G12: 155245
A13: 4 | B13: លក់កាកសំណល់អេតចាយ - Sale Scrap | C13: ACL-20240012 | D13: 45373 | G13: 74982
A14: 5 | B14: លក់កាកសំណល់អេតចាយ - Sale Scrap | C14: ACL-20240011 | D14: 45356 | G14: 99936
A15: 6 | B15: លក់កាកសំណល់អេតចាយ - Sale Scrap | C15: ACL-20240010 | D15: 45356 | G15: 74373
A16: 7 | B16: សេវាកម្មកាត់ដេរ | C16: ACL-20240018 | D16: 45412 | G16: 6885857
A17: 8 | B17: លក់កាកសំណល់អេតចាយ-Sale Scrap | C17: ACL-20240017 | D17: 45412 | G17: 65291
A18: 9 | B18: លក់កាកសំណល់អេតចាយ-Sale Scrap | C18: ACL-20240022 | D18: 45470 | G18: 4482
A19: 10 | B19: លក់កាកសំណល់អេតចាយ-Sale Scrap | C19: ACL-20240025 | D19: 45503 | G19: 117455
A20: 11 | B20: លក់កាកសំណល់អេតចាយ-Sale Scrap | C20: ACL-20240029 | D20: 45534 | G20: 394691
A21: 12 | B21: លក់កាកសំណល់អេតចាយ-Sale Scrap | C21: ACL-20240026 | D21: 45510 | G21: 250215
... A23: 14 | B23: លក់កាកសំណល់អេតចាយ-Sale Scrap | C23: ACL-20240030 | D23: 45600 | G23: 290909
A24: សរុបការលក់ក្នុងស្រុក | G24: =SUM(G10:G23)
G26: រាជធានីភ្នំពេញ.ថ្ងៃទី ខែ ឆ្នាំ
G27: មន្ត្រីសវនកម្ម
G29: ='Company information'!D9 | H29: ='Company information'!E9

Sheet Taxpaid
C4: ='Company information'!D7
B5: ល.រ | C5: ប្រភេទពន្ធ | D5: ចំនួនទឹកប្រាក់ពន្ធ | E5: Jan-2023 | F5: Feb-2023 | G5: Mar-2023 | H5: Apr-2023 | I5: May-2023 | J5: Jun-2023 | K5: Jul-2023 | L5: Aug-2023 | M5: Sep-2023 | N5: Oct-2023 | O5: Nov-2023 | P5: Dec-2023 | Q5: Jan-2024 | R5: Feb-2024 | S5: Mar-2024 | T5: Apr-2024 | U5: May-2024 | V5: Jun-2024 | W5: Jul-2024 | X5: Aug-2024 | Y5: Sep-2024 | Z5: Oct-2024 | AA5: Nov-2024 | AB5: Dec-2024 | AC5: Jan-2025 | AD5: Feb-2025 | AE5: Mar-2025 | AF5: Apr-2025 | AG5: May-2025 | AH5: Jun-2025 | AI5: Jul-2025 | AJ5: Aug-2025 | AK5: Sep-2025 | AL5: Oct-2025 | AM5: Nov-2025 | AN5: Dec-2025
B6: 1 | C6: ពន្ធប៉ាតង់ | D6: =SUM(E6:AN6) | E6: 0 | F6: 0 | G6: 0 | H6: 0 | I6: 0 | J6: 0 | K6: 0 | L6: 1500000 | M6: 0 | N6: 0 | O6: 0 | P6: 0 | Q6: 0 | R6: 0 | S6: 3000000 | T6: 0 | U6: 0 | V6: 0 | W6: 0 | X6: 0 | Y6: 0 | Z6: 0 | AA6: 0 | AB6: 0 | AC6: 0 | AD6: 3000000 | AE6: 0 | AF6: 0 | AG6: 0 | AH6: 0 | AI6: 0 | AJ6: 0 | AK6: 0 | AL6: 0 | AM6: 0 | AN6: 0
B7: 2 | C7: កម្រៃសេវាចុះបញ្ជី ឬធ្វើបច្ចុប្បន្នភាព | D7: =SUM(E7:AN7) | E7: 0 | F7: 0 | G7: 0 | H7: 0 | I7: 0 | J7: 0 | K7: 0 | L7: 400000 | M7: 0 | N7: 0 | O7: 0 | P7: 0 | Q7: 0 | R7: 0 | S7: 0 | T7: 0 | U7: 0 | V7: 0 | W7: 0 | X7: 0 | Y7: 0 | Z7: 0 | AA7: 200000 | AB7: 0 | AC7: 200000 | AD7: 0 | AE7: 0 | AF7: 0 | AG7: 0 | AH7: 0 | AI7: 0 | AJ7: 0 | AK7: 0 | AL7: 0 | AM7: 0 | AN7: 0
B8: 3 | C8: ពន្ធលើប្រាក់បៀវត្ស | D8: =SUM(E8:AN8) | E8: 0 | F8: 0 | G8: 0 | H8: 0 | I8: 0 | J8: 0 | K8: 0 | L8: 0 | M8: 14745919 | N8: 17256700 | O8: 16645636 | P8: 17303541 | Q8: 15943205 | R8: 16907178 | S8: 18095811 | T8: 18473483 | U8: 19887604 | V8: 21319783 | W8: 21197056 | X8: 23579307 | Y8: 21157605 | Z8: 31898419 | AA8: 36331895 | AB8: 34993494 | AC8: 35400179 | AD8: 32414288 | AE8: 25539723 | AF8: 27513458 | AG8: 30395268 | AH8: 44686508 | AI8: 28162473 | AJ8: 27643439 | AK8: 27920299 | AL8: 28924466 | AM8: 30334561 | AN8: 40619391
B9: 4 | C9: ពន្ធលើអត្ថប្រយោជន៍បន្ថែម | D9: =SUM(E9:AN9) | E9: 0 | F9: 0 | G9: 0 | H9: 0 | I9: 0 | J9: 0 | K9: 0 | L9: 0 | M9: 0 | N9: 3416033 | O9: 2893088 | P9: 11751147 | Q9: 9486163 | R9: 4889241 | S9: 4916054 | T9: 6439288 | U9: 13906169 | V9: 10494263 | W9: 8379089 | X9: 8881572 | Y9: 10415723 | Z9: 5148907 | AA9: 11905492 | AB9: 15297731 | AC9: 11758085 | AD9: 11132472 | AE9: 12276029 | AF9: 11448370 | AG9: 9398680 | AH9: 12077278 | AI9: 12565800 | AJ9: 12757756 | AK9: 13539230 | AL9: 12874870 | AM9: 13112662 | AN9: 13773592
B10: 5 | C10: ប្រាក់រំដោះពន្ធលើប្រាក់ចំណូល | D10: =SUM(E10:AN10) | E10: 0 | F10: 0 | G10: 0 | H10: 0 | I10: 0 | J10: 0 | K10: 0 | L10: 0 | M10: 0 | N10: 0 | O10: 0 | P10: 0 | Q10: 0 | R10: 0 | S10: 0 | T10: 0 | U10: 0 | V10: 0 | W10: 0 | X10: 0 | Y10: 0 | Z10: 0 | AA10: 0 | AB10: 0 | AC10: 0 | AD10: 0 | AE10: 0 | AF10: 0 | AG10: 0 | AH10: 0 | AI10: 0 | AJ10: 0 | AK10: 0 | AL10: 0 | AM10: 0 | AN10: 0
B11: 6 | C11: ពន្ធលើប្រាក់ចំណូលប្រចាំឆ្នាំ | D11: =SUM(E11:AN11) | E11: 0 | F11: 0 | G11: 0 | H11: 0 | I11: 0 | J11: 0 | K11: 0 | L11: 0 | M11: 0 | N11: 0 | O11: 0 | P11: 0 | Q11: 0 | R11: 0 | S11: 0 | T11: 0 | U11: 0 | V11: 0 | W11: 0 | X11: 0 | Y11: 0 | Z11: 0 | AA11: 0 | AB11: 0 | AC11: 0 | AD11: 0 | AE11: 0 | AF11: 0 | AG11: 0 | AH11: 0 | AI11: 0 | AJ11: 0 | AK11: 0 | AL11: 0 | AM11: 0 | AN11: 0
B12: 7 | C12: ពន្ធកាត់ទុកលើសេវាកម្ម ១៥% | D12: =SUM(E12:AN12) | E12: 0 | F12: 0 | G12: 0 | H12: 0 | I12: 0 | J12: 0 | K12: 0 | L12: 0 | M12: 0 | N12: 4738214 | O12: 1874218 | P12: 6088836 | Q12: 3880332 | R12: 4292372 | S12: 15258802 | T12: 10939010 | U12: 11238999 | V12: 7855100 | W12: 18447624 | X12: 24896291 | Y12: 23057495 | Z12: 17486099 | AA12: 14246633 | AB12: 14610672 | AC12: 36349234 | AD12: 15216359 | AE12: 15974256 | AF12: 11903645 | AG12: 13691592 | AH12: 10369826 | AI12: 7107482 | AJ12: 13844082 | AK12: 16103330 | AL12: 8330958 | AM12: 7309224 | AN12: 9617986
B13: 8 | C13: ពន្ធកាត់ទុកលើថ្លៃឈ្នួល (រូបវន្ដបុគ្គល) | D13: =SUM(E13:AN13) | E13: 0 | F13: 0 | G13: 0 | H13: 0 | I13: 0 | J13: 0 | K13: 0 | L13: 0 | M13: 0 | N13: 186075 | O13: 185175 | P13: 31209809 | Q13: 4699329 | R13: 6782616 | S13: 6735943 | T13: 6774282 | U13: 6822622 | V13: 7536055 | W13: 6847625 | X13: 6762613 | Y13: 6769281 | Z13: 6772615 | AA13: 6714273 | AB13: 6709273 | AC13: 5694865 | AD13: 5676468 | AE13: 10768492 | AF13: 10776568 | AG13: 10866058 | AH13: 10879623 | AI13: 9648623 | AJ13: 10014160 | AK13: 10030615 | AL13: 10044143 | AM13: 10011662 | AN13: 10644655
B14: 9 | C14: អាករលើតម្លៃបន្ថែម | D14: =SUM(E14:AN14) | E14: 0 | F14: 0 | G14: 0 | H14: 0 | I14: 0 | J14: 0 | K14: 0 | L14: 0 | M14: 0 | N14: 0 | O14: 0 | P14: 0 | Q14: 0 | R14: 241601 | S14: 18911 | T14: 0 | U14: 19155 | V14: 21157 | W14: 19225 | X14: 18986 | Y14: 38011 | Z14: 19014 | AA14: 18851 | AB14: 18837 | AC14: 18832 | AD14: 397409 | AE14: 18720 | AF14: 18734 | AG14: 18743 | AH14: 18766 | AI14: 18748 | AJ14: 18757 | AK14: 18766 | AL14: 18813 | AM14: 649053 | AN14: 18780
B15: 10 | C15: អាករពិសេសលើទំនិញមួយចំនួន | D15: =SUM(E15:AN15) | E15: 0 | F15: 0 | G15: 0 | H15: 0 | I15: 0 | J15: 0 | K15: 0 | L15: 0 | M15: 0 | N15: 0 | O15: 0 | P15: 0 | Q15: 0 | R15: 0 | S15: 0 | T15: 0 | U15: 0 | V15: 0 | W15: 0 | X15: 0 | Y15: 0 | Z15: 0 | AA15: 0 | AB15: 0 | AC15: 0 | AD15: 0 | AE15: 0 | AF15: 0 | AG15: 0 | AH15: 0 | AI15: 0 | AJ15: 0 | AK15: 0 | AL15: 0 | AM15: 0 | AN15: 0
B16: 11 | C16: អាករពិសេសលើសេវាមួយចំនួន | D16: =SUM(E16:AN16) | E16: 0 | F16: 0 | G16: 0 | H16: 0 | I16: 0 | J16: 0 | K16: 0 | L16: 0 | M16: 0 | N16: 0 | O16: 0 | P16: 0 | Q16: 0 | R16: 0 | S16: 0 | T16: 0 | U16: 0 | V16: 0 | W16: 0 | X16: 0 | Y16: 0 | Z16: 0 | AA16: 0 | AB16: 0 | AC16: 0 | AD16: 0 | AE16: 0 | AF16: 0 | AG16: 0 | AH16: 0 | AI16: 0 | AJ16: 0 | AK16: 0 | AL16: 0 | AM16: 0 | AN16: 0
B17: 12 | C17: អាករសម្រាប់បំភ្លឺសាធារណៈ | D17: =SUM(E17:AN17) | E17: 0 | F17: 0 | G17: 0 | H17: 0 | I17: 0 | J17: 0 | K17: 0 | L17: 0 | M17: 0 | N17: 0 | O17: 0 | P17: 0 | Q17: 0 | R17: 0 | S17: 0 | T17: 0 | U17: 0 | V17: 0 | W17: 0 | X17: 0 | Y17: 0 | Z17: 0 | AA17: 0 | AB17: 0 | AC17: 0 | AD17: 0 | AE17: 0 | AF17: 0 | AG17: 0 | AH17: 0 | AI17: 0 | AJ17: 0 | AK17: 0 | AL17: 0 | AM17: 0 | AN17: 0
... B21: 16 | C21: កម្រៃសេវាលើការប្រើប្រាស់កម្មវិធីបញ្ចូលប្រកាសពន្ធអាជីវកម្មអនឡាញ | D21: =SUM(E21:AN21) | E21: 0 | F21: 0 | G21: 0 | H21: 0 | I21: 0 | J21: 0 | K21: 0 | L21: 0 | M21: 0 | N21: 0 | O21: 0 | P21: 0 | Q21: 0 | R21: 0 | S21: 0 | T21: 0 | U21: 0 | V21: 0 | W21: 0 | X21: 0 | Y21: 0 | Z21: 0 | AA21: 0 | AB21: 0 | AC21: 0 | AD21: 0 | AE21: 0 | AF21: 0 | AG21: 0 | AH21: 0 | AI21: 0 | AJ21: 0 | AK21: 0 | AL21: 400000 | AM21: 0 | AN21: 0
C22: សរុបទឹកប្រាក់ពន្ធបានបង់ចូលរដ្ឋ | D22: =SUM(D6:D21)

Sheet Damco
A1: តារាងឧបសម្ព័ន្ឋ
A2: តារាងប្រៀធៀបវិក្ក័យប័ត្រស្នើសុំបង្វិលសងអាករលើតំលៃបន្ថែម ( Cross checking )
A3: ='Annex I-IM State Charge'!#REF!
A4: ='Annex I-IM State Charge'!#REF!
A5: ល.រ | B5: ក្រុមហ៊ុនស្នើសុំបង្វិលសង | E5: អ្នកផ្គត់ផ្គង់ | J5: ផ្សេងៗ
B6: វិក្កយបត្រ | E6: សហគ្រាស | F6: លេខអតប | G6: វិក្កយបត្រ
B7: លេខ | C7: ថ្ងៃទី ខែ ឆ្នាំ | D7: ប្រាក់អាករ | G7: លេខ | H7: ថ្ងៃទី ខែ ឆ្នាំ | I7: ប្រាក់អាករ
A8: 1 | B8: 030209 | C8: 41246 | D8: 58.25 | E8: A P L Logistics | F8: 100046460 | G8: 030209 | H8: 41246 | I8: 58.25 | J8: បានបង់
A9: 2 | B9: 030231 | C9: 41248 | D9: 4 | E9: A P L Logistics | F9: 100046460 | G9: 030231 | H9: 41248 | I9: 4 | J9: បានបង់
A10: 3 | B10: 030241 | C10: 41254 | D10: 49.75 | E10: A P L Logistics | F10: 100046460 | G10: 030241 | H10: 41254 | I10: 49.75 | J10: បានបង់
A11: 4 | B11: 030262 | C11: 41254 | D11: 181.79 | E11: A P L Logistics | F11: 100046460 | G11: 030262 | H11: 41254 | I11: 181.79 | J11: បានបង់
A12: 5 | B12: 030302 | C12: 41260 | D12: 46.69 | E12: A P L Logistics | F12: 100046460 | G12: 030302 | H12: 41260 | I12: 46.69 | J12: បានបង់
A13: 6 | B13: 030328 | C13: 41260 | D13: 236.64 | E13: A P L Logistics | F13: 100046460 | G13: 030328 | H13: 41260 | I13: 236.64 | J13: បានបង់
A14: 7 | B14: 030343 | C14: 41261 | D14: 4 | E14: A P L Logistics | F14: 100046460 | G14: 030343 | H14: 41261 | I14: 4 | J14: បានបង់
A15: 8 | B15: 030353 | C15: 41261 | D15: 10 | E15: A P L Logistics | F15: 100046460 | G15: 030353 | H15: 41261 | I15: 10 | J15: បានបង់
A16: 9 | B16: 030450 | C16: 41274 | D16: 87.52 | E16: A P L Logistics | F16: 100046460 | G16: 030450 | H16: 41274 | I16: 87.52 | J16: បានបង់
A17: 10 | B17: 030469 | C17: 41274 | D17: 39.29 | E17: A P L Logistics | F17: 100046460 | G17: 030469 | H17: 41274 | I17: 39.29 | J17: បានបង់
A18: Total 12/2012 | D18: =SUM(D8:D17) | H18: USD | I18: =SUM(I8:I17)
A19: Total 12/2012 | G19: 3995 | H19: RIEL | I19: =I18*G19
A20: 1 | B20: 029920 | C20: 41218 | D20: 77 | E20: A P L Logistics | F20: 100046460 | G20: 029920 | H20: 41218 | I20: 77 | J20: បានបង់
A21: 2 | B21: 029981 | C21: 41225 | D21: 115.89 | E21: A P L Logistics | F21: 100046460 | G21: 029981 | H21: 41225 | I21: 115.89 | J21: បានបង់
A22: 3 | B22: 030003 | C22: 41225 | D22: 82.91 | E22: A P L Logistics | F22: 100046460 | G22: 030003 | H22: 41225 | I22: 82.91 | J22: បានបង់
A23: 4 | B23: 030044 | C23: 41232 | D23: 55.32 | E23: A P L Logistics | F23: 100046460 | G23: 030044 | H23: 41232 | I23: 55.32 | J23: បានបង់
A24: 5 | B24: 030062 | C24: 41232 | D24: 32.03 | E24: A P L Logistics | F24: 100046460 | G24: 030062 | H24: 41232 | I24: 32.03 | J24: បានបង់
A25: Total 11/2012 | D25: =SUM(D20:D24) | H25: USD | I25: =SUM(I20:I24)
A26: Total 11/2012 | G26: 3999 | H26: RIEL | I26: =I25*G26
A27: 1 | B27: 029638 | C27: 41183 | D27: 89.93 | E27: A P L Logistics | F27: 100046460 | G27: 029638 | H27: 41183 | I27: 89.93 | J27: បានបង់
A28: 2 | B28: 029716 | C28: 41190 | D28: 49.63 | E28: A P L Logistics | F28: 100046460 | G28: 029716 | H28: 41190 | I28: 49.63 | J28: បានបង់
A29: 3 | B29: 029766 | C29: 41197 | D29: 115.81 | E29: A P L Logistics | F29: 100046460 | G29: 029766 | H29: 41197 | I29: 115.81 | J29: បានបង់
A30: 4 | B30: 029816 | C30: 41204 | D30: 101.98 | E30: A P L Logistics | F30: 100046460 | G30: 029816 | H30: 41204 | I30: 101.98 | J30: បានបង់
A31: 5 | B31: 029869 | C31: 41211 | D31: 67.28 | E31: A P L Logistics | F31: 100046460 | G31: 029869 | H31: 41211 | I31: 67.28 | J31: បានបង់
A32: Total 10/2012 | D32: =SUM(D27:D31) | H32: USD | I32: =SUM(I27:I31)
A33: Total 10/2012 | G33: 4028 | H33: RIEL | I33: =I32*G33
A34: 1 | B34: 029426 | C34: 41162 | D34: 206.96 | E34: A P L Logistics | F34: 100046460 | G34: 029426 | H34: 41162 | I34: 206.96 | J34: បានបង់
A35: 2 | B35: 029501 | C35: 41169 | D35: 69.7 | E35: A P L Logistics | F35: 100046460 | G35: 029501 | H35: 41169 | I35: 69.7 | J35: បានបង់
A36: 3 | B36: 029565 | C36: 41176 | D36: 46.66 | E36: A P L Logistics | F36: 100046460 | G36: 029565 | H36: 41176 | I36: 46.66 | J36: បានបង់
A37: Total 09/2012 | D37: =SUM(D34:D36) | H37: USD | I37: =SUM(I34:I36)
A38: Total 09/2012 | G38: 4044 | H38: RIEL | I38: =I37*G38
A39: 1 | B39: 029026 | C39: 41127 | D39: 37.84 | E39: A P L Logistics | F39: 100046460 | G39: 029026 | H39: 41127 | I39: 37.84 | J39: បានបង់
A40: 2 | B40: 029107 | C40: 41134 | D40: 95.46 | E40: A P L Logistics | F40: 100046460 | G40: 029107 | H40: 41134 | I40: 95.46 | J40: បានបង់
...

Sheet Chea Fat
A1: តារាងឧបសម្ព័ន្ឋ
A2: តារាងប្រៀធៀបវិក្ក័យប័ត្រស្នើសុំបង្វិលសងអាករលើតំលៃបន្ថែម ( Cross checking )
A3: នាមករណ៏សហគ្រាស : Maurea Garments Corp
A4: VAT TIN : 1 0 0 0 5 2 9 6 7
A5: ល.រ | B5: ក្រុមហ៊ុនស្នើសុំបង្វិលសង | E5: អ្នកផ្គត់ផ្គង់ | J5: ផ្សេងៗ
B6: វិក័យបត្រ័ | E6: សហគ្រាស | F6: លេខអតប | G6: វិក័យបត្រ័
B7: លេខ | C7: ថ្ងៃទី ខែ ឆ្នាំ | D7: ប្រាក់អាករ | G7: លេខ | H7: ថ្ងៃទី ខែ ឆ្នាំ | I7: ប្រាក់អាករ
A8: 1 | B8: 07-0360 | C8: 41842 | D8: 41.5 | E8: YUSEN LOGISTICS | F8: 104015799 | G8: 07-0360 | H8: 41842 | I8: 41.5
A9: 2 | B9: 07-0367 | C9: 41842 | D9: 64.57 | E9: YUSEN LOGISTICS | F9: 104015799 | G9: 07-0367 | H9: 41842 | I9: 64.57
A10: 3 | B10: 07-0368 | C10: 41842 | D10: 59.11 | E10: YUSEN LOGISTICS | F10: 104015799 | G10: 07-0368 | H10: 41842 | I10: 59.11
A11: 4 | B11: 07-0517 | C11: 41849 | D11: 75.93 | E11: YUSEN LOGISTICS | F11: 104015799 | G11: 07-0517 | H11: 41849 | I11: 75.93
A12: 5 | B12: 08-0039 | C12: 41856 | D12: 46.05 | E12: YUSEN LOGISTICS | F12: 104015799 | G12: 08-0039 | H12: 41856 | I12: 46.05
A13: 6 | B13: 08-0044 | C13: 41856 | D13: 41.5 | E13: YUSEN LOGISTICS | F13: 104015799 | G13: 08-0044 | H13: 41856 | I13: 41.5
A14: 7 | B14: 08-0185 | C14: 41864 | D14: 27.9 | E14: YUSEN LOGISTICS | F14: 104015799 | G14: 08-0185 | H14: 41864 | I14: 27.9
A15: 8 | B15: 08-0677 | C15: 41882 | D15: 143 | E15: YUSEN LOGISTICS | F15: 104015799 | G15: 08-0677 | H15: 41882 | I15: 143
A16: 9 | B16: 08-0685 | C16: 41882 | D16: 60.33 | E16: YUSEN LOGISTICS | F16: 104015799 | G16: 08-0685 | H16: 41882 | I16: 60.33
A17: 10 | B17: 09-0111 | C17: 41892 | D17: 27.53 | E17: YUSEN LOGISTICS | F17: 104015799 | G17: 09-0111 | H17: 41892 | I17: 27.53
A18: 11 | B18: 09-0117 | C18: 41892 | D18: 53.64 | E18: YUSEN LOGISTICS | F18: 104015799 | G18: 09-0117 | H18: 41892 | I18: 53.64
A19: 12 | B19: 09-0199 | C19: 41898 | D19: 34.77 | E19: YUSEN LOGISTICS | F19: 104015799 | G19: 09-0199 | H19: 41898 | I19: 34.77
... A40: 33 | B40: 502-0531 | C40: 42059 | D40: 102.92 | E40: YUSEN LOGISTICS | F40: 104015799 | G40: 502-0531 | H40: 42059 | I40: 102.92
A41: TOTAL 7/2012-02/2015 | D41: =SUM(D8:D40) | I41: =SUM(I8:I40)
E44: YUSEN LOGISTICS | F44: 104015799 | G44: 2-00309 | H44: 41619 | I44: 5

Sheet S G L CAMBODIA
A1: តារាងឧបសម្ព័ន្ឋ
A2: តារាងប្រៀធៀបវិក្ក័យប័ត្រស្នើសុំបង្វិលសងអាករលើតំលៃបន្ថែម ( Cross checking )
A3: នាមករណ៏សហគ្រាស : Maurea Garments Corp
A4: VAT TIN : 1 0 0 0 5 2 9 6 7
A5: ល.រ | B5: ក្រុមហ៊ុនស្នើសុំបង្វិលសង | E5: អ្នកផ្គត់ផ្គង់ | J5: ផ្សេងៗ
B6: វិក័យបត្រ័ | E6: សហគ្រាស | F6: លេខអតប | G6: វិក័យបត្រ័
B7: លេខ | C7: ថ្ងៃទី ខែ ឆ្នាំ | D7: ប្រាក់អាករ | G7: លេខ | H7: ថ្ងៃទី ខែ ឆ្នាំ | I7: ប្រាក់អាករ
A8: 1 | B8: 227231 | C8: 41246 | D8: 8.5 | E8: S G L CAMBODIA | F8: 100119816 | G8: 227231 | H8: 41246 | I8: 8.5
A9: 2 | B9: 227288 | C9: 41246 | D9: 52.36 | E9: S G L CAMBODIA | F9: 100119816 | G9: 227288 | H9: 41246 | I9: 52.36
A10: 3 | B10: 227430 | C10: 41255 | D10: 21.2 | E10: S G L CAMBODIA | F10: 100119816 | G10: 227430 | H10: 41255 | I10: 21.2
A11: 4 | B11: 227461 | C11: 41255 | D11: 29.57 | E11: S G L CAMBODIA | F11: 100119816 | G11: 227461 | H11: 41255 | I11: 29.57
A12: 5 | B12: 227539 | C12: 41260 | D12: 34.24 | E12: S G L CAMBODIA | F12: 100119816 | G12: 227539 | H12: 41260 | I12: 34.24
A13: 6 | B13: 227543 | C13: 41260 | D13: 8.93 | E13: S G L CAMBODIA | F13: 100119816 | G13: 227543 | H13: 41260 | I13: 8.93
A14: 7 | B14: 227552 | C14: 41260 | D14: 27.62 | E14: S G L CAMBODIA | F14: 100119816 | G14: 227552 | H14: 41260 | I14: 27.62
A15: 8 | B15: 227583 | C15: 41261 | D15: 57.77 | E15: S G L CAMBODIA | F15: 100119816 | G15: 227583 | H15: 41261 | I15: 57.77
A16: 9 | B16: 227586 | C16: 41261 | D16: 24 | E16: S G L CAMBODIA | F16: 100119816 | G16: 227586 | H16: 41261 | I16: 24
A17: 10 | B17: 227605 | C17: 41261 | D17: 28.88 | E17: S G L CAMBODIA | F17: 100119816 | G17: 227605 | H17: 41261 | I17: 28.88
A18: 11 | B18: 227826 | C18: 41274 | D18: 24 | E18: S G L CAMBODIA | F18: 100119816 | G18: 227826 | H18: 41274 | I18: 24
A19: 12 | B19: 227862 | C19: 41274 | D19: 36.26 | E19: S G L CAMBODIA | F19: 100119816 | G19: 227862 | H19: 41274 | I19: 36.26
... A458: 455 | B458: 443954 | C458: 42002 | D458: 44.24 | E458: S G L CAMBODIA | F458: 100119816 | G458: 443954 | H458: 42002 | I458: 44.24
A459: TOTAL 7/2012-02/2015 | D459: =SUM(D8:D458) | I459: =SUM(I8:I458)

Sheet Sheet3
A1: តារាងឧបសម្ព័ន្ឋ
A2: តារាងប្រៀធៀបវិក្ក័យប័ត្រស្នើសុំបង្វិលសងអាករលើតំលៃបន្ថែម ( Cross checking )
A3: នាមករណ៏សហគ្រាស : Maurea Garments Corp
A4: VAT TIN : 1 0 0 0 5 2 9 6 7
A5: ល.រ | B5: ក្រុមហ៊ុនស្នើសុំបង្វិលសង | E5: អ្នកផ្គត់ផ្គង់ | J5: ផ្សេងៗ
B6: វិក័យបត្រ័ | E6: សហគ្រាស | F6: លេខអតប | G6: វិក័យបត្រ័
B7: លេខ | C7: ថ្ងៃទី ខែ ឆ្នាំ | D7: ប្រាក់អាករ | G7: លេខ | H7: ថ្ងៃទី ខែ ឆ្នាំ | I7: ប្រាក់អាករ

Sheet Sale - June
A1: សៀវភៅទិនានុប្បវត្តិលក់- នាំចេញ
A2: ខែ​​ មិថុនា ឆ្នាំ ២០១៥
A3: ជី អេវើរហ្រ្គីន( ខេមបូឌា​ ) នីតធីង | K3: Vat:100193102
A4: ភូមិជ្រៃកោង សង្កាត់ចោមចៅ ខណ្ឌ ពោធិសែនជ័យ ក្រុង ភ្នំពេញ | K4: Average: | L4: 4088
A5: វិក្ក័យប័ត្រ | I5: ការផ្គត់ផ្គង់
A6: កាលបរិចេ្ឆទ | B6: វិក្ក័យប័ត្រ | C6: អ្នកទិញ | D6: លេខ អតប | E6: បរិយាយ | F6: បរិមាណ | I6: karlk;Cab;Gakr | M6: សរុបថ្លៃទិញ
D7: TIN | G7: ការផ្គត់ផ្គង់ | H7: ការនាំចេញ | I7: lk;;»übuKþlCab;Gakr | K7: lk;;»üGñkeRbIR)as; | M7: រួមទាំអាករ
G8: មិនជាប់អាករ | H8: អត្រា​​ 0 % | I8: តំលៃជាប់អាករ | J8: អាករ | K8: តំលៃជាប់អាករ | L8: អាករ
A9: 42160 | B9: E 55119 | C9: LPP S.A | E9: Men's Top | F9: 137 CT | H9: 41519138 | M9: =G9+H9
A10: 42160 | B10: E 53624 | C10: PRIMARK | E10: See Val Note | F10: 655 CT | H10: 157610622 | M10: =G10+H10
A11: 42160 | B11: E 9812 | C11: SMYK SP Z.O.O | E11: Girls Knitted Dress | F11: 518 CT | H11: 75926121 | M11: =G11+H11
A12: 42164 | B12: E 10122 | C12: SMYK SP Z.O.O | E12: Girls Knitted Sweat Shirt | F12: 404 CT | H12: 109260590 | M12: =G12+H12
A13: 42167 | B13: E 57854 | C13: PRIMARK | E13: Men's Long Sleeve Hoodie | F13: 550 CT | H13: 136860570 | M13: =G13+H13
A14: 42167 | B14: E 57078 | C14: LPP S.A | E14: Men's Top | F14: 1094 CT | H14: 189450332 | M14: =G14+H14
A15: 42174 | B15: E 60607 | C15: CAPRI SRL | E15: Men's Hoody | F15: 827 CT | H15: 267888456 | M15: =G15+H15
A16: 42174 | B16: E 59730 | C16: LPP S.A | E16: Men's Jogging Top | F16: 815 CT | H16: 233561904 | M16: =G16+H16
A17: 42174 | B17: E 60079 | C17: LPP S.A | E17: Men's Sweater +Top | F17: 400 CT | H17: 106100285 | M17: =G17+H17
A18: 42175 | B18: E 61426 | C18: VISAGE LIMITED | E18: Men's Pari / Monica / Leyton Crew | F18: 556 CT | H18: 145296432 | M18: =G18+H18
A19: 42175 | B19: E 61432 | C19: PRIMARK STORES LIMITED | E19: See Val Note | F19: 1220 CT | H19: 299682480 | M19: =G19+H19
A20: 42181 | B20: E 63424 | C20: PRIMARK US CORP | E20: Men Chest Print Zip | F20: 37 CT | H20: 6493691 | M20: =G20+H20
... A22: 42181 | B22: E 63568 | C22: VISAGE LIMITED | E22: Men's Morgan Crew + Connect Crew+ Leyton | F22: 338 CT | H22: 94840834 | M22: =G22+H22
A23: =L4 | E23: Riel | F23: =SUM(F9:F22) | H23: =SUM(H9:H22) | M23: =SUM(M9:M22)
A24: Total USD | E24: USD | G24: =G23/L4 | H24: =H23/L4 | I24: =I23*4034 | J24: =J23*4034 | K24: =K23*4034 | L24: =L23*4034 | M24: =M23/L4
G25: Box 12 | H25: Box 13 | I25: Box 14 | J25: Box 15 | K25: Box 14 | L25: Box 15
H26: Approved By :
N27: =H23*1%
H28: =H24*1%
G29: Sales
G30: July | H30: ='Sale - Jul'!H30 | I30: 21 invoices
G31: Aug | H31: ='Sale - Aug'!I47 | I31: 38 invoices
G32: June | H32: =H23 | I32: 14 invoices
G33: Total: | H33: =SUM(H30:H32) | I33: =14+38+21
H37: =H24*1%

Sheet Sale - Jul
A1: សៀវភៅទិនានុប្បវត្តិលក់- នាំចេញ
A2: ខែ​​ កក្កដា ឆ្នាំ ២០១៥
A3: ជី អេវើរហ្រ្គីន( ខេមបូឌា​ ) នីតធីង | K3: Vat:100193102
A4: ភូមិជ្រៃកោង សង្កាត់ចោមចៅ ខណ្ឌ ពោធិសែនជ័យ ក្រុង ភ្នំពេញ | K4: Average: | L4: 4099
A5: វិក្ក័យប័ត្រ | I5: ការផ្គត់ផ្គង់
A6: កាលបរិចេ្ឆទ | B6: វិក្ក័យប័ត្រ | C6: អ្នកទិញ | D6: លេខ អតប | E6: បរិយាយ | F6: បរិមាណ | I6: karlk;Cab;Gakr | M6: សរុបថ្លៃទិញ
D7: TIN | G7: ការផ្គត់ផ្គង់ | H7: ការនាំចេញ | I7: lk;;»übuKþlCab;Gakr | K7: lk;;»üGñkeRbIR)as; | M7: រួមទាំអាករ
G8: មិនជាប់អាករ | H8: អត្រា​​ 0 % | I8: តំលៃជាប់អាករ | J8: អាករ | K8: តំលៃជាប់អាករ | L8: អាករ
A9: 42188 | B9: E 65884 | C9: LPP S.A | E9: Men's Jogging Top | F9: 1841 CT | H9: 469164366 | M9: =G9+H9
A10: 42188 | B10: E 65884 | C10: LPP S.A | E10: Men's Knit Trousers | F10: 631 CT | H10: 224637197 | M10: =G10+H10
A11: 42188 | B11: E 65484 | C11: Primark Tiendas Slu | E11: Men's Zip Thru Hoody | F11: 343 CT | H11: 88553682 | M11: =G11+H11
A12: 42189 | B12: E 67494 | C12: PRIMARK | E12: Men's Long Sleeve Zip Thru Hoodie | F12: 1093 CT | H12: 282184182 | M12: =G12+H12
A13: 42194 | B13: E 68109 | C13: PRIMARK STORES LIMITED | E13: 7B (Boy) Core Hoody | F13: 600 CT | H13: 137692800 | M13: =G13+H13
A14: 42194 | B14: E 68146 | C14: PRIMARK | E14: Men's Zip Thru Hoody | F14: 772 CT | H14: 199310328 | M14: =G14+H14
A15: 42195 | B15: E 69396 | C15: LPP S.A | E15: Men's Knit Sweater + Jogging Top | F15: 1133 CT | H15: 222232983 | M15: =G15+H15
A16: 42195 | B16: E 69396 | C16: LPP S.A | E16: Men's Knit Trousers | F16: 39 CT | H16: 15787217 | M16: =G16+H16
A17: 42195 | B17: E 69549 | C17: PRIMARK STORES LIMITED | E17: Men + Boy Hoodies | F17: 638 CT | H17: 147298512 | M17: =G17+H17
A18: 42196 | B18: E 70637 | C18: LPP S.A | E18: Ladies Jogging Top | F18: 490 CT | H18: 108300780 | M18: =G18+H18
A19: 42196 | B19: E 70637 | C19: LPP S.A | E19: Men's Knit Trousers | F19: 99 CT | H19: 39649873 | M19: =G19+H19
A20: 42196 | B20: E 70627 | C20: Primark Tiendas Slu | E20: Men's Zip Thru Hoody | F20: 2066 CT | H20: 532736694 | M20: =G20+H20
... A29: 42203 | B29: E 73524 | C29: VDR FASHION GROUP BV | E29: Ladies Knitted Blazer | F29: 191 CT | H29: 114575606 | M29: =G29+H29
A30: =L4 | E30: Riel | F30: =SUM(F9:F29) | H30: =SUM(H9:H29) | M30: =SUM(M9:M29)
A31: Total USD | E31: USD | G31: =G30/L4 | H31: =H30/L4 | I31: =I30*4034 | J31: =J30*4034 | K31: =K30*4034 | L31: =L30*4034 | M31: =M30/L4
G32: Box 12 | H32: Box 13 | I32: Box 14 | J32: Box 15 | K32: Box 14 | L32: Box 15
H33: Approved By :
H35: =H31*1%
H44: =H31*1%

Sheet Sale - Aug
A1: សៀវភៅទិនានុប្បវត្តិលក់- នាំចេញ
A2: ខែ​​ សីហា ឆ្នាំ ២០១៥
A3: ជី អេវើរហ្រ្គីន( ខេមបូឌា​ ) នីតធីង | L3: Vat:100193102
A4: ភូមិជ្រៃកោង សង្កាត់ចោមចៅ ខណ្ឌ ពោធិសែនជ័យ ក្រុង ភ្នំពេញ | L4: Average: | M4: 4095
A5: វិក្ក័យប័ត្រ | J5: ការផ្គត់ផ្គង់
A6: កាលបរិចេ្ឆទ | B6: វិក្ក័យប័ត្រ | C6: អ្នកទិញ | D6: លេខ អតប | E6: បរិយាយ | F6: បរិមាណ | J6: karlk;Cab;Gakr | N6: សរុបថ្លៃទិញ
D7: TIN | F7: ការផ្គត់ផ្គង់ | I7: ការនាំចេញ | J7: lk;;»übuKþlCab;Gakr | L7: lk;;»üGñkeRbIR)as; | N7: រួមទាំអាករ
F8: មិនជាប់អាករ | I8: អត្រា​​ 0 % | J8: តំលៃជាប់អាករ | K8: អាករ | L8: តំលៃជាប់អាករ | M8: អាករ
A9: 42202 | B9: E 72202 | C9: Primark Us Corp | E9: Men Zip Thru Hoody | F9: 65 | G9: CT | I9: 16764930 | N9: =H9+I9
A10: 42203 | B10: E 13027 | C10: LPP S.A | E10: Ladies Knit Jogging Top | F10: 64 | G10: CT | I10: 26424115 | N10: =H10+I10
A11: 42208 | B11: E 13359 | C11: VDR Fashion Group BV | E11: Ladies Knit Shirt | F11: 36 | G11: CT | I11: 29192000 | N11: =H11+I11
A12: 42209 | B12: E 74804 | C12: Primark Us Corp | E12: Boy Hoody | F12: 305 | G12: CT | I12: 70028000 | N12: =H12+I12
A13: 42209 | B13: E 74578 | C13: LPP S.A | E13: Men's Jogging Top | F13: 904 | G13: CT | I13: 242980473 | N13: =H13+I13
A14: 42210 | B14: E 76431 | C14: Primark | E14: Men Zip Thru Hoody | F14: 700 | G14: CT | I14: 180986400 | N14: =H14+I14
A15: 42210 | B15: E 76547 | C15: Primark Stores Limited | E15: 7/2Boy Core Hoody | F15: 800 | G15: CT | I15: 174420000 | N15: =H15+I15
A16: 42210 | B16: E 65557 | C16: LPP S.A | E16: Ladies Jogging Top | F16: 680 | G16: CT | I16: 178829338 | N16: =H16+I16
A17: 42210 | B17: E 65557 | C17: LPP S.A | E17: Men's Knit Trousers | F17: 93 | G17: CT | I17: 36022203 | N17: =H17+I17
A18: 42215 | B18: E 76966 | C18: Primark | E18: See Val Note | F18: 355 | G18: CT | I18: 89531330 | N18: =H18+I18
A19: 42215 | B19: E 76966 | C19: Primark | E19: Ladies Nylon Zip Back Fl Legging | F19: 267 | G19: CT | I19: 191743220 | N19: =H19+I19
A20: 42216 | B20: E 78298 | C20: Primark Us Corp | E20: Mens Hoody | F20: 70 | G20: CT | I20: 18116280 | N20: =H20+I20
... A41: 42237 | B41: E 87246 | C41: Primark Stores Limited | E41: Boy's Hoody | F41: 200 | G41: CT | I41: 41197900 | N41: =H41+I41
A42: 42237 | B42: E 87199 | C42: Primakr Tiendas S.l.u. | E42: Men's Knit Chest Print Zip Thru | F42: 250 | G42: CT | I42: =15750*4079 | N42: =H42+I42
