Workbook
Name \A: #REF!
Name \D: #REF!
Name \E: #REF!
Name \G: '[1]Company Related Premises'!#REF!
Name \H: '[1]Company Related Premises'!#REF!
Name \L: '[1]Company Related Premises'!#REF!
Name \M: '[1]Company Related Premises'!#REF!
Name \N: #REF!
Name \O: #REF!
Name \P: #REF!
Name \Q: #REF!
Name \R: #REF!
Name \S: #REF!
Name \T: #REF!
Name \U: #REF!
Name \V: #REF!
Name \W: #REF!
Name \X: #REF!
Name \xy: #REF!
Name \Y: #REF!
Name \Z: #REF!
Name __PR1: [2]Sheet!#REF!
Name __SR1: #REF!
Name __SR2: #REF!
Name _PR1: [2]Sheet!#REF!
Name _SR1: #REF!
Name _SR2: #REF!
Name aa: #REF!
Name aaa: #REF!
Name abcd: #REF!
Name All: #REF!
Name ANLAGE_III: [3]Anlagevermögen!$A$1:$Z$29
Name data84: '[4]Purchase Order'!$E$40
Name dflt3: '[4]Customize Your Purchase Order'!$F$24
Name dflt4: '[4]Customize Your Purchase Order'!$E$25
Name DRPAUSE: #REF!
Name DSCTEMP: [5]DSCTEMP!$A$1:$B$65536
Name FTBSch: [2]Sheet!#REF!
Name hh: [2]Sheet!#REF!
Name is: '[6]Company Related Premises'!#REF!
Name jngiüorajg: #REF!
Name ll: #REF!
Name new: #REF!
Name PeriodsInYear: #REF!
Name PrintArea: #REF!
Name qqqqqqqqqqqqqqqqqqqqq: #REF!
Name RANDO: #REF!
Name RANDU: #REF!
Name re: [7]Sheet!#REF!
Name Report: #REF!
Name Sale: #REF!
Name SalSch: #REF!
Name Seite1: #REF!
Name Seite2: #REF!
Name Seite3: #REF!
Name Spec: #REF!
Name SR: #REF!
Name SRC: #REF!
Name tes: [2]Sheet!#REF!
Name Test: [2]Sheet!#REF!

Sheet Company information
B2: COMPANY NAME (KHMER) | D2: វីអ៊ីស៊ិន (ខេមបូឌា) អ៊ិនដាសស្ទ្រី ឯ.ក | F2: AUDIT TIMELINE | H2: ពីថ្ងៃទី១ ខែមីនា ឆ្នាំ២០២៦ ដល់ថ្ងៃទី៣១ ខែមីនា ឆ្នាំ២០២៦
B3: COMPANY NAME (ENGLISH) | D3: Viiition (Cambodia)
B4: VAT NUMBER | D4: L001-901905215 | F4: MOC NUMBER | H4: ១៥៩៧៥៥៤៨MOC
B5: BUSINESS ACTIVITY | D5: កម្មន្តសាលសម្លៀកបំពាក់ (លើកលែងជាសម្លៀកបំពាក់ស្រាប់ឬកាត់) ( ) រោងចក្រកាត់ដេរសម្លៀកបំពាក់ | F5: MOC DATE OF ISSUE | H5: ១១-០៣-២០២៦
B6: ADDRESS NAME | D6: ផ្ទះលេខ ​ ផ្លូវ ​ ភូមិស្រង់ ឃុំស្រង់ ស្រុកគងពិសី ខេត្តកំពង់ស្ពឺ | F6: PATENT ISSUE DATE | H6: ២៣-០៣-២០២៦ | I6: PATENT AMOUNT | K6: ៥,០០០,០០០ ៛
B7: REQUEST PERIOD | D7: ខែមេសា ឆ្នាំ២០២៣ ដល់ខែវិច្ឆិកា ឆ្នាំ២០២៤ | F7: VAT CERTIFICATE ISSUE DATE | H7: ១៩-០៣-២០២៦
B8: AUDITOR NAME | D8: លោក ជា ហុកស័រ | E8: កញ្ញា ប៉ែន សុជាតា | F8: REQUEST DATE | H8: ស្នើសុំបង្វិលសងអាករលើតម្លៃបន្ថែមតាមអនឡាញចុះថ្ងៃទី២២ ខែមីនា ឆ្នាំ២០២៦
D9: ជា ហុកស័រ | E9: ប៉ែន សុជាតា | F9: AMOUNT OF REQUEST | H9: 879446544
B10: PHONE NUMBER | D10: 011777957
B11: BANK ACCOUNT NUMBER TO REFUND | D11: 38800502883099
B12: BANK NAME: | D12: ធនាគារ អេស៊ីលីដាACLEDA Bank Plc.
B13: PERSON TO CONTACT | D13: លោក លាង មេង
B14: POSITION | D14: គណនេយ្យករ

Sheet Annex I-IM State Charge
A1: តារាងឧបសម្ព័ន្ធ I
A2: បញ្ជាក់អំពីអាករលើធាតុចូលដែលមិនអាចស្នើសុំជាឥណទាន
A3: ( ការនាំចូលជាបន្ទុករបស់រដ្ឋ )
A4: ក្រុមហ៊ុន៖ | B4: ='Company information'!D2 | G4: សវនករពន្ធដារ៖ | H4: ='Company information'!D8
A5: លេខ អតប៖ | B5: ='Company information'!D4 | H5: ='Company information'!E8
A6: ='Company information'!E8 | G6: ទឹកប្រាក់ស្នើសុំបង្វិលសងចំនួន៖ | H6: ='Company information'!H9
A7: ល.រ | B7: បរិយាយ | C7: ប្រតិវេទន៍គយនាំចូល/វិក្កយបត្រ | E7: បង្កាន់ដៃទទួលប្រាក់ | G7: ប្រាក់អាករ (រៀល) | H7: ផ្សេងៗ
C8: លេខ | D8: ចុះថ្ងៃទី ខែ ឆ្នាំ | E8: លេខ | F8: ថ្ងៃ ខែ ឆ្នាំ
A9: 1 | C9: I821 | D9: 43857 | G9: 5671447
A10: 2 | C10: I820 | D10: 43857 | G10: 3115425
A11: 3 | C11: I608 | D11: 43850 | G11: 10824695
A12: 4 | C12: I609 | D12: 43843 | G12: 5811817
A13: 5 | C13: I459 | D13: 43845 | G13: 7391034
A14: 6 | B14: COMPUTER | C14: I292 | D14: 44207 | G14: 216700
A15: 7 | B15: AWNING ADAPTER METAL PRODUCTS PAPER SLIPSHEET PLASTIC ACCESSORIE A LIGHT BULB | C15: I291 | D15: 44207 | G15: 31606500
A16: 8 | B16: BATTERY COPPER PRODUCTS LED COPPER WIRE LAMPE LIGHT BULB METAL PRODUCTS PLASTIC ACCESSORIE A PLASTIC TUBE PRINTED CIRUIT BOARD ASSEMBLY SCREW SOLAR PANEL WIRE | C16: I242 | D16: 44204 | G16: 15832100
A17: 9 | B17: METAL PRODUCTS WOOD PRODUCTS | C17: I235 | D17: 44204 | G17: 5990300
A18: 10 | C18: I236 | D18: 44204 | G18: 13990100
A19: 11 | C19: I237 | D19: 44204 | G19: 6094100
A20: 12 | C20: I688 | D20: 44215 | G20: 120512600
A21: 13 | C21: I1016 | D21: 44222 | G21: 5723300
A22: 14 | C22: I961 | D22: 44221 | G22: 31514400
A23: 15 | C23: I1010 | D23: 44222 | G23: 82195100
A24: 16 | C24: I1183 | D24: 44224 | G24: 649700
A25: 17 | C25: I468 | D25: 44209 | G25: 18227300
A26: 18 | C26: I544 | D26: 44211 | G26: 55579000
A27: 19 | C27: I466 | D27: 44209 | G27: 688200
A28: 20 | C28: I707 | D28: 44215 | G28: 45324500
A29: 21 | C29: I240 | D29: 44204 | G29: 65935300
A30: 22 | B30: Import Raw Material | C30: I15369 | D30: 44562 | G30: 73348100
A31: 23 | B31: Import Raw Material | C31: I15321 | D31: 44562 | G31: 113862800
A32: 24 | B32: Import Raw Material | C32: I15323 | D32: 44562 | G32: 72377500
A33: 25 | B33: PLASTIC INJECTTION PRODUCTS,PRINTED CIRCUIT BOARD ASSEMBLY ,LIGHT BULB ... | C33: I1157 | D33: 44952 | G33: 39785000
A34: 26 | B34: PAPER BOARD ,COLOR BOX | C34: I1168 | D34: 44952 | G34: 4580700
A35: 27 | B35: IRON SHEET FRAME,PRINTED CIRCUIT BOARD ASSEMBLY ... | C35: I1166 | D35: 44952 | G35: 8832200
A36: 28 | B36: PRINTED CIRCUIT BOARD ASSEMBLY ,PLASTIC SPRAYING POWER (9),IRON WIRE (10)... | C36: I1162 | D36: 44952 | G36: 15314800
A37: 29 | B37: MOLD (INJECTION),IRON TUBE FRAME ,STRECH FILM | C37: I792 | D37: 44945 | G37: 8562800
A38: 30 | B38: IRON SHEET FRAME | C38: I791 | D38: 44945 | G38: 6542700
A39: 31 | B39: PLASTIC TUBE ,SOLAR PANELS (7),PLASTIC (BLOWN, INJECTION )PRODUCTS... | C39: I772 | D39: 44944 | G39: 10671300
A40: 32 | B40: SCREW (11),PRINTED CIRCUIT BOARD ASSEMBLY ,PLASTIC SPRAYING POWER (9)... | C40: I716 | D40: 44944 | G40: 13793200
...

Sheet Annex II-IM Non-State Charge
A1: តារាងឧបសម្ព័ន្ធ II
A2: តារាងផ្ទៀងផ្ទាត់បញ្ជាក់អំពីអាករលើធាតុចូលដែលអាចស្នើសុំជាឥណទាន
A3: ( ការនាំចូល ឬ អាករគិតជំនួស(Reverse Charge))
A4: ក្រុមហ៊ុន៖ | B4: ='Company information'!D2 | G4: សវនករពន្ធដារ៖ | H4: ='Company information'!D8
A5: លេខ អតប៖ | B5: ='Company information'!D4 | H5: ='Company information'!E8
A6: ='Company information'!E8 | G6: ទឹកប្រាក់ស្នើសុំបង្វិលសងចំនួន៖ | H6: ='Company information'!H9
A7: ល.រ | B7: បរិយាយ | C7: ប្រតិវេទន៍គយនាំចូល/ វិក្កយបត្រ | E7: បង្កាន់ដៃទទួលប្រាក់ | G7: ប្រាក់អាករ (រៀល) | H7: លទ្ធផលផ្ទៀងផ្ទាត់ជាមួយទិន្នន័យពីអគ្គនាយកដ្ឋានគយ/ ឬ អាករគិតជំនួស(Reverse Charge) | I7: ទឹកប្រាក់អនុញ្ញាត
C8: លេខ | D8: ចុះថ្ងៃទី ខែ ឆ្នាំ | E8: លេខ | F8: ថ្ងៃ ខែ ឆ្នាំ | J8: ខ្វះ
A10: I. ការនាំចូល
A11: 1 | C11: I2933 | D11: 43910 | G11: 86294 | I11: 85000 | J11: =G11-I11 | K11: test
A12: 2 | B12: Stretch Film | C12: I3963 | D12: 44287 | G12: 4225100 | I12: 1549751 | J12: =G12-I12
A13: 3 | B13: COB Light board | C13: I5395 | D13: 44337 | G13: 229500 | I13: 0 | J13: =G13-I13
A14: 4 | B14: Lamp holder | C14: I5399 | D14: 44337 | G14: 495400 | I14: 0 | J14: =G14-I14
A15: 5 | B15: ELECTRODE SLICE | C15: I8833 | D15: 44743 | G15: 3300 | I15: 0 | J15: =G15-I15
A16: 6 | B16: Industrial glasses | C16: I8938. | D16: 44414 | G16: 44200 | I16: 0 | J16: =G16-I16
A17: 7 | B17: Industrial glover | C17: I8938 | D17: 44414 | G17: 16300 | I17: 0 | J17: =G17-I17
A18: 8 | B18: Iron stand | C18: I9185 | D18: 44420 | G18: 258400 | I18: 0 | J18: =G18-I18
A19: 9 | B19: Iron tube | C19: I9187 | D19: 44420 | G19: 3710600 | I19: 0 | J19: =G19-I19
A20: 10 | B20: IRON STAND | C20: I10359. | D20: 44446 | G20: 518400 | I20: 0 | J20: =G20-I20
A21: 11 | B21: Import Raw Material | C21: I10761 | D21: 44455 | G21: 65700 | I21: 0 | J21: =G21-I21
A22: 12 | C22: I9794 | D22: 44110 | G22: 1047700 | I22: 0 | J22: =G22-I22
A23: 13 | C23: I12103 | D23: 43810 | G23: 248568 | I23: 0 | J23: =G23-I23
A24: II. អាករលើតម្លៃបន្ថែមតាមវិធីគិតអាករជំនួស(Reverse Charge)
A25: 1 | B25: Online serivce | C25: 01-02-2024 | D25: 19108.4 | G25: 19108.4 | H25: អនុញ្ញាត (បានប្រកាស) | I25: =G25 | J25: =G25-I25
A26: 2 | B26: Online service | C26: 01-02-2024 | D26: 19042.9 | G26: 19042.9 | H26: អនុញ្ញាត (បានប្រកាស) | I26: =G26 | J26: =G26-I26
A27: 3 | B27: Software License | C27: 26-02-2024 | D27: 203450 | G27: 203450 | H27: អនុញ្ញាត (បានប្រកាស) | I27: =G27 | J27: =G27-I27
A28: 4 | B28: Online Service | C28: 01-03-2024 | D28: 18911.9 | G28: 18911.9 | H28: អនុញ្ញាត (បានប្រកាស) | I28: =G28 | J28: =G28-I28
A29: 5 | B29: Online Service | C29: 01-05-2024 | D29: 19155.2 | G29: 19155.2 | H29: អនុញ្ញាត (បានប្រកាស) | I29: =G29 | J29: =G29-I29
A30: 6 | B30: Online Service | C30: 01-06-2024 | D30: 19234.8 | G30: 19234.8 | H30: អនុញ្ញាត (បានប្រកាស) | I30: =G30 | J30: =G30-I30
A31: 7 | B31: Online Service | C31: 01-07-2024 | D31: 19225.4 | G31: 19225.4 | H31: អនុញ្ញាត (បានប្រកាស) | I31: =G31 | J31: =G31-I31
A32: 8 | B32: Online Services | C32: 01-08-2024 | D32: 18986.8 | G32: 18986.8 | H32: អនុញ្ញាត (បានប្រកាស) | I32: =G32 | J32: =G32-I32
A33: 9 | B33: Online Services | C33: 28-09-2024 | D33: 19005.5 | G33: 19005.5 | H33: អនុញ្ញាត (បានប្រកាស) | I33: =G33 | J33: =G33-I33
A34: 10 | B34: Online Services | C34: 01-09-2024 | D34: 19005.5 | G34: 19005.5 | H34: អនុញ្ញាត (បានប្រកាស) | I34: =G34 | J34: =G34-I34
A35: 11 | B35: Online Services | C35: 28-10-2024 | D35: 19014.8 | G35: 19014.8 | H35: អនុញ្ញាត (បានប្រកាស) | I35: =G35 | J35: =G35-I35
A36: 12 | B36: Online Service | C36: 28-11-2024 | D36: 18851 | G36: 18851 | H36: អនុញ្ញាត (បានប្រកាស) | I36: =G36 | J36: =G36-I36
A37: 13 | B37: Online Services | C37: 28-12-2024 | D37: 18837 | G37: 18837 | H37: អនុញ្ញាត (បានប្រកាស) | I37: =G37 | J37: =G37-I37
A38: សរុបអាករលើការនាំចូល ឬ អាករលើតម្លៃបន្ថែមតាមវិធីគិតអាករជំនួស(Reverse Charge) | G38: =SUM(G11:G37) | H38: សរុបទឺកប្រាក់អនុញ្ញាត | I38: =SUM(I11:I37) | J38: =SUM(J11:J37)
A40: សេចក្តីធានាអះអាងរបស់មន្ត្រីសវនករទទួលបន្ទុក៖ លទ្ធផលផ្ទៀងផ្ទាត់ឥណទានអាករ ចំពោះការនាំចូល ឬ/និង អាករលើតម្លៃបន្ថែមតាមវិធីគិតអាករជំនួស(Reverse Charge)ខាងលើពិតជាត្រឹមត្រូវតាមរបាយការណ៍លម្អិតដែលបានទាញទិន្នន័យពីអគ្គនាយកដ្ឋានគយ/ប្រព័ន្ធE-Filing ពិតប្រាកដមែន។
E43: រាជធានីភ្នំពេញ.ថ្ងៃទី ខែ ឆ្នាំ
E44: មន្ត្រីសវនកម្ម
...

Sheet AnnexIII-Local Pur
A1: តារាងឧបសម្ព័ន្ធ III
A2: តារាងផ្ទៀងផ្ទាត់បញ្ជាក់អំពីអាករលើធាតុចូលដែលអាចស្នើសុំជាឥណទាន
A3: (ការទិញក្នុងស្រុក)
A4: ក្រុមហ៊ុន៖ | B4: ='Company information'!D2 | I4: សវនករពន្ធដារ៖ | K4: ='Company information'!D8
A5: លេខ អតប៖ | B5: ='Company information'!D4 | K5: ='Company information'!E8 | N5: FOR REPORT | V5: សម្គាល់ផ្សេងៗ | X5: បញ្ចូលទិន្នន័យ
A6: ='Company information'!E8 | I6: ទឹកប្រាក់ស្នើសុំបង្វិលសងចំនួន៖ | J6: ='Company information'!H9
A7: ល.រ | B7: បរិយាយ | C7: អ្នកផ្គត់ផ្គង់ | D7: លេខ អតប | E7: វិក្កយបត្រ | G7: ទឹកប្រាក់អាករ | J7: ស្ថានភាព | K7: ស្ថានភាពអ្នកប្រើប្រាស់ | L7: មតិអ្នកប្រើប្រាស់ | M7: ផ្សេង (សម្គាល់) | Q7: PURCHASE | R7: SUPPLIER | S7: VAR INVOICE T/F | T7: VAR. DATE T/F | U7: VAR. SUPPLIER & PUCHASER | V7: តេស្តទឹកប្រាក់លម្អៀង | W7: សម្កាល់ | X7: កាលបរិច្ឆេទ | Y7: លេខវិក្កយបត្រ ឬប្រតិវេទគយ | Z7: លេខលិខិតជូនដំណឹងឥណទាន | AA7: អ្នកទិញ | AD7: តម្លៃសរុបលើវិក្កយបត្រ | AE7: តម្លៃ​​មិន​រួមអតប និងមិនជាប់​អតប​ | AG7: អាករលើតម្លៃបន្ថែមអត្រា ០% | AH7: អាករលើតម្លៃបន្ថែម | AJ7: អាករលើតម្លៃបន្ថែម(បន្ទុករដ្ឋ) | AK7: អតប កាត់ទុកដោយរតនាគារជាតិ | AL7: អាករបំភ្លឺសាធារណៈ | AM7: អាករពិសេសលើទំនិញមួយចំនួន | AN7: អាករពិសេសលើសេវាមួយចំនួន | AO7: អាករលើការស្នាក់នៅ | AP7: អត្រាប្រាក់រំដោះពន្ធលើប្រាក់ចំណូល | AQ7: កំណត់សម្គាល់ | AR7: បរិយាយ | AS7: ស្ថានភាពប្រកាសពន្ធ
E8: លេខ | F8: ថ្ងៃ ខែ ឆ្នាំ | G8: ជាដុល្លារអាមេរិក | H8: អត្រា | I8: ជារៀល | N8: បានប្រកាស | O8: នៅខ្វះ | P8: ស្ថានភាពត្រួតពិនិត្យ | AA8: ប្រភេទ | AB8: លេខសម្គាល់ចុះបញ្ជីពន្ធដា | AC8: ឈ្មោះ | AE8: តម្លៃមិនរួមអតប | AF8: ការលក់មិនជាប់អតប | AH8: ការលក់ក្នុងស្រុក | AI8: អតបលើការនាំចេញ
A9: 1 | C9: អ៊ីជីអេហ្វ ឡូជីស្ទីក ខូ អិលធីឌី | D9: L001-901501877 | E9: 2001007 | F9: 43861 | G9: 279450 | I9: 279450 | J9: =IF(AND(S9=TRUE, T9=TRUE, U9=TRUE), IF(W9<-0.05, "អនុញ្ញាត (អ្នកផ្គត់ផ្គង់ប្រកាសខ្វះ)", "បានប្រកាស (អនុញ្ញាត)"), IF(AND(S9=FALSE, T9=FALSE, U9=FALSE), "ព្យួរទុក (មិនមានទិន្នន័យ)", "ប្រកាសខុស (ព្យួរទុក)")) | N9: =IF(W9<0,AH9,I9) | O9: =I9-M9 | Q9: 2001007 | R9: 2001007 | S9: =Q9=R9 | T9: =AND(MONTH(F9)=MONTH(X9), YEAR(F9)=YEAR(X9)) | U9: =AND(AB9<>"", 'Company information'!D$4<>"", RIGHT(SUBSTITUTE(AB9,"-",""),9)=RIGHT(SUBSTITUTE('Company information'!D$4,"-",""),9)) | V9: =AH9-I9 | X9: 43861 | Y9: 2001007 | AA9: បុគ្គលជាប់អាករ | AB9: L001-901905215 | AC9: វីអ៊ីស៊ិន (ខេមបូឌា) អ៊ិនដាសស្ទ្រី ឯ.ក | AD9: 3073950 | AE9: 2794500 | AF9: 0 | AG9: 123 | AH9: 279450 | AI9: 0 | AJ9: 0 | AK9: 0 | AL9: 0 | AM9: 0 | AN9: 0 | AO9: 0 | AP9: 0 | AS9: បានប្រកាសពន្ធ
A10: 2 | C10: អិនខេ ត្រេឌីង (ខេមបូឌា) ឯ.ក | D10: K009-901700707 | E10: NK00006 | F10: 43844 | G10: 406000 | I10: 406000 | J10: =IF(AND(S10=TRUE, T10=TRUE, U10=TRUE), IF(W10<-0.05, "អនុញ្ញាត (អ្នកផ្គត់ផ្គង់ប្រកាសខ្វះ)", "បានប្រកាស (អនុញ្ញាត)"), IF(AND(S10=FALSE, T10=FALSE, U10=FALSE), "ព្យួរទុក (មិនមានទិន្នន័យ)", "ប្រកាសខុស (ព្យួរទុក)")) | N10: =IF(W10<0,AH10,I10) | O10: =I10-M10 | Q10: NK00006 | R10: NK-00006 | S10: =Q10=R10 | T10: =AND(MONTH(F10)=MONTH(X10), YEAR(F10)=YEAR(X10)) | U10: =AND(AB10<>"", 'Company information'!D$4<>"", RIGHT(SUBSTITUTE(AB10,"-",""),9)=RIGHT(SUBSTITUTE('Company information'!D$4,"-",""),9)) | V10: =AH10-I10 | X10: 43844 | Y10: NK-00006 | AA10: បុគ្គលជាប់អាករ | AB10: L001-901905215 | AC10: វីអ៊ីស៊ិន (ខេមបូឌា) អ៊ិនដាសស្ទ្រី ឯ.ក | AD10: 4455000 | AE10: 4050000 | AF10: 0 | AG10: 0 | AH10: 405000 | AI10: 0 | AJ10: 0 | AK10: 0 | AL10: 0 | AM10: 0 | AN10: 0 | AO10: 0 | AP10: 0 | AS10: បានប្រកាសពន្ធ
A11: 3 | C11: ថេកអេស៊ីស៊ី ផេភើរ សឺវីស ខនសាល់ធេន ឯ.ក | D11: K004-901801112 | E11: 000013 | F11: 44105 | G11: 162800 | I11: 162800 | J11: =IF(AND(S11=TRUE, T11=TRUE, U11=TRUE), IF(W11<-0.05, "អនុញ្ញាត (អ្នកផ្គត់ផ្គង់ប្រកាសខ្វះ)", "បានប្រកាស (អនុញ្ញាត)"), IF(AND(S11=FALSE, T11=FALSE, U11=FALSE), "ព្យួរទុក (មិនមានទិន្នន័យ)", "ប្រកាសខុស (ព្យួរទុក)")) | N11: =IF(W11<0,AH11,I11) | O11: =I11-M11 | Q11: 000013 | R11: 000013 | S11: =Q11=R11 | T11: =AND(MONTH(F11)=MONTH(X11), YEAR(F11)=YEAR(X11)) | U11: =AND(AB11<>"", 'Company information'!D$4<>"", RIGHT(SUBSTITUTE(AB11,"-",""),9)=RIGHT(SUBSTITUTE('Company information'!D$4,"-",""),9)) | V11: =AH11-I11 | X11: 43840 | Y11: 000013 | AA11: បុគ្គលជាប់អាករ | AB11: L001-901905215 | AC11: វីអ៊ីស៊ិន (ខេមបូឌា) អ៊ិនដាសស្ទ្រី ឯ.ក | AD11: 1790800 | AE11: 1628000 | AF11: 0 | AG11: 0 | AH11: 162800 | AI11: 0 | AJ11: 0 | AK11: 0 | AL11: 0 | AM11: 0 | AN11: 0 | AO11: 0 | AP11: 0 | AS11: បានប្រកាសពន្ធ
A12: 4 | C12: ប្យួរ៉ូ វេរីតាស (ខេមបូឌា) លីមីធីត | D12: L001-107024462 | E12: 59006679 | F12: 43861 | G12: 67073 | I12: 67073 | J12: =IF(AND(S12=TRUE, T12=TRUE, U12=TRUE), IF(W12<-0.05, "អនុញ្ញាត (អ្នកផ្គត់ផ្គង់ប្រកាសខ្វះ)", "បានប្រកាស (អនុញ្ញាត)"), IF(AND(S12=FALSE, T12=FALSE, U12=FALSE), "ព្យួរទុក (មិនមានទិន្នន័យ)", "ប្រកាសខុស (ព្យួរទុក)")) | N12: =IF(W12<0,AH12,I12) | O12: =I12-M12 | Q12: 59006679 | R12: 59006679 | S12: =Q12=R12 | T12: =AND(MONTH(F12)=MONTH(X12), YEAR(F12)=YEAR(X12)) | U12: =AND(AB12<>"", 'Company information'!D$4<>"", RIGHT(SUBSTITUTE(AB12,"-",""),9)=RIGHT(SUBSTITUTE('Company information'!D$4,"-",""),9)) | V12: =AH12-I12 | X12: 43861 | Y12: 59006679 | AA12: បុគ្គលជាប់អាករ | AB12: L001-901905215 | AC12: វីអ៊ីស៊ិន (ខេមបូឌា) អ៊ិនដាសស្ទ្រី ឯ.ក | AD12: 737797 | AE12: 670725 | AF12: 0 | AG12: 0 | AH12: 67072 | AI12: 0 | AJ12: 0 | AK12: 0 | AL12: 0 | AM12: 0 | AN12: 0 | AO12: 0 | AP12: 0 | AS12: បានប្រកាសពន្ធ
A13: 5 | C13: ប្យួរ៉ូ វេរីតាស (ខេមបូឌា) លីមីធីត | D13: L001-107024462 | E13: 59006668 | F13: 43861 | G13: 102845 | I13: 102845 | J13: =IF(AND(S13=TRUE, T13=TRUE, U13=TRUE), IF(W13<-0.05, "អនុញ្ញាត (អ្នកផ្គត់ផ្គង់ប្រកាសខ្វះ)", "បានប្រកាស (អនុញ្ញាត)"), IF(AND(S13=FALSE, T13=FALSE, U13=FALSE), "ព្យួរទុក (មិនមានទិន្នន័យ)", "ប្រកាសខុស (ព្យួរទុក)")) | N13: =IF(W13<0,AH13,I13) | O13: =I13-M13 | Q13: 59006668 | R13: 59006668 | S13: =Q13=R13 | T13: =AND(MONTH(F13)=MONTH(X13), YEAR(F13)=YEAR(X13)) | U13: =AND(AB13<>"", 'Company information'!D$4<>"", RIGHT(SUBSTITUTE(AB13,"-",""),9)=RIGHT(SUBSTITUTE('Company information'!D$4,"-",""),9)) | V13: =AH13-I13 | X13: 43861 | Y13: 59006668 | AA13: បុគ្គលជាប់អាករ | AB13: L001-901905215 | AC13: វីអ៊ីស៊ិន (ខេមបូឌា) អ៊ិនដាសស្ទ្រី ឯ.ក | AD13: 1131289 | AE13: 1028445 | AF13: 0 | AG13: 0 | AH13: 102844 | AI13: 0 | AJ13: 0 | AK13: 0 | AL13: 0 | AM13: 0 | AN13: 0 | AO13: 0 | AP13: 0 | AS13: បានប្រកាសពន្ធ
A14: 6 | C14: ប្យួរ៉ូ វេរីតាស (ខេមបូឌា) លីមីធីត | D14: L001-107024462 | E14: 59006650 | F14: 43860 | G14: 134145 | I14: 134145 | J14: =IF(AND(S14=TRUE, T14=TRUE, U14=TRUE), IF(W14<-0.05, "អនុញ្ញាត (អ្នកផ្គត់ផ្គង់ប្រកាសខ្វះ)", "បានប្រកាស (អនុញ្ញាត)"), IF(AND(S14=FALSE, T14=FALSE, U14=FALSE), "ព្យួរទុក (មិនមានទិន្នន័យ)", "ប្រកាសខុស (ព្យួរទុក)")) | N14: =IF(W14<0,AH14,I14) | O14: =I14-M14 | Q14: 59006650 | R14: 59006650 | S14: =Q14=R14 | T14: =AND(MONTH(F14)=MONTH(X14), YEAR(F14)=YEAR(X14)) | U14: =AND(AB14<>"", 'Company information'!D$4<>"", RIGHT(SUBSTITUTE(AB14,"-",""),9)=RIGHT(SUBSTITUTE('Company information'!D$4,"-",""),9)) | V14: =AH14-I14 | X14: 43860 | Y14: 59006650 | AA14: បុគ្គលជាប់អាករ | AB14: L001-901905215 | AC14: វីអ៊ីស៊ិន (ខេមបូឌា) អ៊ិនដាសស្ទ្រី ឯ.ក | AD14: 1475595 | AE14: 1341450 | AF14: 0 | AG14: 0 | AH14: 134145 | AI14: 0 | AJ14: 0 | AK14: 0 | AL14: 0 | AM14: 0 | AN14: 0 | AO14: 0 | AP14: 0 | AS14: បានប្រកាសពន្ធ
A15: 7 | C15: ប្យួរ៉ូ វេរីតាស (ខេមបូឌា) លីមីធីត | D15: L001-107024462 | E15: 59006649 | F15: 43860 | G15: 67073 | I15: 67073 | J15: =IF(AND(S15=TRUE, T15=TRUE, U15=TRUE), IF(W15<-0.05, "អនុញ្ញាត (អ្នកផ្គត់ផ្គង់ប្រកាសខ្វះ)", "បានប្រកាស (អនុញ្ញាត)"), IF(AND(S15=FALSE, T15=FALSE, U15=FALSE), "ព្យួរទុក (មិនមានទិន្នន័យ)", "ប្រកាសខុស (ព្យួរទុក)")) | N15: =IF(W15<0,AH15,I15) | O15: =I15-M15 | Q15: 59006649 | R15: 59006649 | S15: =Q15=R15 | T15: =AND(MONTH(F15)=MONTH(X15), YEAR(F15)=YEAR(X15)) | U15: =AND(AB15<>"", 'Company information'!D$4<>"", RIGHT(SUBSTITUTE(AB15,"-",""),9)=RIGHT(SUBSTITUTE('Company information'!D$4,"-",""),9)) | V15: =AH15-I15 | X15: 43860 | Y15: 59006649 | Z15: 123 | AA15: បុគ្គលជាប់អាករ | AB15: L001-901905215 | AC15: វីអ៊ីស៊ិន (ខេមបូឌា) អ៊ិនដាសស្ទ្រី ឯ.ក | AD15: 737797 | AE15: 670725 | AF15: 0 | AG15: 0 | AH15: 67072 | AI15: 0 | AJ15: 0 | AK15: 0 | AL15: 0 | AM15: 0 | AN15: 0 | AO15: 0 | AP15: 0 | AS15: បានប្រកាសពន្ធ
A16: 8 | C16: ប្យួរ៉ូ វេរីតាស (ខេមបូឌា) លីមីធីត | D16: L001-107024462 | E16: 59006619 | F16: 43850 | G16: 399590 | I16: 399590 | J16: =IF(AND(S16=TRUE, T16=TRUE, U16=TRUE), IF(W16<-0.05, "អនុញ្ញាត (អ្នកផ្គត់ផ្គង់ប្រកាសខ្វះ)", "បានប្រកាស (អនុញ្ញាត)"), IF(AND(S16=FALSE, T16=FALSE, U16=FALSE), "ព្យួរទុក (មិនមានទិន្នន័យ)", "ប្រកាសខុស (ព្យួរទុក)")) | N16: =IF(W16<0,AH16,I16) | O16: =I16-M16 | Q16: 59006619 | R16: 59006619 | S16: =Q16=R16 | T16: =AND(MONTH(F16)=MONTH(X16), YEAR(F16)=YEAR(X16)) | U16: =AND(AB16<>"", 'Company information'!D$4<>"", RIGHT(SUBSTITUTE(AB16,"-",""),9)=RIGHT(SUBSTITUTE('Company information'!D$4,"-",""),9)) | V16: =AH16-I16 | X16: 43850 | Y16: 59006619 | AA16: បុគ្គលជាប់អាករ | AB16: L001-901905215 | AC16: វីអ៊ីស៊ិន (ខេមបូឌា) អ៊ិនដាសស្ទ្រី ឯ.ក | AD16: 4395484 | AE16: 3995895 | AF16: 0 | AG16: 0 | AH16: 399589 | AI16: 0 | AJ16: 0 | AK16: 0 | AL16: 0 | AM16: 0 | AN16: 0 | AO16: 0 | AP16: 0 | AS16: បានប្រកាសពន្ធ
A17: 9 | C17: ប្យួរ៉ូ វេរីតាស (ខេមបូឌា) លីមីធីត | D17: L001-107024462 | E17: 59006612 | F17: 43848 | G17: 67073 | I17: 67073 | J17: =IF(AND(S17=TRUE, T17=TRUE, U17=TRUE), IF(W17<-0.05, "អនុញ្ញាត (អ្នកផ្គត់ផ្គង់ប្រកាសខ្វះ)", "បានប្រកាស (អនុញ្ញាត)"), IF(AND(S17=FALSE, T17=FALSE, U17=FALSE), "ព្យួរទុក (មិនមានទិន្នន័យ)", "ប្រកាសខុស (ព្យួរទុក)")) | N17: =IF(W17<0,AH17,I17) | O17: =I17-M17 | Q17: 59006612 | R17: 59006612 | S17: =Q17=R17 | T17: =AND(MONTH(F17)=MONTH(X17), YEAR(F17)=YEAR(X17)) | U17: =AND(AB17<>"", 'Company information'!D$4<>"", RIGHT(SUBSTITUTE(AB17,"-",""),9)=RIGHT(SUBSTITUTE('Company information'!D$4,"-",""),9)) | V17: =AH17-I17 | X17: 43848 | Y17: 59006612 | AA17: បុគ្គលជាប់អាករ | AB17: L001-901905215 | AC17: វីអ៊ីស៊ិន (ខេមបូឌា) អ៊ិនដាសស្ទ្រី ឯ.ក | AD17: 737797 | AE17: 670725 | AF17: 0 | AG17: 0 | AH17: 67072 | AI17: 0 | AJ17: 0 | AK17: 0 | AL17: 0 | AM17: 0 | AN17: 0 | AO17: 0 | AP17: 0 | AS17: បានប្រកាសពន្ធ
A18: 10 | C18: ប្យួរ៉ូ វេរីតាស (ខេមបូឌា) លីមីធីត | D18: L001-107024462 | E18: 59006582 | F18: 43847 | G18: 134145 | I18: 134145 | J18: =IF(AND(S18=TRUE, T18=TRUE, U18=TRUE), IF(W18<-0.05, "អនុញ្ញាត (អ្នកផ្គត់ផ្គង់ប្រកាសខ្វះ)", "បានប្រកាស (អនុញ្ញាត)"), IF(AND(S18=FALSE, T18=FALSE, U18=FALSE), "ព្យួរទុក (មិនមានទិន្នន័យ)", "ប្រកាសខុស (ព្យួរទុក)")) | N18: =IF(W18<0,AH18,I18) | O18: =I18-M18 | Q18: 59006582 | R18: 59006582 | S18: =Q18=R18 | T18: =AND(MONTH(F18)=MONTH(X18), YEAR(F18)=YEAR(X18)) | U18: =AND(AB18<>"", 'Company information'!D$4<>"", RIGHT(SUBSTITUTE(AB18,"-",""),9)=RIGHT(SUBSTITUTE('Company information'!D$4,"-",""),9)) | V18: =AH18-I18 | X18: 43847 | Y18: 59006582 | AA18: បុគ្គលជាប់អាករ | AB18: L001-901905215 | AC18: វីអ៊ីស៊ិន (ខេមបូឌា) អ៊ិនដាសស្ទ្រី ឯ.ក | AD18: 1475595 | AE18: 1341450 | AF18: 0 | AG18: 0 | AH18: 134145 | AI18: 0 | AJ18: 0 | AK18: 0 | AL18: 0 | AM18: 0 | AN18: 0 | AO18: 0 | AP18: 0 | AS18: បានប្រកាសពន្ធ
A19: 11 | C19: ប្យួរ៉ូ វេរីតាស (ខេមបូឌា) លីមីធីត | D19: L001-107024462 | E19: 59006581 | F19: 43847 | G19: 134145 | I19: 134145 | J19: =IF(AND(S19=TRUE, T19=TRUE, U19=TRUE), IF(W19<-0.05, "អនុញ្ញាត (អ្នកផ្គត់ផ្គង់ប្រកាសខ្វះ)", "បានប្រកាស (អនុញ្ញាត)"), IF(AND(S19=FALSE, T19=FALSE, U19=FALSE), "ព្យួរទុក (មិនមានទិន្នន័យ)", "ប្រកាសខុស (ព្យួរទុក)")) | N19: =IF(W19<0,AH19,I19) | O19: =I19-M19 | Q19: 59006581 | R19: 59006581 | S19: =Q19=R19 | T19: =AND(MONTH(F19)=MONTH(X19), YEAR(F19)=YEAR(X19)) | U19: =AND(AB19<>"", 'Company information'!D$4<>"", RIGHT(SUBSTITUTE(AB19,"-",""),9)=RIGHT(SUBSTITUTE('Company information'!D$4,"-",""),9)) | V19: =AH19-I19 | X19: 43847 | Y19: 59006581 | AA19: បុគ្គលជាប់អាករ | AB19: L001-901905215 | AC19: វីអ៊ីស៊ិន (ខេមបូឌា) អ៊ិនដាសស្ទ្រី ឯ.ក | AD19: 1475595 | AE19: 1341450 | AF19: 0 | AG19: 0 | AH19: 134145 | AI19: 0 | AJ19: 0 | AK19: 0 | AL19: 0 | AM19: 0 | AN19: 0 | AO19: 0 | AP19: 0 | AS19: បានប្រកាសពន្ធ
A20: 12 | C20: ប្យួរ៉ូ វេរីតាស (ខេមបូឌា) លីមីធីត | D20: L001-107024462 | E20: 59006580 | F20: 43847 | G20: 67073 | I20: 67073 | J20: =IF(AND(S20=TRUE, T20=TRUE, U20=TRUE), IF(W20<-0.05, "អនុញ្ញាត (អ្នកផ្គត់ផ្គង់ប្រកាសខ្វះ)", "បានប្រកាស (អនុញ្ញាត)"), IF(AND(S20=FALSE, T20=FALSE, U20=FALSE), "ព្យួរទុក (មិនមានទិន្នន័យ)", "ប្រកាសខុស (ព្យួរទុក)")) | N20: =IF(W20<0,AH20,I20) | O20: =I20-M20 | Q20: 59006580 | R20: 59006580 | S20: =Q20=R20 | T20: =AND(MONTH(F20)=MONTH(X20), YEAR(F20)=YEAR(X20)) | U20: =AND(AB20<>"", 'Company information'!D$4<>"", RIGHT(SUBSTITUTE(AB20,"-",""),9)=RIGHT(SUBSTITUTE('Company information'!D$4,"-",""),9)) | V20: =AH20-I20 | X20: 43847 | Y20: 59006580 | AA20: បុគ្គលជាប់អាករ | AB20: L001-901905215 | AC20: វីអ៊ីស៊ិន (ខេមបូឌា) អ៊ិនដាសស្ទ្រី ឯ.ក | AD20: 737797 | AE20: 670725 | AF20: 0 | AG20: 0 | AH20: 67072 | AI20: 0 | AJ20: 0 | AK20: 0 | AL20: 0 | AM20: 0 | AN20: 0 | AO20: 0 | AP20: 0 | AS20: បានប្រកាសពន្ធ
A21: 13 | C21: ប្យួរ៉ូ វេរីតាស (ខេមបូឌា) លីមីធីត | D21: L001-107024462 | E21: 59006451 | F21: 43846 | G21: 67073 | I21: 67073 | J21: =IF(AND(S21=TRUE, T21=TRUE, U21=TRUE), IF(W21<-0.05, "អនុញ្ញាត (អ្នកផ្គត់ផ្គង់ប្រកាសខ្វះ)", "បានប្រកាស (អនុញ្ញាត)"), IF(AND(S21=FALSE, T21=FALSE, U21=FALSE), "ព្យួរទុក (មិនមានទិន្នន័យ)", "ប្រកាសខុស (ព្យួរទុក)")) | N21: =IF(W21<0,AH21,I21) | O21: =I21-M21 | Q21: 59006451 | R21: 59006451 | S21: =Q21=R21 | T21: =AND(MONTH(F21)=MONTH(X21), YEAR(F21)=YEAR(X21)) | U21: =AND(AB21<>"", 'Company information'!D$4<>"", RIGHT(SUBSTITUTE(AB21,"-",""),9)=RIGHT(SUBSTITUTE('Company information'!D$4,"-",""),9)) | V21: =AH21-I21 | X21: 43843 | Y21: 59006451 | AA21: បុគ្គលជាប់អាករ | AB21: L001-901700229 | AC21: ឈី មីង ស៊ីន ហ្វេកធើរី ឯ.ក | AD21: 18333 | AE21: 16666 | AF21: 0 | AG21: 0 | AH21: 1667 | AI21: 0 | AJ21: 0 | AK21: 0 | AL21: 0 | AM21: 0 | AN21: 0 | AO21: 0 | AP21: 0 | AS21: បានប្រកាសពន្ធ
A22: 14 | C22: ប្យួរ៉ូ វេរីតាស (ខេមបូឌា) លីមីធីត | D22: L001-107024462 | E22: 59006450 | F22: 43843 | G22: 229673 | I22: 229673 | J22: =IF(AND(S22=TRUE, T22=TRUE, U22=TRUE), IF(W22<-0.05, "អនុញ្ញាត (អ្នកផ្គត់ផ្គង់ប្រកាសខ្វះ)", "បានប្រកាស (អនុញ្ញាត)"), IF(AND(S22=FALSE, T22=FALSE, U22=FALSE), "ព្យួរទុក (មិនមានទិន្នន័យ)", "ប្រកាសខុស (ព្យួរទុក)")) | N22: =IF(W22<0,AH22,I22) | O22: =I22-M22 | Q22: 59006450 | R22: 59006450 | S22: =Q22=R22 | T22: =AND(MONTH(F22)=MONTH(X22), YEAR(F22)=YEAR(X22)) | U22: =AND(AB22<>"", 'Company information'!D$4<>"", RIGHT(SUBSTITUTE(AB22,"-",""),9)=RIGHT(SUBSTITUTE('Company information'!D$4,"-",""),9)) | V22: =AH22-I22 | X22: 43843 | Y22: 59006450 | Z22: 123 | AA22: បុគ្គលជាប់អាករ | AB22: L001-901905215 | AC22: វីអ៊ីស៊ិន (ខេមបូឌា) អ៊ិនដាសស្ទ្រី ឯ.ក | AD22: 2526397 | AE22: 2296725 | AF22: 0 | AG22: 0 | AH22: 229672 | AI22: 0 | AJ22: 0 | AK22: 0 | AL22: 0 | AM22: 0 | AN22: 0 | AO22: 0 | AP22: 0 | AS22: បានប្រកាសពន្ធ
A23: 15 | C23: ប្យួរ៉ូ វេរីតាស (ខេមបូឌា) លីមីធីត | D23: L001-107024462 | E23: 59006449 | F23: 43843 | G23: 229673 | I23: 229673 | J23: =IF(AND(S23=TRUE, T23=TRUE, U23=TRUE), IF(W23<-0.05, "អនុញ្ញាត (អ្នកផ្គត់ផ្គង់ប្រកាសខ្វះ)", "បានប្រកាស (អនុញ្ញាត)"), IF(AND(S23=FALSE, T23=FALSE, U23=FALSE), "ព្យួរទុក (មិនមានទិន្នន័យ)", "ប្រកាសខុស (ព្យួរទុក)")) | N23: =IF(W23<0,AH23,I23) | O23: =I23-M23 | Q23: 59006449 | R23: 59006449 | S23: =Q23=R23 | T23: =AND(MONTH(F23)=MONTH(X23), YEAR(F23)=YEAR(X23)) | U23: =AND(AB23<>"", 'Company information'!D$4<>"", RIGHT(SUBSTITUTE(AB23,"-",""),9)=RIGHT(SUBSTITUTE('Company information'!D$4,"-",""),9)) | V23: =AH23-I23 | X23: 43843 | Y23: 59006449 | AA23: បុគ្គលជាប់អាករ | AB23: L001-901905215 | AC23: វីអ៊ីស៊ិន (ខេមបូឌា) អ៊ិនដាសស្ទ្រី ឯ.ក | AD23: 2526397 | AE23: 2296725 | AF23: 0 | AG23: 0 | AH23: 229672 | AI23: 0 | AJ23: 0 | AK23: 0 | AL23: 0 | AM23: 0 | AN23: 0 | AO23: 0 | AP23: 0 | AS23: បានប្រកាសពន្ធ
A24: 16 | C24: ប្យួរ៉ូ វេរីតាស (ខេមបូឌា) លីមីធីត | D24: L001-107024462 | E24: 59006446 | F24: 44105 | G24: 67073 | I24: 67073 | J24: =IF(AND(S24=TRUE, T24=TRUE, U24=TRUE), IF(W24<-0.05, "អនុញ្ញាត (អ្នកផ្គត់ផ្គង់ប្រកាសខ្វះ)", "បានប្រកាស (អនុញ្ញាត)"), IF(AND(S24=FALSE, T24=FALSE, U24=FALSE), "ព្យួរទុក (មិនមានទិន្នន័យ)", "ប្រកាសខុស (ព្យួរទុក)")) | N24: =IF(W24<0,AH24,I24) | O24: =I24-M24 | Q24: 59006446 | R24: 59006446 | S24: =Q24=R24 | T24: =AND(MONTH(F24)=MONTH(X24), YEAR(F24)=YEAR(X24)) | U24: =AND(AB24<>"", 'Company information'!D$4<>"", RIGHT(SUBSTITUTE(AB24,"-",""),9)=RIGHT(SUBSTITUTE('Company information'!D$4,"-",""),9)) | V24: =AH24-I24 | X24: 43840 | Y24: 59006446 | AA24: បុគ្គលជាប់អាករ | AB24: L001-901905215 | AC24: វីអ៊ីស៊ិន (ខេមបូឌា) អ៊ិនដាសស្ទ្រី ឯ.ក | AD24: 737797 | AE24: 670725 | AF24: 0 | AG24: 0 | AH24: 67072 | AI24: 0 | AJ24: 0 | AK24: 0 | AL24: 0 | AM24: 0 | AN24: 0 | AO24: 0 | AP24: 0 | AS24: បានប្រកាសពន្ធ
A25: 17 | C25: ប្យួរ៉ូ វេរីតាស (ខេមបូឌា) លីមីធីត | D25: L001-107024462 | E25: 59006444 | F25: 44105 | G25: 256095 | I25: 256095 | J25: =IF(AND(S25=TRUE, T25=TRUE, U25=TRUE), IF(W25<-0.05, "អនុញ្ញាត (អ្នកផ្គត់ផ្គង់ប្រកាសខ្វះ)", "បានប្រកាស (អនុញ្ញាត)"), IF(AND(S25=FALSE, T25=FALSE, U25=FALSE), "ព្យួរទុក (មិនមានទិន្នន័យ)", "ប្រកាសខុស (ព្យួរទុក)")) | N25: =IF(W25<0,AH25,I25) | O25: =I25-M25 | Q25: 59006444 | R25: 59006444 | S25: =Q25=R25 | T25: =AND(MONTH(F25)=MONTH(X25), YEAR(F25)=YEAR(X25)) | U25: =AND(AB25<>"", 'Company information'!D$4<>"", RIGHT(SUBSTITUTE(AB25,"-",""),9)=RIGHT(SUBSTITUTE('Company information'!D$4,"-",""),9)) | V25: =AH25-I25 | X25: 43840 | Y25: 59006444 | AA25: បុគ្គលជាប់អាករ | AB25: L001-901905215 | AC25: វីអ៊ីស៊ិន (ខេមបូឌា) អ៊ិនដាសស្ទ្រី ឯ.ក | AD25: 2817045 | AE25: 2560950 | AF25: 0 | AG25: 0 | AH25: 256095 | AI25: 0 | AJ25: 0 | AK25: 0 | AL25: 0 | AM25: 0 | AN25: 0 | AO25: 0 | AP25: 0 | AS25: បានប្រកាសពន្ធ
A26: 18 | C26: ប្យួរ៉ូ វេរីតាស (ខេមបូឌា) លីមីធីត | D26: L001-107024462 | E26: 59006440 | F26: 44105 | G26: 134145 | I26: 134145 | J26: =IF(AND(S26=TRUE, T26=TRUE, U26=TRUE), IF(W26<-0.05, "អនុញ្ញាត (អ្នកផ្គត់ផ្គង់ប្រកាសខ្វះ)", "បានប្រកាស (អនុញ្ញាត)"), IF(AND(S26=FALSE, T26=FALSE, U26=FALSE), "ព្យួរទុក (មិនមានទិន្នន័យ)", "ប្រកាសខុស (ព្យួរទុក)")) | N26: =IF(W26<0,AH26,I26) | O26: =I26-M26 | Q26: 59006440 | R26: 59006440 | S26: =Q26=R26 | T26: =AND(MONTH(F26)=MONTH(X26), YEAR(F26)=YEAR(X26)) | U26: =AND(AB26<>"", 'Company information'!D$4<>"", RIGHT(SUBSTITUTE(AB26,"-",""),9)=RIGHT(SUBSTITUTE('Company information'!D$4,"-",""),9)) | V26: =AH26-I26 | X26: 43840 | Y26: 59006440 | AA26: បុគ្គលជាប់អាករ | AB26: L001-901905215 | AC26: វីអ៊ីស៊ិន (ខេមបូឌា) អ៊ិនដាសស្ទ្រី ឯ.ក | AD26: 1475595 | AE26: 1341450 | AF26: 0 | AG26: 0 | AH26: 134145 | AI26: 0 | AJ26: 0 | AK26: 0 | AL26: 0 | AM26: 0 | AN26: 0 | AO26: 0 | AP26: 0 | AS26: បានប្រកាសពន្ធ
A27: 19 | C27: ប្យួរ៉ូ វេរីតាស (ខេមបូឌា) លីមីធីត | D27: L001-107024462 | E27: 59006403 | F27: 44044 | G27: 189023 | I27: 189023 | J27: =IF(AND(S27=TRUE, T27=TRUE, U27=TRUE), IF(W27<-0.05, "អនុញ្ញាត (អ្នកផ្គត់ផ្គង់ប្រកាសខ្វះ)", "បានប្រកាស (អនុញ្ញាត)"), IF(AND(S27=FALSE, T27=FALSE, U27=FALSE), "ព្យួរទុក (មិនមានទិន្នន័យ)", "ប្រកាសខុស (ព្យួរទុក)")) | N27: =IF(W27<0,AH27,I27) | O27: =I27-M27 | Q27: 59006403 | R27: 59006403 | S27: =Q27=R27 | T27: =AND(MONTH(F27)=MONTH(X27), YEAR(F27)=YEAR(X27)) | U27: =AND(AB27<>"", 'Company information'!D$4<>"", RIGHT(SUBSTITUTE(AB27,"-",""),9)=RIGHT(SUBSTITUTE('Company information'!D$4,"-",""),9)) | V27: =AH27-I27 | X27: 43838 | Y27: 59006403 | AA27: បុគ្គលជាប់អាករ | AB27: L001-901905215 | AC27: វីអ៊ីស៊ិន (ខេមបូឌា) អ៊ិនដាសស្ទ្រី ឯ.ក | AD27: 2079247 | AE27: 1890225 | AF27: 0 | AG27: 0 | AH27: 189022 | AI27: 0 | AJ27: 0 | AK27: 0 | AL27: 0 | AM27: 0 | AN27: 0 | AO27: 0 | AP27: 0 | AS27: បានប្រកាសពន្ធ
A28: 20 | C28: ប្យួរ៉ូ វេរីតាស (ខេមបូឌា) លីមីធីត | D28: L001-107024462 | E28: 59006359 | F28: 43983 | G28: 229673 | I28: 229673 | J28: =IF(AND(S28=TRUE, T28=TRUE, U28=TRUE), IF(W28<-0.05, "អនុញ្ញាត (អ្នកផ្គត់ផ្គង់ប្រកាសខ្វះ)", "បានប្រកាស (អនុញ្ញាត)"), IF(AND(S28=FALSE, T28=FALSE, U28=FALSE), "ព្យួរទុក (មិនមានទិន្នន័យ)", "ប្រកាសខុស (ព្យួរទុក)")) | N28: =IF(W28<0,AH28,I28) | O28: =I28-M28 | Q28: 59006359 | R28: 59006359 | S28: =Q28=R28 | T28: =AND(MONTH(F28)=MONTH(X28), YEAR(F28)=YEAR(X28)) | U28: =AND(AB28<>"", 'Company information'!D$4<>"", RIGHT(SUBSTITUTE(AB28,"-",""),9)=RIGHT(SUBSTITUTE('Company information'!D$4,"-",""),9)) | V28: =AH28-I28 | X28: 43836 | Y28: 59006359 | AA28: បុគ្គលជាប់អាករ | AB28: L001-901905215 | AC28: វីអ៊ីស៊ិន (ខេមបូឌា) អ៊ិនដាសស្ទ្រី ឯ.ក | AD28: 2526397 | AE28: 2296725 | AF28: 0 | AG28: 0 | AH28: 229672 | AI28: 0 | AJ28: 0 | AK28: 0 | AL28: 0 | AM28: 0 | AN28: 0 | AO28: 0 | AP28: 0 | AS28: បានប្រកាសពន្ធ
A29: 21 | C29: អ៊ិចស្ពែឌីធ័រ ខេមបូឌា អិលធីឌី | D29: L001-100045898 | E29: TI0169609 | F29: 43860 | G29: 145395 | I29: 145395 | J29: =IF(AND(S29=TRUE, T29=TRUE, U29=TRUE), IF(W29<-0.05, "អនុញ្ញាត (អ្នកផ្គត់ផ្គង់ប្រកាសខ្វះ)", "បានប្រកាស (អនុញ្ញាត)"), IF(AND(S29=FALSE, T29=FALSE, U29=FALSE), "ព្យួរទុក (មិនមានទិន្នន័យ)", "ប្រកាសខុស (ព្យួរទុក)")) | N29: =IF(W29<0,AH29,I29) | O29: =I29-M29 | Q29: TI0169609 | R29: TI-0169609 | S29: =Q29=R29 | T29: =AND(MONTH(F29)=MONTH(X29), YEAR(F29)=YEAR(X29)) | U29: =AND(AB29<>"", 'Company information'!D$4<>"", RIGHT(SUBSTITUTE(AB29,"-",""),9)=RIGHT(SUBSTITUTE('Company information'!D$4,"-",""),9)) | V29: =AH29-I29 | X29: 43860 | Y29: TI-0169609 | AA29: បុគ្គលជាប់អាករ | AB29: L001-901905215 | AC29: វីអ៊ីស៊ិន (ខេមបូឌា) អ៊ិនដាសស្ទ្រី ឯ.ក | AD29: 1599345 | AE29: 1453950 | AF29: 0 | AG29: 0 | AH29: 145395 | AI29: 0 | AJ29: 0 | AK29: 0 | AL29: 0 | AM29: 0 | AN29: 0 | AO29: 0 | AP29: 0 | AS29: បានប្រកាសពន្ធ
A30: 22 | C30: អ៊ិចស្ពែឌីធ័រ ខេមបូឌា អិលធីឌី | D30: L001-100045898 | E30: TI0169607 | F30: 43860 | G30: 145395 | I30: 145395 | J30: =IF(AND(S30=TRUE, T30=TRUE, U30=TRUE), IF(W30<-0.05, "អនុញ្ញាត (អ្នកផ្គត់ផ្គង់ប្រកាសខ្វះ)", "បានប្រកាស (អនុញ្ញាត)"), IF(AND(S30=FALSE, T30=FALSE, U30=FALSE), "ព្យួរទុក (មិនមានទិន្នន័យ)", "ប្រកាសខុស (ព្យួរទុក)")) | N30: =IF(W30<0,AH30,I30) | O30: =I30-M30 | Q30: TI0169607 | R30: TI-0169607 | S30: =Q30=R30 | T30: =AND(MONTH(F30)=MONTH(X30), YEAR(F30)=YEAR(X30)) | U30: =AND(AB30<>"", 'Company information'!D$4<>"", RIGHT(SUBSTITUTE(AB30,"-",""),9)=RIGHT(SUBSTITUTE('Company information'!D$4,"-",""),9)) | V30: =AH30-I30 | X30: 43860 | Y30: TI-0169607 | AA30: បុគ្គលជាប់អាករ | AB30: L001-901905215 | AC30: វីអ៊ីស៊ិន (ខេមបូឌា) អ៊ិនដាសស្ទ្រី ឯ.ក | AD30: 1599345 | AE30: 1453950 | AF30: 0 | AG30: 0 | AH30: 145395 | AI30: 0 | AJ30: 0 | AK30: 0 | AL30: 0 | AM30: 0 | AN30: 0 | AO30: 0 | AP30: 0 | AS30: បានប្រកាសពន្ធ
A31: 23 | C31: អ៊ិចស្ពែឌីធ័រ ខេមបូឌា អិលធីឌី | D31: L001-100045898 | E31: TI0169605 | F31: 43860 | G31: 145395 | I31: 145395 | J31: =IF(AND(S31=TRUE, T31=TRUE, U31=TRUE), IF(W31<-0.05, "អនុញ្ញាត (អ្នកផ្គត់ផ្គង់ប្រកាសខ្វះ)", "បានប្រកាស (អនុញ្ញាត)"), IF(AND(S31=FALSE, T31=FALSE, U31=FALSE), "ព្យួរទុក (មិនមានទិន្នន័យ)", "ប្រកាសខុស (ព្យួរទុក)")) | N31: =IF(W31<0,AH31,I31) | O31: =I31-M31 | Q31: TI0169605 | R31: TI-0169605 | S31: =Q31=R31 | T31: =AND(MONTH(F31)=MONTH(X31), YEAR(F31)=YEAR(X31)) | U31: =AND(AB31<>"", 'Company information'!D$4<>"", RIGHT(SUBSTITUTE(AB31,"-",""),9)=RIGHT(SUBSTITUTE('Company information'!D$4,"-",""),9)) | V31: =AH31-I31 | X31: 43860 | Y31: TI-0169605 | AA31: បុគ្គលជាប់អាករ | AB31: L001-901905215 | AC31: វីអ៊ីស៊ិន (ខេមបូឌា) អ៊ិនដាសស្ទ្រី ឯ.ក | AD31: 1599345 | AE31: 1453950 | AF31: 0 | AG31: 0 | AH31: 145395 | AI31: 0 | AJ31: 0 | AK31: 0 | AL31: 0 | AM31: 0 | AN31: 0 | AO31: 0 | AP31: 0 | AS31: បានប្រកាសពន្ធ
A32: 24 | C32: អ៊ិចស្ពែឌីធ័រ ខេមបូឌា អិលធីឌី | D32: L001-100045898 | E32: TI0168468 | F32: 43847 | G32: 52366 | I32: 52366 | J32: =IF(AND(S32=TRUE, T32=TRUE, U32=TRUE), IF(W32<-0.05, "អនុញ្ញាត (អ្នកផ្គត់ផ្គង់ប្រកាសខ្វះ)", "បានប្រកាស (អនុញ្ញាត)"), IF(AND(S32=FALSE, T32=FALSE, U32=FALSE), "ព្យួរទុក (មិនមានទិន្នន័យ)", "ប្រកាសខុស (ព្យួរទុក)")) | N32: =IF(W32<0,AH32,I32) | O32: =I32-M32 | Q32: TI0168468 | R32: TI-0168468 | S32: =Q32=R32 | T32: =AND(MONTH(F32)=MONTH(X32), YEAR(F32)=YEAR(X32)) | U32: =AND(AB32<>"", 'Company information'!D$4<>"", RIGHT(SUBSTITUTE(AB32,"-",""),9)=RIGHT(SUBSTITUTE('Company information'!D$4,"-",""),9)) | V32: =AH32-I32 | X32: 43847 | Y32: TI-0168468 | AA32: បុគ្គលជាប់អាករ | AB32: L001-901905215 | AC32: វីអ៊ីស៊ិន (ខេមបូឌា) អ៊ិនដាសស្ទ្រី ឯ.ក | AD32: 576743 | AE32: 524312 | AF32: 0 | AG32: 0 | AH32: 52431 | AI32: 0 | AJ32: 0 | AK32: 0 | AL32: 0 | AM32: 0 | AN32: 0 | AO32: 0 | AP32: 0 | AS32: បានប្រកាសពន្ធ
A33: 25 | C33: អ៊ិចស្ពែឌីធ័រ ខេមបូឌា អិលធីឌី | D33: L001-100045898 | E33: TI0168455 | F33: 43847 | G33: 48460 | I33: 48460 | J33: =IF(AND(S33=TRUE, T33=TRUE, U33=TRUE), IF(W33<-0.05, "អនុញ្ញាត (អ្នកផ្គត់ផ្គង់ប្រកាសខ្វះ)", "បានប្រកាស (អនុញ្ញាត)"), IF(AND(S33=FALSE, T33=FALSE, U33=FALSE), "ព្យួរទុក (មិនមានទិន្នន័យ)", "ប្រកាសខុស (ព្យួរទុក)")) | N33: =IF(W33<0,AH33,I33) | O33: =I33-M33 | Q33: TI0168455 | R33: TI-0168455 | S33: =Q33=R33 | T33: =AND(MONTH(F33)=MONTH(X33), YEAR(F33)=YEAR(X33)) | U33: =AND(AB33<>"", 'Company information'!D$4<>"", RIGHT(SUBSTITUTE(AB33,"-",""),9)=RIGHT(SUBSTITUTE('Company information'!D$4,"-",""),9)) | V33: =AH33-I33 | X33: 43847 | Y33: TI-0168455 | AA33: បុគ្គលជាប់អាករ | AB33: L001-901905215 | AC33: វីអ៊ីស៊ិន (ខេមបូឌា) អ៊ិនដាសស្ទ្រី ឯ.ក | AD33: 533922 | AE33: 485384 | AF33: 0 | AG33: 0 | AH33: 48538 | AI33: 0 | AJ33: 0 | AK33: 0 | AL33: 0 | AM33: 0 | AN33: 0 | AO33: 0 | AP33: 0 | AS33: បានប្រកាសពន្ធ
A34: 26 | C34: អ៊ិចស្ពែឌីធ័រ ខេមបូឌា អិលធីឌី | D34: L001-100045898 | E34: TI0168454 | F34: 43847 | G34: 51052 | I34: 51052 | J34: =IF(AND(S34=TRUE, T34=TRUE, U34=TRUE), IF(W34<-0.05, "អនុញ្ញាត (អ្នកផ្គត់ផ្គង់ប្រកាសខ្វះ)", "បានប្រកាស (អនុញ្ញាត)"), IF(AND(S34=FALSE, T34=FALSE, U34=FALSE), "ព្យួរទុក (មិនមានទិន្នន័យ)", "ប្រកាសខុស (ព្យួរទុក)")) | N34: =IF(W34<0,AH34,I34) | O34: =I34-M34 | Q34: TI0168454 | R34: TI-0168454 | S34: =Q34=R34 | T34: =AND(MONTH(F34)=MONTH(X34), YEAR(F34)=YEAR(X34)) | U34: =AND(AB34<>"", 'Company information'!D$4<>"", RIGHT(SUBSTITUTE(AB34,"-",""),9)=RIGHT(SUBSTITUTE('Company information'!D$4,"-",""),9)) | V34: =AH34-I34 | X34: 43847 | Y34: TI-0168454 | AA34: បុគ្គលជាប់អាករ | AB34: L001-901905215 | AC34: វីអ៊ីស៊ិន (ខេមបូឌា) អ៊ិនដាសស្ទ្រី ឯ.ក | AD34: 562469 | AE34: 511335 | AF34: 0 | AG34: 0 | AH34: 51134 | AI34: 0 | AJ34: 0 | AK34: 0 | AL34: 0 | AM34: 0 | AN34: 0 | AO34: 0 | AP34: 0 | AS34: បានប្រកាសពន្ធ
... A39: 31 | C39: អ៊ិចស្ពែឌីធ័រ ខេមបូឌា អិលធីឌី | D39: L001-100045898 | E39: TI0168448 | F39: 43847 | G39: 52366 | I39: 52366 | J39: =IF(AND(S39=TRUE, T39=TRUE, U39=TRUE), IF(W39<-0.05, "អនុញ្ញាត (អ្នកផ្គត់ផ្គង់ប្រកាសខ្វះ)", "បានប្រកាស (អនុញ្ញាត)"), IF(AND(S39=FALSE, T39=FALSE, U39=FALSE), "ព្យួរទុក (មិនមានទិន្នន័យ)", "ប្រកាសខុស (ព្យួរទុក)")) | N39: =IF(W39<0,AH39,I39) | O39: =I39-M39 | Q39: TI0168448 | R39: TI-0168448 | S39: =Q39=R39 | T39: =AND(MONTH(F39)=MONTH(X39), YEAR(F39)=YEAR(X39)) | U39: =AND(AB39<>"", 'Company information'!D$4<>"", RIGHT(SUBSTITUTE(AB39,"-",""),9)=RIGHT(SUBSTITUTE('Company information'!D$4,"-",""),9)) | V39: =AH39-I39 | X39: 43847 | Y39: TI-0168448 | AA39: បុគ្គលជាប់អាករ | AB39: L001-901905215 | AC39: វីអ៊ីស៊ិន (ខេមបូឌា) អ៊ិនដាសស្ទ្រី ឯ.ក | AD39: 576743 | AE39: 524312 | AF39: 0 | AG39: 0 | AH39: 52431 | AI39: 0 | AJ39: 0 | AK39: 0 | AL39: 0 | AM39: 0 | AN39: 0 | AO39: 0 | AP39: 0 | AS39: បានប្រកាសពន្ធ
A40: 32 | C40: កំពង់ផែស្វយ័តក្រុងព្រះសីហនុ | D40: L001-100044638 | E40: 008584 | F40: 43845 | G40: 7290 | I40: 7290 | J40: =IF(AND(S40=TRUE, T40=TRUE, U40=TRUE), IF(W40<-0.05, "អនុញ្ញាត (អ្នកផ្គត់ផ្គង់ប្រកាសខ្វះ)", "បានប្រកាស (អនុញ្ញាត)"), IF(AND(S40=FALSE, T40=FALSE, U40=FALSE), "ព្យួរទុក (មិនមានទិន្នន័យ)", "ប្រកាសខុស (ព្យួរទុក)")) | N40: =IF(W40<0,AH40,I40) | O40: =I40-M40 | Q40: 008584 | S40: =Q40=R40 | T40: =AND(MONTH(F40)=MONTH(X40), YEAR(F40)=YEAR(X40)) | U40: =AND(AB40<>"", 'Company information'!D$4<>"", RIGHT(SUBSTITUTE(AB40,"-",""),9)=RIGHT(SUBSTITUTE('Company information'!D$4,"-",""),9)) | V40: =AH40-I40
A41: 33 | C41: កំពង់ផែស្វយ័តក្រុងព្រះសីហនុ | D41: L001-100044638 | E41: 007430 | F41: 43843 | G41: 64395 | I41: 64395 | J41: =IF(AND(S41=TRUE, T41=TRUE, U41=TRUE), IF(W41<-0.05, "អនុញ្ញាត (អ្នកផ្គត់ផ្គង់ប្រកាសខ្វះ)", "បានប្រកាស (អនុញ្ញាត)"), IF(AND(S41=FALSE, T41=FALSE, U41=FALSE), "ព្យួរទុក (មិនមានទិន្នន័យ)", "ប្រកាសខុស (ព្យួរទុក)")) | N41: =IF(W41<0,AH41,I41) | O41: =I41-M41 | Q41: 007430 | S41: =Q41=R41 | T41: =AND(MONTH(F41)=MONTH(X41), YEAR(F41)=YEAR(X41)) | U41: =AND(AB41<>"", 'Company information'!D$4<>"", RIGHT(SUBSTITUTE(AB41,"-",""),9)=RIGHT(SUBSTITUTE('Company information'!D$4,"-",""),9)) | V41: =AH41-I41
A42: 34 | C42: កំពង់ផែស្វយ័តក្រុងព្រះសីហនុ | D42: L001-100044638 | E42: 006642 | F42: 44136 | G42: 23085 | I42: 23085 | J42: =IF(AND(S42=TRUE, T42=TRUE, U42=TRUE), IF(W42<-0.05, "អនុញ្ញាត (អ្នកផ្គត់ផ្គង់ប្រកាសខ្វះ)", "បានប្រកាស (អនុញ្ញាត)"), IF(AND(S42=FALSE, T42=FALSE, U42=FALSE), "ព្យួរទុក (មិនមានទិន្នន័យ)", "ប្រកាសខុស (ព្យួរទុក)")) | N42: =IF(W42<0,AH42,I42) | O42: =I42-M42 | Q42: 006642 | S42: =Q42=R42 | T42: =AND(MONTH(F42)=MONTH(X42), YEAR(F42)=YEAR(X42)) | U42: =AND(AB42<>"", 'Company information'!D$4<>"", RIGHT(SUBSTITUTE(AB42,"-",""),9)=RIGHT(SUBSTITUTE('Company information'!D$4,"-",""),9)) | V42: =AH42-I42
A43: 35 | C43: អឹមេហ្ស៊ីង ឡូជីស្ទីក & សឹបផ្លាយ ឆេន (ខេមបូឌា) ឯ.ក | D43: K009-901703255 | E43: 200116 | F43: 43852 | G43: 540645 | I43: 540645 | J43: =IF(AND(S43=TRUE, T43=TRUE, U43=TRUE), IF(W43<-0.05, "អនុញ្ញាត (អ្នកផ្គត់ផ្គង់ប្រកាសខ្វះ)", "បានប្រកាស (អនុញ្ញាត)"), IF(AND(S43=FALSE, T43=FALSE, U43=FALSE), "ព្យួរទុក (មិនមានទិន្នន័យ)", "ប្រកាសខុស (ព្យួរទុក)")) | N43: =IF(W43<0,AH43,I43) | O43: =I43-M43 | Q43: 200116 | R43: 200116 | S43: =Q43=R43 | T43: =AND(MONTH(F43)=MONTH(X43), YEAR(F43)=YEAR(X43)) | U43: =AND(AB43<>"", 'Company information'!D$4<>"", RIGHT(SUBSTITUTE(AB43,"-",""),9)=RIGHT(SUBSTITUTE('Company information'!D$4,"-",""),9)) | V43: =AH43-I43 | X43: 43852 | Y43: 200116 | AA43: បុគ្គលជាប់អាករ | AB43: L001-901905215 | AC43: វីអ៊ីស៊ិន (ខេមបូឌា) អ៊ិនដាសស្ទ្រី ឯ.ក | AD43: 5947095 | AE43: 5406450 | AF43: 0 | AG43: 0 | AH43: 540645 | AI43: 0 | AJ43: 0 | AK43: 0 | AL43: 0 | AM43: 0 | AN43: 0 | AO43: 0 | AP43: 0 | AS43: បានប្រកាសពន្ធ
A44: 36 | C44: វ៉ាយ.ស៊ី ផេកខេជីង ឯ.ក | D44: L001-901700417 | E44: TI0008 | F44: 43851 | G44: 11694624 | I44: 11694624 | J44: =IF(AND(S44=TRUE, T44=TRUE, U44=TRUE), IF(W44<-0.05, "អនុញ្ញាត (អ្នកផ្គត់ផ្គង់ប្រកាសខ្វះ)", "បានប្រកាស (អនុញ្ញាត)"), IF(AND(S44=FALSE, T44=FALSE, U44=FALSE), "ព្យួរទុក (មិនមានទិន្នន័យ)", "ប្រកាសខុស (ព្យួរទុក)")) | N44: =IF(W44<0,AH44,I44) | O44: =I44-M44 | Q44: TI0008 | R44: TI0008 | S44: =Q44=R44 | T44: =AND(MONTH(F44)=MONTH(X44), YEAR(F44)=YEAR(X44)) | U44: =AND(AB44<>"", 'Company information'!D$4<>"", RIGHT(SUBSTITUTE(AB44,"-",""),9)=RIGHT(SUBSTITUTE('Company information'!D$4,"-",""),9)) | V44: =AH44-I44 | X44: 43851 | Y44: TI0008 | AA44: បុគ្គលជាប់អាករ | AB44: L001-901905215 | AC44: វីអ៊ីស៊ិន (ខេមបូឌា) អ៊ិនដាសស្ទ្រី ឯ.ក | AD44: 128166162 | AE44: 116514693 | AF44: 0 | AG44: 0 | AH44: 11651469 | AI44: 0 | AJ44: 0 | AK44: 0 | AL44: 0 | AM44: 0 | AN44: 0 | AO44: 0 | AP44: 0 | AS44: បានប្រកាសពន្ធ
...

Sheet Annex IV-EX
A1: តារាងឧបសម្ព័ន្ធ IV
A2: បញ្ជាក់អំពីការលក់
A3: (ការនាំចេញ/លក់បន្ទុករដ្ឋ/លក់តាមអត្រា០%)
A4: ក្រុមហ៊ុន៖ | B4: ='Company information'!D2 | D4: សវនករពន្ធដារ៖ | E4: ='Company information'!D8
A5: លេខ អតប ៖ | B5: ='Company information'!D4 | E5: ='Company information'!E8
A6: ='Company information'!E8 | D6: ទឹកប្រាក់ស្នើសុំបង្វិលសងចំនួន៖ | E6: ='Company information'!H9
A7: ល.រ | B7: បរិយាយ | C7: ប្រតិវេទន៍គយនាំចេញ/វិក្កយបត្រ | E7: តម្លៃជារៀល
C8: លេខ | D8: ចុះថ្ងៃទី ខែ ឆ្នាំ
A9: 1 | B9: សេវាកម្មកាត់ដេរ Garment Service | C9: ACL-20230004 | D9: 45291 | E9: 581845
A10: 2 | B10: នាំចេញសំលៀកបំពាក់ | C10: PFA240512 | D10: 45407 | E10: 74373
A11: 3 | B11: នាំចេញសំលៀកបំពាក់ | C11: PFA240425 | D11: 45385 | E11: 581845
A12: 4 | B12: សេវាកម្មកាត់ដេរ | C12: ACLCMT-20240009 | D12: 45412 | E12: 581845
A13: 5 | B13: សេវាកម្មកាត់ដេរ | C13: ACLCMT-20240007 | D13: 45412 | E13: 99936
A14: 6 | B14: សេវាកម្មកាត់ដេរ | C14: ACLCMT-20240048 | D14: 45443 | E14: 74982
A15: 7 | B15: នាំចេញសំលៀកបំពាក់ | C15: E15445 | D15: 45442 | E15: 74982
A16: 8 | B16: សេវាកម្មកាត់ដេរ | C16: ACLCMT-20240068 | D16: 45471 | E16: 74982
A17: 9 | B17: នាំចេញសំលៀកបំពាក់ | C17: E103463 | D17: 45451 | E17: 74982
A18: 10 | B18: នាំចេញសំលៀកបំពាក់ | C18: E97797 | D18: 45444 | E18: 74982
A19: 11 | B19: សេវាកម្មកាត់ដេរ | C19: ACLCMT-20240168 | D19: 45504 | E19: 74982
A20: 12 | B20: សេវាកម្មកាត់ដេរ | C20: ACLCMT-20240121 | D20: 45504 | E20: 117455
... A22: 14 | B22: នាំចេញសំលៀកបំពាក់ | C22: E139173 | D22: 45495 | E22: 117455
A23: សរុបការនាំចេញ | E23: =SUM(E9:E22)
D25: រាជធានីភ្នំពេញ.ថ្ងៃទី ខែ ឆ្នាំ
D26: មន្ត្រីសវនកម្ម
D28: ='Company information'!D9 | E28: ='Company information'!E9

Sheet Annex V-Local Sale
A1: តារាងឧបសម្ព័ន្ធ V
A2: បញ្ជាក់អំពីអាករលើធាតុចេញ
A3: ( ការលក់ក្នុងស្រុក )
A4: ក្រុមហ៊ុន៖ | B4: ='Company information'!D2 | G4: សវនករពន្ធដារ៖ | H4: ='Company information'!D8
A5: លេខ អតប ៖ | B5: ='Company information'!D4 | H5: ='Company information'!E8
A6: ='Company information'!E8 | F6: ទឹកប្រាក់ស្នើសុំបង្វិលសងចំនួន៖ | H6: ='Company information'!H9
A7: ល.រ | B7: បរិយាយ | C7: វិក្កយបត្រ | E7: អាករតម្លៃ (ដុល្លា) | F7: អត្រាប្តូរប្រាក់ | G7: អាករតម្លៃ (រៀល) | H7: ផ្សេងៗ
C8: លេខ | D8: ថ្ងៃ ខែ ឆ្នាំ
A9: 1 | B9: លក់កាកសំណល់អេតចាយ - Sale Scrap | C9: ACL-20240002 | D9: 45314 | G9: 581845
A10: 2 | B10: លក់កាកសំណល់អេតចាយ - Sale Scrap | C10: ACL-20240001 | D10: 45314 | G10: 100136
A11: 3 | B11: លក់កាកសំណល់អេតចាយ - Sale Scrap | C11: ACL-20240004 | D11: 45341 | G11: 155245
A12: 4 | B12: លក់កាកសំណល់អេតចាយ - Sale Scrap | C12: ACL-20240012 | D12: 45373 | G12: 74982
A13: 5 | B13: លក់កាកសំណល់អេតចាយ - Sale Scrap | C13: ACL-20240011 | D13: 45356 | G13: 99936
A14: 6 | B14: លក់កាកសំណល់អេតចាយ - Sale Scrap | C14: ACL-20240010 | D14: 45356 | G14: 74373
A15: 7 | B15: សេវាកម្មកាត់ដេរ | C15: ACL-20240018 | D15: 45412 | G15: 6885857
A16: 8 | B16: លក់កាកសំណល់អេតចាយ-Sale Scrap | C16: ACL-20240017 | D16: 45412 | G16: 65291
A17: 9 | B17: លក់កាកសំណល់អេតចាយ-Sale Scrap | C17: ACL-20240022 | D17: 45470 | G17: 4482
A18: 10 | B18: លក់កាកសំណល់អេតចាយ-Sale Scrap | C18: ACL-20240025 | D18: 45503 | G18: 117455
A19: 11 | B19: លក់កាកសំណល់អេតចាយ-Sale Scrap | C19: ACL-20240029 | D19: 45534 | G19: 394691
A20: 12 | B20: លក់កាកសំណល់អេតចាយ-Sale Scrap | C20: ACL-20240026 | D20: 45510 | G20: 250215
... A22: 14 | B22: លក់កាកសំណល់អេតចាយ-Sale Scrap | C22: ACL-20240030 | D22: 45600 | G22: 290909
A23: សរុបការលក់ក្នុងស្រុក | G23: =SUM(G9:G22)
G25: រាជធានីភ្នំពេញ.ថ្ងៃទី ខែ ឆ្នាំ
G26: មន្ត្រីសវនកម្ម
G28: ='Company information'!D9 | H28: ='Company information'!E9

Sheet Taxpaid
C4: ='Company information'!D7
B5: ល.រ | C5: ប្រភេទពន្ធ | D5: ចំនួនទឹកប្រាក់ពន្ធ | E5: Jan-2023 | F5: Feb-2023 | G5: Mar-2023 | H5: Apr-2023 | I5: May-2023 | J5: Jun-2023 | K5: Jul-2023 | L5: Aug-2023 | M5: Sep-2023 | N5: Oct-2023 | O5: Nov-2023 | P5: Dec-2023 | Q5: Jan-2024 | R5: Feb-2024 | S5: Mar-2024 | T5: Apr-2024 | U5: May-2024 | V5: Jun-2024 | W5: Jul-2024 | X5: Aug-2024 | Y5: Sep-2024 | Z5: Oct-2024 | AA5: Nov-2024 | AB5: Dec-2024
B6: 1 | C6: ពន្ធប៉ាតង់ | D6: =SUM(E6:AB6) | E6: 0 | F6: 0 | G6: 0 | H6: 0 | I6: 0 | J6: 0 | K6: 0 | L6: 1500000 | M6: 0 | N6: 0 | O6: 0 | P6: 0 | Q6: 0 | R6: 0 | S6: 3000000 | T6: 0 | U6: 0 | V6: 0 | W6: 0 | X6: 0 | Y6: 0 | Z6: 0 | AA6: 0 | AB6: 0
B7: 2 | C7: កម្រៃសេវាចុះបញ្ជី ឬធ្វើបច្ចុប្បន្នភាព | D7: =SUM(E7:AB7) | E7: 0 | F7: 0 | G7: 0 | H7: 0 | I7: 0 | J7: 0 | K7: 0 | L7: 400000 | M7: 0 | N7: 0 | O7: 0 | P7: 0 | Q7: 0 | R7: 0 | S7: 0 | T7: 0 | U7: 0 | V7: 0 | W7: 0 | X7: 0 | Y7: 0 | Z7: 0 | AA7: 200000 | AB7: 0
B8: 3 | C8: ពន្ធលើប្រាក់បៀវត្ស | D8: =SUM(E8:AB8) | E8: 0 | F8: 0 | G8: 0 | H8: 0 | I8: 0 | J8: 0 | K8: 0 | L8: 0 | M8: 14745919 | N8: 17256700 | O8: 16645636 | P8: 17303541 | Q8: 15943205 | R8: 16907178 | S8: 18095811 | T8: 18473483 | U8: 19887604 | V8: 21319783 | W8: 21197056 | X8: 23579307 | Y8: 21157605 | Z8: 31898419 | AA8: 36331895 | AB8: 0
B9: 4 | C9: ពន្ធលើអត្ថប្រយោជន៍បន្ថែម | D9: =SUM(E9:AB9) | E9: 0 | F9: 0 | G9: 0 | H9: 0 | I9: 0 | J9: 0 | K9: 0 | L9: 0 | M9: 0 | N9: 3416033 | O9: 2893088 | P9: 11751147 | Q9: 9486163 | R9: 4889241 | S9: 4916054 | T9: 6439288 | U9: 13906169 | V9: 10494263 | W9: 8379089 | X9: 8881572 | Y9: 10415723 | Z9: 5148907 | AA9: 11905492 | AB9: 0
B10: 5 | C10: ប្រាក់រំដោះពន្ធលើប្រាក់ចំណូល | D10: =SUM(E10:AB10) | E10: 0 | F10: 0 | G10: 0 | H10: 0 | I10: 0 | J10: 0 | K10: 0 | L10: 0 | M10: 0 | N10: 0 | O10: 0 | P10: 0 | Q10: 0 | R10: 0 | S10: 0 | T10: 0 | U10: 0 | V10: 0 | W10: 0 | X10: 0 | Y10: 0 | Z10: 0 | AA10: 0 | AB10: 0
B11: 6 | C11: ពន្ធលើប្រាក់ចំណូលប្រចាំឆ្នាំ | D11: =SUM(E11:AB11) | E11: 0 | F11: 0 | G11: 0 | H11: 0 | I11: 0 | J11: 0 | K11: 0 | L11: 0 | M11: 0 | N11: 0 | O11: 0 | P11: 0 | Q11: 0 | R11: 0 | S11: 0 | T11: 0 | U11: 0 | V11: 0 | W11: 0 | X11: 0 | Y11: 0 | Z11: 0 | AA11: 0 | AB11: 0
B12: 7 | C12: ពន្ធកាត់ទុកលើសេវាកម្ម ១៥% | D12: =SUM(E12:AB12) | E12: 0 | F12: 0 | G12: 0 | H12: 0 | I12: 0 | J12: 0 | K12: 0 | L12: 0 | M12: 0 | N12: 4738214 | O12: 1874218 | P12: 6088836 | Q12: 3880332 | R12: 4292372 | S12: 15258802 | T12: 10939010 | U12: 11238999 | V12: 7855100 | W12: 18447624 | X12: 24896291 | Y12: 23057495 | Z12: 17486099 | AA12: 14246633 | AB12: 0
B13: 8 | C13: ពន្ធកាត់ទុកលើថ្លៃឈ្នួល (រូបវន្ដបុគ្គល) | D13: =SUM(E13:AB13) | E13: 0 | F13: 0 | G13: 0 | H13: 0 | I13: 0 | J13: 0 | K13: 0 | L13: 0 | M13: 0 | N13: 186075 | O13: 185175 | P13: 31209809 | Q13: 4699329 | R13: 6782616 | S13: 6735943 | T13: 6774282 | U13: 6822622 | V13: 7536055 | W13: 6847625 | X13: 6762613 | Y13: 6769281 | Z13: 6772615 | AA13: 6714273 | AB13: 0
B14: 9 | C14: អាករលើតម្លៃបន្ថែម | D14: =SUM(E14:AB14) | E14: 0 | F14: 0 | G14: 0 | H14: 0 | I14: 0 | J14: 0 | K14: 0 | L14: 0 | M14: 0 | N14: 0 | O14: 0 | P14: 0 | Q14: 0 | R14: 241601 | S14: 18911 | T14: 0 | U14: 19155 | V14: 21157 | W14: 19225 | X14: 18986 | Y14: 38011 | Z14: 19014 | AA14: 18851 | AB14: 0
B15: 10 | C15: អាករពិសេសលើទំនិញមួយចំនួន | D15: =SUM(E15:AB15) | E15: 0 | F15: 0 | G15: 0 | H15: 0 | I15: 0 | J15: 0 | K15: 0 | L15: 0 | M15: 0 | N15: 0 | O15: 0 | P15: 0 | Q15: 0 | R15: 0 | S15: 0 | T15: 0 | U15: 0 | V15: 0 | W15: 0 | X15: 0 | Y15: 0 | Z15: 0 | AA15: 0 | AB15: 0
B16: 11 | C16: អាករពិសេសលើសេវាមួយចំនួន | D16: =SUM(E16:AB16) | E16: 0 | F16: 0 | G16: 0 | H16: 0 | I16: 0 | J16: 0 | K16: 0 | L16: 0 | M16: 0 | N16: 0 | O16: 0 | P16: 0 | Q16: 0 | R16: 0 | S16: 0 | T16: 0 | U16: 0 | V16: 0 | W16: 0 | X16: 0 | Y16: 0 | Z16: 0 | AA16: 0 | AB16: 0
B17: 12 | C17: អាករសម្រាប់បំភ្លឺសាធារណៈ | D17: =SUM(E17:AB17) | E17: 0 | F17: 0 | G17: 0 | H17: 0 | I17: 0 | J17: 0 | K17: 0 | L17: 0 | M17: 0 | N17: 0 | O17: 0 | P17: 0 | Q17: 0 | R17: 0 | S17: 0 | T17: 0 | U17: 0 | V17: 0 | W17: 0 | X17: 0 | Y17: 0 | Z17: 0 | AA17: 0 | AB17: 0
... B20: 15 | C20: ពន្ធកាត់ទុកលើការប្រាក់ ១៥% | D20: =SUM(E20:AB20) | E20: 0 | F20: 0 | G20: 0 | H20: 0 | I20: 0 | J20: 0 | K20: 0 | L20: 0 | M20: 0 | N20: 0 | O20: 0 | P20: 0 | Q20: 0 | R20: 0 | S20: 542353 | T20: 0 | U20: 0 | V20: 0 | W20: 0 | X20: 25166817 | Y20: 27019415 | Z20: 0 | AA20: 0 | AB20: 0
C21: សរុបទឹកប្រាក់ពន្ធបានបង់ចូលរដ្ឋ | D21: =SUM(D6:D20)

Sheet Damco
A1: តារាងឧបសម្ព័ន្ឋ
A2: តារាងប្រៀធៀបវិក្ក័យប័ត្រស្នើសុំបង្វិលសងអាករលើតំលៃបន្ថែម ( Cross checking )
A3: ='Annex I-IM State Charge'!#REF!
A4: ='Annex I-IM State Charge'!#REF!
A5: ល.រ | B5: ក្រុមហ៊ុនស្នើសុំបង្វិលសង | E5: អ្នកផ្គត់ផ្គង់ | J5: ផ្សេងៗ
B6: វិក្កយបត្រ | E6: សហគ្រាស | F6: លេខអតប | G6: វិក្កយបត្រ
B7: លេខ | C7: ថ្ងៃទី ខែ ឆ្នាំ | D7: ប្រាក់អាករ | G7: លេខ | H7: ថ្ងៃទី ខែ ឆ្នាំ | I7: ប្រាក់អាករ
A8: 1 | B8: 030209 | C8: 41246 | D8: 58.25 | E8: A P L Logistics | F8: 100046460 | G8: 030209 | H8: 41246 | I8: 58.25 | J8: បានបង់
A9: 2 | B9: 030231 | C9: 41248 | D9: 4 | E9: A P L Logistics | F9: 100046460 | G9: 030231 | H9: 41248 | I9: 4 | J9: បានបង់
A10: 3 | B10: 030241 | C10: 41254 | D10: 49.75 | E10: A P L Logistics | F10: 100046460 | G10: 030241 | H10: 41254 | I10: 49.75 | J10: បានបង់
A11: 4 | B11: 030262 | C11: 41254 | D11: 181.79 | E11: A P L Logistics | F11: 100046460 | G11: 030262 | H11: 41254 | I11: 181.79 | J11: បានបង់
A12: 5 | B12: 030302 | C12: 41260 | D12: 46.69 | E12: A P L Logistics | F12: 100046460 | G12: 030302 | H12: 41260 | I12: 46.69 | J12: បានបង់
A13: 6 | B13: 030328 | C13: 41260 | D13: 236.64 | E13: A P L Logistics | F13: 100046460 | G13: 030328 | H13: 41260 | I13: 236.64 | J13: បានបង់
A14: 7 | B14: 030343 | C14: 41261 | D14: 4 | E14: A P L Logistics | F14: 100046460 | G14: 030343 | H14: 41261 | I14: 4 | J14: បានបង់
A15: 8 | B15: 030353 | C15: 41261 | D15: 10 | E15: A P L Logistics | F15: 100046460 | G15: 030353 | H15: 41261 | I15: 10 | J15: បានបង់
A16: 9 | B16: 030450 | C16: 41274 | D16: 87.52 | E16: A P L Logistics | F16: 100046460 | G16: 030450 | H16: 41274 | I16: 87.52 | J16: បានបង់
A17: 10 | B17: 030469 | C17: 41274 | D17: 39.29 | E17: A P L Logistics | F17: 100046460 | G17: 030469 | H17: 41274 | I17: 39.29 | J17: បានបង់
A18: Total 12/2012 | D18: =SUM(D8:D17) | H18: USD | I18: =SUM(I8:I17)
A19: Total 12/2012 | G19: 3995 | H19: RIEL | I19: =I18*G19
A20: 1 | B20: 029920 | C20: 41218 | D20: 77 | E20: A P L Logistics | F20: 100046460 | G20: 029920 | H20: 41218 | I20: 77 | J20: បានបង់
A21: 2 | B21: 029981 | C21: 41225 | D21: 115.89 | E21: A P L Logistics | F21: 100046460 | G21: 029981 | H21: 41225 | I21: 115.89 | J21: បានបង់
A22: 3 | B22: 030003 | C22: 41225 | D22: 82.91 | E22: A P L Logistics | F22: 100046460 | G22: 030003 | H22: 41225 | I22: 82.91 | J22: បានបង់
A23: 4 | B23: 030044 | C23: 41232 | D23: 55.32 | E23: A P L Logistics | F23: 100046460 | G23: 030044 | H23: 41232 | I23: 55.32 | J23: បានបង់
A24: 5 | B24: 030062 | C24: 41232 | D24: 32.03 | E24: A P L Logistics | F24: 100046460 | G24: 030062 | H24: 41232 | I24: 32.03 | J24: បានបង់
A25: Total 11/2012 | D25: =SUM(D20:D24) | H25: USD | I25: =SUM(I20:I24)
A26: Total 11/2012 | G26: 3999 | H26: RIEL | I26: =I25*G26
A27: 1 | B27: 029638 | C27: 41183 | D27: 89.93 | E27: A P L Logistics | F27: 100046460 | G27: 029638 | H27: 41183 | I27: 89.93 | J27: បានបង់
A28: 2 | B28: 029716 | C28: 41190 | D28: 49.63 | E28: A P L Logistics | F28: 100046460 | G28: 029716 | H28: 41190 | I28: 49.63 | J28: បានបង់
A29: 3 | B29: 029766 | C29: 41197 | D29: 115.81 | E29: A P L Logistics | F29: 100046460 | G29: 029766 | H29: 41197 | I29: 115.81 | J29: បានបង់
A30: 4 | B30: 029816 | C30: 41204 | D30: 101.98 | E30: A P L Logistics | F30: 100046460 | G30: 029816 | H30: 41204 | I30: 101.98 | J30: បានបង់
A31: 5 | B31: 029869 | C31: 41211 | D31: 67.28 | E31: A P L Logistics | F31: 100046460 | G31: 029869 | H31: 41211 | I31: 67.28 | J31: បានបង់
A32: Total 10/2012 | D32: =SUM(D27:D31) | H32: USD | I32: =SUM(I27:I31)
A33: Total 10/2012 | G33: 4028 | H33: RIEL | I33: =I32*G33
A34: 1 | B34: 029426 | C34: 41162 | D34: 206.96 | E34: A P L Logistics | F34: 100046460 | G34: 029426 | H34: 41162 | I34: 206.96 | J34: បានបង់
A35: 2 | B35: 029501 | C35: 41169 | D35: 69.7 | E35: A P L Logistics | F35: 100046460 | G35: 029501 | H35: 41169 | I35: 69.7 | J35: បានបង់
A36: 3 | B36: 029565 | C36: 41176 | D36: 46.66 | E36: A P L Logistics | F36: 100046460 | G36: 029565 | H36: 41176 | I36: 46.66 | J36: បានបង់
A37: Total 09/2012 | D37: =SUM(D34:D36) | H37: USD | I37: =SUM(I34:I36)
A38: Total 09/2012 | G38: 4044 | H38: RIEL | I38: =I37*G38
A39: 1 | B39: 029026 | C39: 41127 | D39: 37.84 | E39: A P L Logistics | F39: 100046460 | G39: 029026 | H39: 41127 | I39: 37.84 | J39: បានបង់
A40: 2 | B40: 029107 | C40: 41134 | D40: 95.46 | E40: A P L Logistics | F40: 100046460 | G40: 029107 | H40: 41134 | I40: 95.46 | J40: បានបង់
...

Sheet Chea Fat
A1: តារាងឧបសម្ព័ន្ឋ
A2: តារាងប្រៀធៀបវិក្ក័យប័ត្រស្នើសុំបង្វិលសងអាករលើតំលៃបន្ថែម ( Cross checking )
A3: នាមករណ៏សហគ្រាស : Maurea Garments Corp
A4: VAT TIN : 1 0 0 0 5 2 9 6 7
A5: ល.រ | B5: ក្រុមហ៊ុនស្នើសុំបង្វិលសង | E5: អ្នកផ្គត់ផ្គង់ | J5: ផ្សេងៗ
B6: វិក័យបត្រ័ | E6: សហគ្រាស | F6: លេខអតប | G6: វិក័យបត្រ័
B7: លេខ | C7: ថ្ងៃទី ខែ ឆ្នាំ | D7: ប្រាក់អាករ | G7: លេខ | H7: ថ្ងៃទី ខែ ឆ្នាំ | I7: ប្រាក់អាករ
A8: 1 | B8: 07-0360 | C8: 41842 | D8: 41.5 | E8: YUSEN LOGISTICS | F8: 104015799 | G8: 07-0360 | H8: 41842 | I8: 41.5
A9: 2 | B9: 07-0367 | C9: 41842 | D9: 64.57 | E9: YUSEN LOGISTICS | F9: 104015799 | G9: 07-0367 | H9: 41842 | I9: 64.57
A10: 3 | B10: 07-0368 | C10: 41842 | D10: 59.11 | E10: YUSEN LOGISTICS | F10: 104015799 | G10: 07-0368 | H10: 41842 | I10: 59.11
A11: 4 | B11: 07-0517 | C11: 41849 | D11: 75.93 | E11: YUSEN LOGISTICS | F11: 104015799 | G11: 07-0517 | H11: 41849 | I11: 75.93
A12: 5 | B12: 08-0039 | C12: 41856 | D12: 46.05 | E12: YUSEN LOGISTICS | F12: 104015799 | G12: 08-0039 | H12: 41856 | I12: 46.05
A13: 6 | B13: 08-0044 | C13: 41856 | D13: 41.5 | E13: YUSEN LOGISTICS | F13: 104015799 | G13: 08-0044 | H13: 41856 | I13: 41.5
A14: 7 | B14: 08-0185 | C14: 41864 | D14: 27.9 | E14: YUSEN LOGISTICS | F14: 104015799 | G14: 08-0185 | H14: 41864 | I14: 27.9
A15: 8 | B15: 08-0677 | C15: 41882 | D15: 143 | E15: YUSEN LOGISTICS | F15: 104015799 | G15: 08-0677 | H15: 41882 | I15: 143
A16: 9 | B16: 08-0685 | C16: 41882 | D16: 60.33 | E16: YUSEN LOGISTICS | F16: 104015799 | G16: 08-0685 | H16: 41882 | I16: 60.33
A17: 10 | B17: 09-0111 | C17: 41892 | D17: 27.53 | E17: YUSEN LOGISTICS | F17: 104015799 | G17: 09-0111 | H17: 41892 | I17: 27.53
A18: 11 | B18: 09-0117 | C18: 41892 | D18: 53.64 | E18: YUSEN LOGISTICS | F18: 104015799 | G18: 09-0117 | H18: 41892 | I18: 53.64
A19: 12 | B19: 09-0199 | C19: 41898 | D19: 34.77 | E19: YUSEN LOGISTICS | F19: 104015799 | G19: 09-0199 | H19: 41898 | I19: 34.77
... A40: 33 | B40: 502-0531 | C40: 42059 | D40: 102.92 | E40: YUSEN LOGISTICS | F40: 104015799 | G40: 502-0531 | H40: 42059 | I40: 102.92
A41: TOTAL 7/2012-02/2015 | D41: =SUM(D8:D40) | I41: =SUM(I8:I40)
E44: YUSEN LOGISTICS | F44: 104015799 | G44: 2-00309 | H44: 41619 | I44: 5

Sheet S G L CAMBODIA
A1: តារាងឧបសម្ព័ន្ឋ
A2: តារាងប្រៀធៀបវិក្ក័យប័ត្រស្នើសុំបង្វិលសងអាករលើតំលៃបន្ថែម ( Cross checking )
A3: នាមករណ៏សហគ្រាស : Maurea Garments Corp
A4: VAT TIN : 1 0 0 0 5 2 9 6 7
A5: ល.រ | B5: ក្រុមហ៊ុនស្នើសុំបង្វិលសង | E5: អ្នកផ្គត់ផ្គង់ | J5: ផ្សេងៗ
B6: វិក័យបត្រ័ | E6: សហគ្រាស | F6: លេខអតប | G6: វិក័យបត្រ័
B7: លេខ | C7: ថ្ងៃទី ខែ ឆ្នាំ | D7: ប្រាក់អាករ | G7: លេខ | H7: ថ្ងៃទី ខែ ឆ្នាំ | I7: ប្រាក់អាករ
A8: 1 | B8: 227231 | C8: 41246 | D8: 8.5 | E8: S G L CAMBODIA | F8: 100119816 | G8: 227231 | H8: 41246 | I8: 8.5
A9: 2 | B9: 227288 | C9: 41246 | D9: 52.36 | E9: S G L CAMBODIA | F9: 100119816 | G9: 227288 | H9: 41246 | I9: 52.36
A10: 3 | B10: 227430 | C10: 41255 | D10: 21.2 | E10: S G L CAMBODIA | F10: 100119816 | G10: 227430 | H10: 41255 | I10: 21.2
A11: 4 | B11: 227461 | C11: 41255 | D11: 29.57 | E11: S G L CAMBODIA | F11: 100119816 | G11: 227461 | H11: 41255 | I11: 29.57
A12: 5 | B12: 227539 | C12: 41260 | D12: 34.24 | E12: S G L CAMBODIA | F12: 100119816 | G12: 227539 | H12: 41260 | I12: 34.24
A13: 6 | B13: 227543 | C13: 41260 | D13: 8.93 | E13: S G L CAMBODIA | F13: 100119816 | G13: 227543 | H13: 41260 | I13: 8.93
A14: 7 | B14: 227552 | C14: 41260 | D14: 27.62 | E14: S G L CAMBODIA | F14: 100119816 | G14: 227552 | H14: 41260 | I14: 27.62
A15: 8 | B15: 227583 | C15: 41261 | D15: 57.77 | E15: S G L CAMBODIA | F15: 100119816 | G15: 227583 | H15: 41261 | I15: 57.77
A16: 9 | B16: 227586 | C16: 41261 | D16: 24 | E16: S G L CAMBODIA | F16: 100119816 | G16: 227586 | H16: 41261 | I16: 24
A17: 10 | B17: 227605 | C17: 41261 | D17: 28.88 | E17: S G L CAMBODIA | F17: 100119816 | G17: 227605 | H17: 41261 | I17: 28.88
A18: 11 | B18: 227826 | C18: 41274 | D18: 24 | E18: S G L CAMBODIA | F18: 100119816 | G18: 227826 | H18: 41274 | I18: 24
A19: 12 | B19: 227862 | C19: 41274 | D19: 36.26 | E19: S G L CAMBODIA | F19: 100119816 | G19: 227862 | H19: 41274 | I19: 36.26
... A458: 455 | B458: 443954 | C458: 42002 | D458: 44.24 | E458: S G L CAMBODIA | F458: 100119816 | G458: 443954 | H458: 42002 | I458: 44.24
A459: TOTAL 7/2012-02/2015 | D459: =SUM(D8:D458) | I459: =SUM(I8:I458)

Sheet Sheet3
A1: តារាងឧបសម្ព័ន្ឋ
A2: តារាងប្រៀធៀបវិក្ក័យប័ត្រស្នើសុំបង្វិលសងអាករលើតំលៃបន្ថែម ( Cross checking )
A3: នាមករណ៏សហគ្រាស : Maurea Garments Corp
A4: VAT TIN : 1 0 0 0 5 2 9 6 7
A5: ល.រ | B5: ក្រុមហ៊ុនស្នើសុំបង្វិលសង | E5: អ្នកផ្គត់ផ្គង់ | J5: ផ្សេងៗ
B6: វិក័យបត្រ័ | E6: សហគ្រាស | F6: លេខអតប | G6: វិក័យបត្រ័
B7: លេខ | C7: ថ្ងៃទី ខែ ឆ្នាំ | D7: ប្រាក់អាករ | G7: លេខ | H7: ថ្ងៃទី ខែ ឆ្នាំ | I7: ប្រាក់អាករ

Sheet Sale - June
A1: សៀវភៅទិនានុប្បវត្តិលក់- នាំចេញ
A2: ខែ​​ មិថុនា ឆ្នាំ ២០១៥
A3: ជី អេវើរហ្រ្គីន( ខេមបូឌា​ ) នីតធីង | K3: Vat:100193102
A4: ភូមិជ្រៃកោង សង្កាត់ចោមចៅ ខណ្ឌ ពោធិសែនជ័យ ក្រុង ភ្នំពេញ | K4: Average: | L4: 4088
A5: វិក្ក័យប័ត្រ | I5: ការផ្គត់ផ្គង់
A6: កាលបរិចេ្ឆទ | B6: វិក្ក័យប័ត្រ | C6: អ្នកទិញ | D6: លេខ អតប | E6: បរិយាយ | F6: បរិមាណ | I6: karlk;Cab;Gakr | M6: សរុបថ្លៃទិញ
D7: TIN | G7: ការផ្គត់ផ្គង់ | H7: ការនាំចេញ | I7: lk;;»übuKþlCab;Gakr | K7: lk;;»üGñkeRbIR)as; | M7: រួមទាំអាករ
G8: មិនជាប់អាករ | H8: អត្រា​​ 0 % | I8: តំលៃជាប់អាករ | J8: អាករ | K8: តំលៃជាប់អាករ | L8: អាករ
A9: 42160 | B9: E 55119 | C9: LPP S.A | E9: Men's Top | F9: 137 CT | H9: 41519138 | M9: =G9+H9
A10: 42160 | B10: E 53624 | C10: PRIMARK | E10: See Val Note | F10: 655 CT | H10: 157610622 | M10: =G10+H10
A11: 42160 | B11: E 9812 | C11: SMYK SP Z.O.O | E11: Girls Knitted Dress | F11: 518 CT | H11: 75926121 | M11: =G11+H11
A12: 42164 | B12: E 10122 | C12: SMYK SP Z.O.O | E12: Girls Knitted Sweat Shirt | F12: 404 CT | H12: 109260590 | M12: =G12+H12
A13: 42167 | B13: E 57854 | C13: PRIMARK | E13: Men's Long Sleeve Hoodie | F13: 550 CT | H13: 136860570 | M13: =G13+H13
A14: 42167 | B14: E 57078 | C14: LPP S.A | E14: Men's Top | F14: 1094 CT | H14: 189450332 | M14: =G14+H14
A15: 42174 | B15: E 60607 | C15: CAPRI SRL | E15: Men's Hoody | F15: 827 CT | H15: 267888456 | M15: =G15+H15
A16: 42174 | B16: E 59730 | C16: LPP S.A | E16: Men's Jogging Top | F16: 815 CT | H16: 233561904 | M16: =G16+H16
A17: 42174 | B17: E 60079 | C17: LPP S.A | E17: Men's Sweater +Top | F17: 400 CT | H17: 106100285 | M17: =G17+H17
A18: 42175 | B18: E 61426 | C18: VISAGE LIMITED | E18: Men's Pari / Monica / Leyton Crew | F18: 556 CT | H18: 145296432 | M18: =G18+H18
A19: 42175 | B19: E 61432 | C19: PRIMARK STORES LIMITED | E19: See Val Note | F19: 1220 CT | H19: 299682480 | M19: =G19+H19
A20: 42181 | B20: E 63424 | C20: PRIMARK US CORP | E20: Men Chest Print Zip | F20: 37 CT | H20: 6493691 | M20: =G20+H20
... A22: 42181 | B22: E 63568 | C22: VISAGE LIMITED | E22: Men's Morgan Crew + Connect Crew+ Leyton | F22: 338 CT | H22: 94840834 | M22: =G22+H22
A23: =L4 | E23: Riel | F23: =SUM(F9:F22) | H23: =SUM(H9:H22) | M23: =SUM(M9:M22)
