Workbook
Name \A: #REF!
Name \D: #REF!
Name \E: #REF!
Name \G: '[1]Company Related Premises'!#REF!
Name \H: '[1]Company Related Premises'!#REF!
Name \L: '[1]Company Related Premises'!#REF!
Name \M: '[1]Company Related Premises'!#REF!
Name \N: #REF!
Name \O: #REF!
Name \P: #REF!
Name \Q: #REF!
Name \R: #REF!
Name \S: #REF!
Name \T: #REF!
Name \U: #REF!
Name \V: #REF!
Name \W: #REF!
Name \X: #REF!
Name \xy: #REF!
Name \Y: #REF!
Name \Z: #REF!
Name __PR1: [2]Sheet!#REF!
Name __SR1: #REF!
Name __SR2: #REF!
Name _PR1: [2]Sheet!#REF!
Name _SR1: #REF!
Name _SR2: #REF!
Name aa: #REF!
Name aaa: #REF!
Name abcd: #REF!
Name All: #REF!
Name ANLAGE_III: [3]Anlagevermögen!$A$1:$Z$29
Name data84: '[4]Purchase Order'!$E$40
Name dflt3: '[4]Customize Your Purchase Order'!$F$24
Name dflt4: '[4]Customize Your Purchase Order'!$E$25
Name DRPAUSE: #REF!
Name DSCTEMP: [5]DSCTEMP!$A$1:$B$65536
Name FTBSch: [2]Sheet!#REF!
Name hh: [2]Sheet!#REF!
Name is: '[6]Company Related Premises'!#REF!
Name jngiüorajg: #REF!
Name ll: #REF!
Name new: #REF!
Name PeriodsInYear: #REF!
Name PrintArea: #REF!
Name qqqqqqqqqqqqqqqqqqqqq: #REF!
Name RANDO: #REF!
Name RANDU: #REF!
Name re: [7]Sheet!#REF!
Name Report: #REF!
Name Sale: #REF!
Name SalSch: #REF!
Name Seite1: #REF!
Name Seite2: #REF!
Name Seite3: #REF!
Name Spec: #REF!
Name SR: #REF!
Name SRC: #REF!
Name tes: [2]Sheet!#REF!
Name Test: [2]Sheet!#REF!

Sheet Company information
B2: COMPANY NAME (KHMER) | D2: វីអ៊ីស៊ិន (ខេមបូឌា) អ៊ិនដាសស្ទ្រី ឯ.ក | F2: Audit timeline
B3: COMPANY NAME (ENGLISH) | D3: Viiition (Cambodia)
B4: VAT NUMBER | D4: L001-901905215 | F4: MOC NUMBER
B5: Business Activity | F5: MOC DATE OF ISSUE
B6: Address Main | D6: ផ្ទះលេខ ​ ផ្លូវ ​ ភូមិស្រង់ ឃុំស្រង់ ស្រុកគងពិសី ខេត្តកំពង់ស្ពឺ | F6: PATENT ISSUE DATE
B7: Request Period | F7: VAT CERTIFICATE ISSUE DATE
B8: Auditor Name | F8: Request Date
F9: Amount of Request
B10: Phone Number | D10: 011777957
B11: BANK ACCOUNT NUMBER TO REFUND
B12: BANK NAME:
B13: Person to Contact
B14: Position

Sheet Annex I-IM State Charge
A1: តារាងឧបសម្ព័ន្ធ I
A2: បញ្ជាក់អំពីអាករលើធាតុចូលដែលមិនអាចស្នើសុំជាឥណទាន
A3: ( ការនាំចូលជាបន្ទុករបស់រដ្ឋ )
A4: ក្រុមហ៊ុន៖ | B4: ='Company information'!C2 | G4: សវនករពន្ធដារ៖ | H4: ='Company information'!C8
A5: លេខ អតប៖ | B5: ='Company information'!C4 | H5: ='Company information'!D8
A6: ='Company information'!H8 | G6: ទឹកប្រាក់ស្នើសុំបង្វិលសងចំនួន៖ | H6: ='Company information'!H9
A7: ល.រ | B7: បរិយាយ | C7: ប្រតិវេទន៍គយនាំចូល/វិក្កយបត្រ | E7: បង្កាន់ដៃទទួលប្រាក់ | G7: ប្រាក់អាករ (រៀល) | H7: ផ្សេងៗ
C8: លេខ | D8: ចុះថ្ងៃទី ខែ ឆ្នាំ | E8: លេខ | F8: ថ្ងៃ ខែ ឆ្នាំ
A4213: សរុបអាករលើការនាំចូលជាបន្ទុករដ្ឋ | G4213: =SUM(G9:G4212)
E4215: រាជធានីភ្នំពេញ.ថ្ងៃទី ខែ ឆ្នាំ២០២៤
E4216: មន្ត្រីសវនកម្ម
E4219: ='Company information'!C9 | H4219: ='Company information'!D9

Sheet Annex II-IM Non-State Charge
A1: តារាងឧបសម្ព័ន្ធ II
A2: តារាងផ្ទៀងផ្ទាត់បញ្ជាក់អំពីអាករលើធាតុចូលដែលអាចស្នើសុំជាឥណទាន
A3: ( ការនាំចូល ឬ អាករគិតជំនួស(Reverse Charge))
A4: ក្រុមហ៊ុន៖ | B4: ='Company information'!C2 | G4: សវនករពន្ធដារ៖ | H4: ='Company information'!C8
A5: លេខ អតប៖ | B5: ='Company information'!C4 | H5: ='Company information'!D8
A6: ='Company information'!H8 | G6: ទឹកប្រាក់ស្នើសុំបង្វិលសងចំនួន៖ | H6: ='Company information'!H9
A7: ល.រ | B7: បរិយាយ | C7: ប្រតិវេទន៍គយនាំចូល/ វិក្កយបត្រ | E7: បង្កាន់ដៃទទួលប្រាក់ | G7: ប្រាក់អាករ (រៀល) | H7: លទ្ធផលផ្ទៀងផ្ទាត់ជាមួយទិន្នន័យពីអគ្គនាយកដ្ឋានគយ/ ឬ អាករគិតជំនួស(Reverse Charge) | I7: ផ្សេងៗ
C8: លេខ | D8: ចុះថ្ងៃទី ខែ ឆ្នាំ | E8: លេខ | F8: ថ្ងៃ ខែ ឆ្នាំ | J8: បានប្រកាស | K8: ខ្វះ
A17: សរុបអាករលើការនាំចូលជាមិនមែនបន្ទុករដ្ឋ | G17: =SUM(G9:G16)
G19: រាជធានីភ្នំពេញ.ថ្ងៃទី ខែ ឆ្នាំ២០២៥
G20: មន្ត្រីសវនកម្ម
G23: ='Company information'!C9 | H23: ='Company information'!D9

Sheet AnnexIII-Local Pur
A1: តារាងឧបសម្ព័ន្ធ III
A2: តារាងផ្ទៀងផ្ទាត់បញ្ជាក់អំពីអាករលើធាតុចូលដែលអាចស្នើសុំជាឥណទាន
A3: (ការទិញក្នុងស្រុក)
A4: ក្រុមហ៊ុន៖ | B4: ='Company information'!C2 | I4: សវនករពន្ធដារ៖ | K4: ='Company information'!C8
A5: លេខ អតប៖ | B5: ='Company information'!C4 | K5: ='Company information'!D8 | L5: FOR REPORT | R5: សម្គាល់ផ្សេងៗ | T5: បញ្ចូលទិន្នន័យ
A6: ='Company information'!H8 | I6: ទឹកប្រាក់ស្នើសុំបង្វិលសងចំនួន៖ | J6: ='Company information'!H9
A7: ល.រ | B7: បរិយាយ | C7: អ្នកផ្គត់ផ្គង់ | D7: លេខ អតប | E7: វិក្កយបត្រ | G7: ទឹកប្រាក់អាករ | J7: ស្ថានភាព | K7: ផ្សេង (សម្គាល់) | O7: VAR INVOICE T/F | P7: VAR. DATE T/F | Q7: VAR. SUPPLIER & PUCHASER | R7: តេស្តទឹកប្រាក់លម្អៀង | S7: សម្កាល់ | T7: កាលបរិច្ឆេទ | U7: លេខវិក្កយបត្រ ឬប្រតិវេទគយ | V7: លេខលិខិតជូនដំណឹងឥណទាន | W7: អ្នកទិញ | Z7: តម្លៃសរុបលើវិក្កយបត្រ | AA7: តម្លៃ​​មិន​រួមអតប និងមិនជាប់​អតប​ | AC7: អាករលើតម្លៃបន្ថែមអត្រា ០% | AD7: អាករលើតម្លៃបន្ថែម | AF7: Under
E8: លេខ | F8: ថ្ងៃ ខែ ឆ្នាំ | G8: ជាដុល្លារអាមេរិក | H8: អត្រា | I8: ជារៀល | W8: ប្រភេទ | X8: លេខសម្គាល់ចុះបញ្ជីពន្ធដា TIN/BIN/TID | Y8: ឈ្មោះ | AA8: តម្លៃមិនរួមអតប | AB8: ការលក់មិនជាប់អតប | AD8: ការលក់ក្នុងស្រុក | AE8: អតបលើការនាំចេញ
B9: description | C9: supplier_name | D9: supplier_tin | E9: invoice_no | F9: date | I9: vat | L9: បានប្រកាស | M9: នៅខ្វះ | T9: date | U9: vat_local_sale | V9: credit_notification_letter_number | W9: type | X9: tax_registration_id | Y9: buyer_name | Z9: total_invoice_amount | AA9: amount_exclude_vat | AB9: non_vat_sales | AC9: vat_zero_rate | AD9: vat_local_sale | AE9: vat_export
A10: 1 | B10: Rental Building E G& L | C10: JALIANKA INTERNATIONAL (CAMBODIA) CO., LTD. | D10: B105-901907504 | E10: JILLANKA2401049 | F10: 45596 | I10: 20811742 | J10: អនុញ្ញាត (បានប្រកាស) | L10: =I10 | M10: =I10-L10 | N10: បានពិនិត្យវិក្កយបត្រ | O10: =U10=E10 | P10: =MONTH(F10)-MONTH(T10) | Q10: =$B$5=X10 | R10: =I10-AD10 | T10: 45596 | U10: JILLANKA2401049 | V10: 0 | W10: បុគ្គលជាប់អាករ | X10: L001-901640009 | Y10: ហូលីដេ ឌីហ្សាញ (ខេមបូឌា) ឯ.ក | Z10: 228929166 | AA10: 208117424 | AB10: 0 | AC10: - | AD10: 20811742 | AE10: 0 | AF10: 0 | AG10: 0 | AH10: 0 | AI10: 0 | AJ10: 0 | AK10: 0 | AL10: 0.01 | AM10: 0 | AN10: Rental Building E , G, L | AO10: បានប្រកាសនិងបង់ពន្ធ
A11: =A10+1 | B11: Rental Building D & F | C11: JALIANKA INTERNATIONAL (CAMBODIA) CO., LTD. | D11: B105-901907504 | E11: JILLANKA2401047 | F11: 45596 | I11: 13082860 | J11: អនុញ្ញាត (បានប្រកាស) | L11: =I11 | M11: =I11-L11 | N11: បានពិនិត្យវិក្កយបត្រ | O11: =U11=E11 | P11: =MONTH(F11)-MONTH(T11) | Q11: =$B$5=X11 | R11: =I11-AD11 | T11: 45596 | U11: JILLANKA2401047 | V11: 0 | W11: បុគ្គលជាប់អាករ | X11: L001-901640009 | Y11: ហូលីដេ ឌីហ្សាញ (ខេមបូឌា) ឯ.ក | Z11: 143911460 | AA11: 130828600 | AB11: 0 | AC11: - | AD11: 13082860 | AE11: 0 | AF11: 0 | AG11: 0 | AH11: 0 | AI11: 0 | AJ11: 0 | AK11: 0 | AL11: 0.01 | AM11: 0 | AN11: Rental Building D , F | AO11: បានប្រកាសនិងបង់ពន្ធ
A12: =A11+1 | B12: Rental Building D & F | C12: JALIANKA INTERNATIONAL (CAMBODIA) CO., LTD. | D12: B105-901907504 | E12: JILLANKA2401052 | F12: 45626 | I12: 12970160 | J12: អនុញ្ញាត (បានប្រកាស) | L12: =I12 | M12: =I12-L12 | N12: បានពិនិត្យវិក្កយបត្រ | O12: =U12=E12 | P12: =MONTH(F12)-MONTH(T12) | Q12: =$B$5=X12 | R12: =I12-AD12 | T12: 45626 | U12: JILLANKA2401052 | V12: 0 | W12: បុគ្គលជាប់អាករ | X12: L001-901640009 | Y12: ហូលីដេ ឌីហ្សាញ (ខេមបូឌា) ឯ.ក | Z12: 142671760 | AA12: 129701600 | AB12: 0 | AC12: - | AD12: 12970160 | AE12: 0 | AF12: 0 | AG12: 0 | AH12: 0 | AI12: 0 | AJ12: 0 | AK12: 0 | AL12: 0.01 | AM12: 0 | AN12: Rental Building D , F | AO12: បានប្រកាសនិងបង់ពន្ធ
A13: =A12+1 | B13: Rental Building E G& L | C13: JALIANKA INTERNATIONAL (CAMBODIA) CO., LTD. | D13: B105-901907504 | E13: JILLANKA2401054 | F13: 45626 | I13: 20632463 | J13: អនុញ្ញាត (បានប្រកាស) | L13: =I13 | M13: =I13-L13 | N13: បានពិនិត្យវិក្កយបត្រ | O13: =U13=E13 | P13: =MONTH(F13)-MONTH(T13) | Q13: =$B$5=X13 | R13: =I13-AD13 | T13: 45626 | U13: JILLANKA2401054 | V13: 0 | W13: បុគ្គលជាប់អាករ | X13: L001-901640009 | Y13: ហូលីដេ ឌីហ្សាញ (ខេមបូឌា) ឯ.ក | Z13: 226957096 | AA13: 206324633 | AB13: 0 | AC13: - | AD13: 20632463 | AE13: 0 | AF13: 0 | AG13: 0 | AH13: 0 | AI13: 0 | AJ13: 0 | AK13: 0 | AL13: 0.01 | AM13: 0 | AN13: Rental Building E , G, L | AO13: បានប្រកាសនិងបង់ពន្ធ
A14: =A13+1 | B14: Rental Building E G& L | C14: JALIANKA INTERNATIONAL (CAMBODIA) CO., LTD. | D14: B105-901907504 | E14: JILLANKA2401060 | F14: 45657 | I14: 20617097 | J14: អនុញ្ញាត (បានប្រកាស) | L14: =I14 | M14: =I14-L14 | N14: បានពិនិត្យវិក្កយបត្រ | O14: =U14=E14 | P14: =MONTH(F14)-MONTH(T14) | Q14: =$B$5=X14 | R14: =I14-AD14 | T14: 45657 | U14: JILLANKA2401060 | V14: 0 | W14: បុគ្គលជាប់អាករ | X14: L001-901640009 | Y14: ហូលីដេ ឌីហ្សាញ (ខេមបូឌា) ឯ.ក | Z14: 226788062 | AA14: 206170965 | AB14: 0 | AC14: - | AD14: 20617097 | AE14: 0 | AF14: 0 | AG14: 0 | AH14: 0 | AI14: 0 | AJ14: 0 | AK14: 0 | AL14: 0.01 | AM14: 0 | AN14: Rental Building E , G, L | AO14: បានប្រកាសនិងបង់ពន្ធ
A15: =A14+1 | B15: Rental Building D & F | C15: JALIANKA INTERNATIONAL (CAMBODIA) CO., LTD. | D15: B105-901907504 | E15: JILLANKA2401058 | F15: 45657 | I15: 12960500 | J15: អនុញ្ញាត (បានប្រកាស) | L15: =I15 | M15: =I15-L15 | N15: បានពិនិត្យវិក្កយបត្រ | O15: =U15=E15 | P15: =MONTH(F15)-MONTH(T15) | Q15: =$B$5=X15 | R15: =I15-AD15 | T15: 45657 | U15: JILLANKA2401058 | V15: 0 | W15: បុគ្គលជាប់អាករ | X15: L001-901640009 | Y15: ហូលីដេ ឌីហ្សាញ (ខេមបូឌា) ឯ.ក | Z15: 142565500 | AA15: 129605000 | AB15: 0 | AC15: - | AD15: 12960500 | AE15: 0 | AF15: 0 | AG15: 0 | AH15: 0 | AI15: 0 | AJ15: 0 | AK15: 0 | AL15: 0.01 | AM15: 0 | AN15: Rental Building D , F | AO15: បានប្រកាសនិងបង់ពន្ធ
A16: =A15+1 | B16: Terminal Handling | C16: EXPEDITORS CAMBODIA LTD. | D16: L001-100045898 | E16: TI-0292395 | F16: 45574 | I16: 522149 | J16: អនុញ្ញាត (បានប្រកាស) | L16: =I16 | M16: =I16-L16 | O16: =U16=E16 | P16: =MONTH(F16)-MONTH(T16) | Q16: =$B$5=X16 | R16: =I16-AD16 | T16: 45574 | U16: TI-0292395 | V16: 0 | W16: បុគ្គលជាប់អាករ | X16: L001-901640009 | Y16: ហូលីដេ ឌីហ្សាញ (ខេមបូឌា) ឯ.ក | Z16: 5743642 | AA16: 5221493 | AB16: 0 | AC16: - | AD16: 522149 | AE16: 0 | AF16: 0 | AG16: 0 | AH16: 0 | AI16: 0 | AJ16: 0 | AK16: 0 | AL16: 0.01 | AM16: 0 | AN16: Local Charge
A17: =A16+1 | B17: BL Amendment | C17: EXPEDITORS CAMBODIA LTD. | D17: L001-100045898 | E17: TI-0292567 | F17: 45575 | I17: 24396 | J17: អនុញ្ញាត (បានប្រកាស) | L17: =I17 | M17: =I17-L17 | O17: =U17=E17 | P17: =MONTH(F17)-MONTH(T17) | Q17: =$B$5=X17 | R17: =I17-AD17 | T17: 45575 | U17: TI-0292567 | V17: 0 | W17: បុគ្គលជាប់អាករ | X17: L001-901640009 | Y17: ហូលីដេ ឌីហ្សាញ (ខេមបូឌា) ឯ.ក | Z17: 268356 | AA17: 243960 | AB17: 0 | AC17: - | AD17: 24396 | AE17: 0 | AF17: 0 | AG17: 0 | AH17: 0 | AI17: 0 | AJ17: 0 | AK17: 0 | AL17: 0.01 | AM17: 0 | AN17: Local Charge
A18: =A17+1 | B18: Detention | C18: EXPEDITORS CAMBODIA LTD. | D18: L001-100045898 | E18: TI-0292734 | F18: 45579 | I18: 16248 | J18: អនុញ្ញាត (បានប្រកាស) | L18: =I18 | M18: =I18-L18 | O18: =U18=E18 | P18: =MONTH(F18)-MONTH(T18) | Q18: =$B$5=X18 | R18: =I18-AD18 | T18: 45579 | U18: TI-0292734 | V18: 0 | W18: បុគ្គលជាប់អាករ | X18: L001-901640009 | Y18: ហូលីដេ ឌីហ្សាញ (ខេមបូឌា) ឯ.ក | Z18: 178728 | AA18: 162480 | AB18: 0 | AC18: - | AD18: 16248 | AE18: 0 | AF18: 0 | AG18: 0 | AH18: 0 | AI18: 0 | AJ18: 0 | AK18: 0 | AL18: 0.01 | AM18: 0 | AN18: Local Charge
A19: =A18+1 | B19: Detention | C19: EXPEDITORS CAMBODIA LTD. | D19: L001-100045898 | E19: TI-0292731 | F19: 45579 | I19: 40620 | J19: អនុញ្ញាត (បានប្រកាស) | L19: =I19 | M19: =I19-L19 | O19: =U19=E19 | P19: =MONTH(F19)-MONTH(T19) | Q19: =$B$5=X19 | R19: =I19-AD19 | T19: 45579 | U19: TI-0292731 | V19: 0 | W19: បុគ្គលជាប់អាករ | X19: L001-901640009 | Y19: ហូលីដេ ឌីហ្សាញ (ខេមបូឌា) ឯ.ក | Z19: 446820 | AA19: 406200 | AB19: 0 | AC19: - | AD19: 40620 | AE19: 0 | AF19: 0 | AG19: 0 | AH19: 0 | AI19: 0 | AJ19: 0 | AK19: 0 | AL19: 0.01 | AM19: 0 | AN19: Local Charge
A20: =A19+1 | B20: Detention | C20: EXPEDITORS CAMBODIA LTD. | D20: L001-100045898 | E20: TI-0292738 | F20: 45579 | I20: 8124 | J20: អនុញ្ញាត (បានប្រកាស) | L20: =I20 | M20: =I20-L20 | O20: =U20=E20 | P20: =MONTH(F20)-MONTH(T20) | Q20: =$B$5=X20 | R20: =I20-AD20 | T20: 45579 | U20: TI-0292738 | V20: 0 | W20: បុគ្គលជាប់អាករ | X20: L001-901640009 | Y20: ហូលីដេ ឌីហ្សាញ (ខេមបូឌា) ឯ.ក | Z20: 89364 | AA20: 81240 | AB20: 0 | AC20: - | AD20: 8124 | AE20: 0 | AF20: 0 | AG20: 0 | AH20: 0 | AI20: 0 | AJ20: 0 | AK20: 0 | AL20: 0.01 | AM20: 0 | AN20: Local Charge
A21: =A20+1 | B21: Detention | C21: EXPEDITORS CAMBODIA LTD. | D21: L001-100045898 | E21: TI-0292732 | F21: 45579 | I21: 16248 | J21: អនុញ្ញាត (បានប្រកាស) | L21: =I21 | M21: =I21-L21 | O21: =U21=E21 | P21: =MONTH(F21)-MONTH(T21) | Q21: =$B$5=X21 | R21: =I21-AD21 | T21: 45579 | U21: TI-0292732 | V21: 0 | W21: បុគ្គលជាប់អាករ | X21: L001-901640009 | Y21: ហូលីដេ ឌីហ្សាញ (ខេមបូឌា) ឯ.ក | Z21: 178728 | AA21: 162480 | AB21: 0 | AC21: - | AD21: 16248 | AE21: 0 | AF21: 0 | AG21: 0 | AH21: 0 | AI21: 0 | AJ21: 0 | AK21: 0 | AL21: 0.01 | AM21: 0 | AN21: Local Charge
A22: =A21+1 | B22: Rental Building E G& L | C22: JALIANKA INTERNATIONAL (CAMBODIA) CO., LTD. | D22: B105-901907504 | E22: JILLANKA2501004 | F22: 45688 | I22: 20611974 | J22: អនុញ្ញាត (បានប្រកាស) | L22: =I22 | M22: =I22-L22 | N22: បានពិនិត្យវិក្កយបត្រ | O22: =U22=E22 | P22: =MONTH(F22)-MONTH(T22) | Q22: =$B$5=X22 | R22: =I22-AD22 | T22: 45688 | U22: JILLANKA2501004 | V22: 0 | W22: បុគ្គលជាប់អាករ | X22: L001-901640009 | Y22: ហូលីដេ ឌីហ្សាញ (ខេមបូឌា) ឯ.ក | Z22: 226731717 | AA22: 206119743 | AB22: 0 | AC22: - | AD22: 20611974 | AE22: 0 | AF22: 0 | AG22: 0 | AH22: 0 | AI22: 0 | AJ22: 0 | AK22: 0 | AL22: 0.01 | AM22: 0 | AN22: Rental Building E , G, L | AO22: បានប្រកាសនិងបង់ពន្ធ
A23: =A22+1 | B23: CREDIT | C23: EXPEDITORS CAMBODIA LTD. | D23: L001-100045898 | E23: TI-0292897 | F23: 45581 | I23: -72674 | J23: អនុញ្ញាត (បានប្រកាស) | L23: =I23 | M23: =I23-L23 | O23: =U23=E23 | P23: =MONTH(F23)-MONTH(T23) | Q23: =$B$5=X23 | R23: =I23-AD23
A24: =A23+1 | B24: CREDIT | C24: EXPEDITORS CAMBODIA LTD. | D24: L001-100045898 | E24: TI-0295955 | F24: 45603 | I24: -2032 | J24: អនុញ្ញាត (បានប្រកាស) | L24: =I24 | M24: =I24-L24 | O24: =U24=E24 | P24: =MONTH(F24)-MONTH(T24) | Q24: =$B$5=X24 | R24: =I24-AD24
A25: =A24+1 | B25: Rental Building D & F | C25: JALIANKA INTERNATIONAL (CAMBODIA) CO., LTD. | D25: B105-901907504 | E25: JILLANKA2501002 | F25: 45688 | I25: 12957280 | J25: អនុញ្ញាត (បានប្រកាស) | L25: =I25 | M25: =I25-L25 | N25: បានពិនិត្យវិក្កយបត្រ | O25: =U25=E25 | P25: =MONTH(F25)-MONTH(T25) | Q25: =$B$5=X25 | R25: =I25-AD25 | T25: 45688 | U25: JILLANKA2501002 | V25: 0 | W25: បុគ្គលជាប់អាករ | X25: L001-901640009 | Y25: ហូលីដេ ឌីហ្សាញ (ខេមបូឌា) ឯ.ក | Z25: 142530080 | AA25: 129572800 | AB25: 0 | AC25: - | AD25: 12957280 | AE25: 0 | AF25: 0 | AG25: 0 | AH25: 0 | AI25: 0 | AJ25: 0 | AK25: 0 | AL25: 0.01 | AM25: 0 | AN25: Rental Building D , F | AO25: បានប្រកាសនិងបង់ពន្ធ
A26: =A25+1 | B26: Rental Building E G& L | C26: JALIANKA INTERNATIONAL (CAMBODIA) CO., LTD. | D26: B105-901907504 | E26: JILLANKA2501008 | F26: 45716 | I26: 20545385 | J26: អនុញ្ញាត (បានប្រកាស) | L26: =I26 | M26: =I26-L26 | N26: បានពិនិត្យវិក្កយបត្រ | O26: =U26=E26 | P26: =MONTH(F26)-MONTH(T26) | Q26: =$B$5=X26 | R26: =I26-AD26 | T26: 45716 | U26: JILLANKA2501008 | V26: 0 | W26: បុគ្គលជាប់អាករ | X26: L001-901640009 | Y26: ហូលីដេ ឌីហ្សាញ (ខេមបូឌា) ឯ.ក | Z26: 225999233 | AA26: 205453848 | AB26: 0 | AC26: - | AD26: 20545385 | AE26: 0 | AF26: 0 | AG26: 0 | AH26: 0 | AI26: 0 | AJ26: 0 | AK26: 0 | AL26: 0.01 | AM26: 0 | AN26: Rental Building E , G, L | AO26: បានប្រកាសនិងបង់ពន្ធ
A27: =A26+1 | B27: Rental Building D & F | C27: JALIANKA INTERNATIONAL (CAMBODIA) CO., LTD. | D27: B105-901907504 | E27: JILLANKA2501007 | F27: 45716 | I27: 12915420 | J27: អនុញ្ញាត (បានប្រកាស) | L27: =I27 | M27: =I27-L27 | N27: បានពិនិត្យវិក្កយបត្រ | O27: =U27=E27 | P27: =MONTH(F27)-MONTH(T27) | Q27: =$B$5=X27 | R27: =I27-AD27 | T27: 45716 | U27: JILLANKA2501007 | V27: 0 | W27: បុគ្គលជាប់អាករ | X27: L001-901640009 | Y27: ហូលីដេ ឌីហ្សាញ (ខេមបូឌា) ឯ.ក | Z27: 142069620 | AA27: 129154200 | AB27: 0 | AC27: - | AD27: 12915420 | AE27: 0 | AF27: 0 | AG27: 0 | AH27: 0 | AI27: 0 | AJ27: 0 | AK27: 0 | AL27: 0.01 | AM27: 0 | AN27: Rental Building D , F | AO27: បានប្រកាសនិងបង់ពន្ធ
A28: =A27+1 | B28: Detention Fee | C28: EXPEDITORS CAMBODIA LTD. | D28: L001-100045898 | E28: TI-0298544 | F28: 45625 | I28: 80560 | J28: អនុញ្ញាត (បានប្រកាស) | L28: =I28 | M28: =I28-L28 | O28: =U28=E28 | P28: =MONTH(F28)-MONTH(T28) | Q28: =$B$5=X28 | R28: =I28-AD28 | T28: 45625 | U28: TI-0298544 | V28: 0 | W28: បុគ្គលជាប់អាករ | X28: L001-901640009 | Y28: ហូលីដេ ឌីហ្សាញ (ខេមបូឌា) ឯ.ក | Z28: 886160 | AA28: 805600 | AB28: 0 | AC28: - | AD28: 80560 | AE28: 0 | AF28: 0 | AG28: 0 | AH28: 0 | AI28: 0 | AJ28: 0 | AK28: 0 | AL28: 0.01 | AM28: 0 | AN28: Local Charge
A29: =A28+1 | B29: Detention Fee | C29: EXPEDITORS CAMBODIA LTD. | D29: L001-100045898 | E29: TI-0298481 | F29: 45623 | I29: 16096 | J29: អនុញ្ញាត (បានប្រកាស) | L29: =I29 | M29: =I29-L29 | O29: =U29=E29 | P29: =MONTH(F29)-MONTH(T29) | Q29: =$B$5=X29 | R29: =I29-AD29 | T29: 45623 | U29: TI-0298481 | V29: 0 | W29: បុគ្គលជាប់អាករ | X29: L001-901640009 | Y29: ហូលីដេ ឌីហ្សាញ (ខេមបូឌា) ឯ.ក | Z29: 177056 | AA29: 160960 | AB29: 0 | AC29: - | AD29: 16096 | AE29: 0 | AF29: 0 | AG29: 0 | AH29: 0 | AI29: 0 | AJ29: 0 | AK29: 0 | AL29: 0.01 | AM29: 0 | AN29: Local Charge
A30: =A29+1 | B30: Detention Fee | C30: EXPEDITORS CAMBODIA LTD. | D30: L001-100045898 | E30: TI-0298472 | F30: 45623 | I30: 8048 | J30: អនុញ្ញាត (បានប្រកាស) | L30: =I30 | M30: =I30-L30 | O30: =U30=E30 | P30: =MONTH(F30)-MONTH(T30) | Q30: =$B$5=X30 | R30: =I30-AD30 | T30: 45623 | U30: TI-0298472 | V30: 0 | W30: បុគ្គលជាប់អាករ | X30: L001-901640009 | Y30: ហូលីដេ ឌីហ្សាញ (ខេមបូឌា) ឯ.ក | Z30: 88528 | AA30: 80480 | AB30: 0 | AC30: - | AD30: 8048 | AE30: 0 | AF30: 0 | AG30: 0 | AH30: 0 | AI30: 0 | AJ30: 0 | AK30: 0 | AL30: 0.01 | AM30: 0 | AN30: Local Charge
A31: =A30+1 | B31: Terminal Handling | C31: EXPEDITORS CAMBODIA LTD. | D31: L001-100045898 | E31: TI-0296235 | F31: 45607 | I31: 6089 | J31: អនុញ្ញាត (បានប្រកាស) | L31: =I31 | M31: =I31-L31 | O31: =U31=E31 | P31: =MONTH(F31)-MONTH(T31) | Q31: =$B$5=X31 | R31: =I31-AD31 | T31: 45607 | U31: TI-0296235 | V31: 0 | W31: បុគ្គលជាប់អាករ | X31: L001-901640009 | Y31: ហូលីដេ ឌីហ្សាញ (ខេមបូឌា) ឯ.ក | Z31: 66974 | AA31: 60885 | AB31: 0 | AC31: - | AD31: 6089 | AE31: 0 | AF31: 0 | AG31: 0 | AH31: 0 | AI31: 0 | AJ31: 0 | AK31: 0 | AL31: 0.01 | AM31: 0 | AN31: Local Charge
A32: =A31+1 | B32: Terminal Handling | C32: EXPEDITORS CAMBODIA LTD. | D32: L001-100045898 | E32: TI-0295873 | F32: 45602 | I32: 4064 | J32: អនុញ្ញាត (បានប្រកាស) | L32: =I32 | M32: =I32-L32 | O32: =U32=E32 | P32: =MONTH(F32)-MONTH(T32) | Q32: =$B$5=X32 | R32: =I32-AD32 | T32: 45602 | U32: TI-0295873 | V32: 0 | W32: បុគ្គលជាប់អាករ | X32: L001-901640009 | Y32: ហូលីដេ ឌីហ្សាញ (ខេមបូឌា) ឯ.ក | Z32: 44704 | AA32: 40640 | AB32: 0 | AC32: - | AD32: 4064 | AE32: 0 | AF32: 0 | AG32: 0 | AH32: 0 | AI32: 0 | AJ32: 0 | AK32: 0 | AL32: 0.01 | AM32: 0 | AN32: Local Charge
A33: =A32+1 | B33: Terminal Handling | C33: EXPEDITORS CAMBODIA LTD. | D33: L001-100045898 | E33: TI-0295880 | F33: 45602 | I33: 6096 | J33: អនុញ្ញាត (បានប្រកាស) | L33: =I33 | M33: =I33-L33 | O33: =U33=E33 | P33: =MONTH(F33)-MONTH(T33) | Q33: =$B$5=X33 | R33: =I33-AD33 | T33: 45602 | U33: TI-0295880 | V33: 0 | W33: បុគ្គលជាប់អាករ | X33: L001-901640009 | Y33: ហូលីដេ ឌីហ្សាញ (ខេមបូឌា) ឯ.ក | Z33: 67056 | AA33: 60960 | AB33: 0 | AC33: - | AD33: 6096 | AE33: 0 | AF33: 0 | AG33: 0 | AH33: 0 | AI33: 0 | AJ33: 0 | AK33: 0 | AL33: 0.01 | AM33: 0 | AN33: Local Charge
A34: =A33+1 | B34: Terminal Handling | C34: EXPEDITORS CAMBODIA LTD. | D34: L001-100045898 | E34: TI-0295882 | F34: 45602 | I34: 8128 | J34: អនុញ្ញាត (បានប្រកាស) | L34: =I34 | M34: =I34-L34 | O34: =U34=E34 | P34: =MONTH(F34)-MONTH(T34) | Q34: =$B$5=X34 | R34: =I34-AD34 | T34: 45602 | U34: TI-0295882 | V34: 0 | W34: បុគ្គលជាប់អាករ | X34: L001-901640009 | Y34: ហូលីដេ ឌីហ្សាញ (ខេមបូឌា) ឯ.ក | Z34: 89408 | AA34: 81280 | AB34: 0 | AC34: - | AD34: 8128 | AE34: 0 | AF34: 0 | AG34: 0 | AH34: 0 | AI34: 0 | AJ34: 0 | AK34: 0 | AL34: 0.01 | AM34: 0 | AN34: Local Charge
A35: =A34+1 | B35: Terminal Handling | C35: EXPEDITORS CAMBODIA LTD. | D35: L001-100045898 | E35: TI-0295883 | F35: 45602 | I35: 6096 | J35: អនុញ្ញាត (បានប្រកាស) | L35: =I35 | M35: =I35-L35 | O35: =U35=E35 | P35: =MONTH(F35)-MONTH(T35) | Q35: =$B$5=X35 | R35: =I35-AD35 | T35: 45602 | U35: TI-0295883 | V35: 0 | W35: បុគ្គលជាប់អាករ | X35: L001-901640009 | Y35: ហូលីដេ ឌីហ្សាញ (ខេមបូឌា) ឯ.ក | Z35: 67056 | AA35: 60960 | AB35: 0 | AC35: - | AD35: 6096 | AE35: 0 | AF35: 0 | AG35: 0 | AH35: 0 | AI35: 0 | AJ35: 0 | AK35: 0 | AL35: 0.01 | AM35: 0 | AN35: Local Charge
A36: =A35+1 | B36: Terminal Handling | C36: EXPEDITORS CAMBODIA LTD. | D36: L001-100045898 | E36: TI-0295884 | F36: 45602 | I36: 2032 | J36: អនុញ្ញាត (បានប្រកាស) | L36: =I36 | M36: =I36-L36 | O36: =U36=E36 | P36: =MONTH(F36)-MONTH(T36) | Q36: =$B$5=X36 | R36: =I36-AD36 | T36: 45602 | U36: TI-0295884 | V36: 0 | W36: បុគ្គលជាប់អាករ | X36: L001-901640009 | Y36: ហូលីដេ ឌីហ្សាញ (ខេមបូឌា) ឯ.ក | Z36: 22352 | AA36: 20320 | AB36: 0 | AC36: - | AD36: 2032 | AE36: 0 | AF36: 0 | AG36: 0 | AH36: 0 | AI36: 0 | AJ36: 0 | AK36: 0 | AL36: 0.01 | AM36: 0 | AN36: Local Charge
A37: =A36+1 | B37: Terminal Handling | C37: EXPEDITORS CAMBODIA LTD. | D37: L001-100045898 | E37: TI-0295886 | F37: 45602 | I37: 2032 | J37: អនុញ្ញាត (បានប្រកាស) | L37: =I37 | M37: =I37-L37 | O37: =U37=E37 | P37: =MONTH(F37)-MONTH(T37) | Q37: =$B$5=X37 | R37: =I37-AD37 | T37: 45602 | U37: TI-0295886 | V37: 0 | W37: បុគ្គលជាប់អាករ | X37: L001-901640009 | Y37: ហូលីដេ ឌីហ្សាញ (ខេមបូឌា) ឯ.ក | Z37: 22352 | AA37: 20320 | AB37: 0 | AC37: - | AD37: 2032 | AE37: 0 | AF37: 0 | AG37: 0 | AH37: 0 | AI37: 0 | AJ37: 0 | AK37: 0 | AL37: 0.01 | AM37: 0 | AN37: Local Charge
A38: =A37+1 | B38: Terminal Handling | C38: EXPEDITORS CAMBODIA LTD. | D38: L001-100045898 | E38: TI-0295887 | F38: 45602 | I38: 8128 | J38: អនុញ្ញាត (បានប្រកាស) | L38: =I38 | M38: =I38-L38 | O38: =U38=E38 | P38: =MONTH(F38)-MONTH(T38) | Q38: =$B$5=X38 | R38: =I38-AD38 | T38: 45602 | U38: TI-0295887 | V38: 0 | W38: បុគ្គលជាប់អាករ | X38: L001-901640009 | Y38: ហូលីដេ ឌីហ្សាញ (ខេមបូឌា) ឯ.ក | Z38: 89408 | AA38: 81280 | AB38: 0 | AC38: - | AD38: 8128 | AE38: 0 | AF38: 0 | AG38: 0 | AH38: 0 | AI38: 0 | AJ38: 0 | AK38: 0 | AL38: 0.01 | AM38: 0 | AN38: Local Charge
A39: =A38+1 | B39: Terminal Handling | C39: EXPEDITORS CAMBODIA LTD. | D39: L001-100045898 | E39: TI-0295888 | F39: 45602 | I39: 2032 | J39: អនុញ្ញាត (បានប្រកាស) | L39: =I39 | M39: =I39-L39 | O39: =U39=E39 | P39: =MONTH(F39)-MONTH(T39) | Q39: =$B$5=X39 | R39: =I39-AD39 | T39: 45602 | U39: TI-0295888 | V39: 0 | W39: បុគ្គលជាប់អាករ | X39: L001-901640009 | Y39: ហូលីដេ ឌីហ្សាញ (ខេមបូឌា) ឯ.ក | Z39: 22352 | AA39: 20320 | AB39: 0 | AC39: - | AD39: 2032 | AE39: 0 | AF39: 0 | AG39: 0 | AH39: 0 | AI39: 0 | AJ39: 0 | AK39: 0 | AL39: 0.01 | AM39: 0 | AN39: Local Charge
... A45: =A44+1 | B45: Detention Fee | C45: EXPEDITORS CAMBODIA LTD. | D45: L001-100045898 | E45: TI-0298548 | F45: 45625 | I45: 16112 | J45: អនុញ្ញាត (បានប្រកាស) | L45: =I45 | M45: =I45-L45 | O45: =U45=E45 | P45: =MONTH(F45)-MONTH(T45) | Q45: =$B$5=X45 | R45: =I45-AD45 | T45: 45625 | U45: TI-0298548 | V45: 0 | W45: បុគ្គលជាប់អាករ | X45: L001-901640009 | Y45: ហូលីដេ ឌីហ្សាញ (ខេមបូឌា) ឯ.ក | Z45: 177232 | AA45: 161120 | AB45: 0 | AC45: - | AD45: 16112 | AE45: 0 | AF45: 0 | AG45: 0 | AH45: 0 | AI45: 0 | AJ45: 0 | AK45: 0 | AL45: 0.01 | AM45: 0 | AN45: Local Charge
...

Sheet Annex IV-EX
A1: តារាងឧបសម្ព័ន្ធ IV
A2: បញ្ជាក់អំពីការលក់
A3: (ការនាំចេញ/លក់បន្ទុករដ្ឋ/លក់តាមអត្រា០%)
A4: ក្រុមហ៊ុន៖ | B4: ='Company information'!C2 | D4: សវនករពន្ធដារ៖ | E4: ='Company information'!C8
A5: លេខ អតប ៖ | B5: ='Company information'!C4 | E5: ='Company information'!D8
A6: ='Company information'!H8 | D6: ទឹកប្រាក់ស្នើសុំបង្វិលសងចំនួន៖ | E6: ='Company information'!H9
A7: ល.រ | B7: បរិយាយ | C7: ប្រតិវេទន៍គយនាំចេញ/វិក្កយបត្រ | E7: តម្លៃជារៀល
C8: លេខ | D8: ចុះថ្ងៃទី ខែ ឆ្នាំ
A10: 1 | B10: Sample Aritificail Christmas Trees | C10: E826 | D10: 45666 | E10: 484680
A11: =A10+1 | B11: Artificial Christmas Trees | C11: E65515 | D11: 45744 | E11: 83289380
A12: =A11+1 | B12: Artificial Christmas Trees | C12: E65535 | D12: 45744 | E12: 83289380
A13: =A12+1 | B13: Artificial Christmas Tree | C13: E112738 | D13: 45806 | E13: 59359060
A14: =A13+1 | B14: Artificial Christmas Tree | C14: E103083 | D14: 45793 | E14: 65108778
A15: =A14+1 | B15: Artificial Christmas Tree | C15: E114909 | D15: 45807 | E15: 62091918
A16: =A15+1 | B16: Artificial Christmas Tree | C16: E115070 | D16: 45807 | E16: 229986284
A17: =A16+1 | B17: Artificial Christmas Tree | C17: E102146 | D17: 45793 | E17: 332889882
A18: =A17+1 | B18: Artificial Christmas Tree | C18: E102497 | D18: 45793 | E18: 127028603
A19: =A18+1 | B19: Artificial Christmas Tree | C19: E102119 | D19: 45793 | E19: 395201062
A20: =A19+1 | B20: Artificial Christmas Tree | C20: E103361 | D20: 45793 | E20: 31706405
A21: =A20+1 | B21: Artificial Christmas Tree | C21: E103328 | D21: 45793 | E21: 44852495
A22: =A21+1 | B22: Artificial Christmas Tree | C22: E102362 | D22: 45793 | E22: 258436834
... A137: =A136+1 | B137: Artificial Christmas Tree | C137: E99144 | D137: 45790 | E137: 78785613
A139: ទឹកប្រាក់សរុបចំនួន | E139: =SUM(E10:E137) | I139: =E139+'Annex V-Local Sale'!G12*10
D141: រាជធានីភ្នំពេញ.ថ្ងៃទី ខែ ឆ្នាំ២០២៥
D142: មន្ត្រីសវនកម្ម
D145: ='Company information'!C9 | E145: ='Company information'!D9

Sheet Annex V-Local Sale
A1: តារាងឧបសម្ព័ន្ធ V
A2: បញ្ជាក់អំពីអាករលើធាតុចេញ
A3: ( ការលក់ក្នុងស្រុក )
A4: ក្រុមហ៊ុន៖ | B4: ='Company information'!C2 | G4: សវនករពន្ធដារ៖ | H4: ='Company information'!C8
A5: លេខ អតប ៖ | B5: ='Company information'!C4 | H5: ='Company information'!D8
A6: ='Company information'!H8 | F6: ទឹកប្រាក់ស្នើសុំបង្វិលសងចំនួន៖ | H6: ='Company information'!H9
A7: ល.រ | B7: បរិយាយ | C7: វិក្កយបត្រ | E7: អាករតម្លៃ (ដុល្លា) | F7: អត្រាប្តូរប្រាក់ | G7: អាករតម្លៃ (រៀល) | H7: ផ្សេងៗ
C8: លេខ | D8: ថ្ងៃ ខែ ឆ្នាំ
A10: 1 | B10: Sale Car | C10: 2409002 | D10: 45632 | G10: 6042000
A12: សរុបអាករលើការលក់ក្នុងស្រុក | G12: =SUM(G10:G10)
G14: រាជធានីភ្នំពេញ.ថ្ងៃទី ខែ ឆ្នាំ២០២៥
G15: មន្ត្រីសវនកម្ម
M16: 543815675772
M17: 26860899310
F18: ='Company information'!C9 | H18: ='Company information'!D9 | M18: =SUM(M16:M17)
M19: 40586375597
M20: 5769650
M21: =SUM(M19:M20)

Sheet Taxpaid
C4: ='Company information'!C7
B5: ល.រ | C5: ប្រភេទពន្ធ | D5: ចំនួនទឺកប្រាក់ពន្ធ | E5: 43221 | F5: =EDATE(E5,1) | G5: =EDATE(F5,1) | H5: =EDATE(G5,1) | I5: =EDATE(H5,1) | J5: =EDATE(I5,1) | K5: =EDATE(J5,1) | L5: =EDATE(K5,1) | M5: =EDATE(L5,1) | ... DX5: =EDATE(DW5,1)
B6: 1 | C6: ពន្ធលើប្រាក់បៀវត្ស | D6: =SUM(E6:DX6) | E6: 138869440 | F6: 140885344 | G6: 132428533 | H6: 135869325 | I6: 135942085 | J6: 139853397 | K6: 136657782 | L6: 157030330 | M6: 516408757 | N6: 137808913 | O6: 138355061 | P6: 142234910 | Q6: 143916953 | R6: 188500663 | S6: 141498213 | T6: - | U6: 284584373 | V6: 149452871 | W6: 150360645 | X6: 184870824 | Y6: 491804348 | Z6: 155603306 | AA6: 153585511 | AB6: 132106384 | AC6: 127511678 | AD6: 122547019 | AE6: 124130964 | AF6: 123714960 | AG6: 128548213 | AH6: 130826841 | AI6: 129347721 | AJ6: 167051020 | AK6: 278896324 | AL6: 129672213 | AM6: 159943490 | AN6: 129052482 | AO6: 152256038 | AP6: 154206765 | AQ6: 128373786 | AR6: 127381802 | AS6: 119524398 | AT6: 118858587 | AU6: 128235314 | AV6: 155694726 | AW6: 294047128 | AX6: 126887841 | AY6: 123876900 | AZ6: 125169176 | BA6: 128487000 | BB6: 158458595 | BC6: 131266345 | BD6: 128134452 | BE6: 134453266 | BF6: 136391533 | BG6: 136460596 | BH6: 194974793 | BI6: 480560844 | BJ6: 141367312 | BK6: 125155905 | BL6: 138802989 | BM6: 144412556 | BN6: 178960560 | BO6: 150834592 | BP6: 152359006
B7: 2 | C7: ពន្ធលើអត្ថប្រយោជន៍បន្ថែម | D7: =SUM(E7:DX7) | E7: - | F7: - | G7: - | H7: 43866608 | I7: - | J7: - | K7: - | L7: - | M7: - | N7: - | O7: - | P7: - | Q7: - | R7: 4771113 | S7: - | T7: 78776901 | U7: - | V7: - | W7: - | X7: 2847600 | Y7: - | Z7: 29792018 | AA7: - | AB7: 35488063 | AC7: - | AD7: - | AE7: - | AF7: - | AG7: - | AH7: - | AI7: - | AJ7: 16908100 | AK7: 0 | AL7: 0 | AM7: 0 | AN7: 0 | AO7: 0 | AP7: 0 | AQ7: 0 | AR7: 1631600 | AS7: 0 | AT7: 0 | AU7: 0 | AV7: 3339040 | AW7: 0 | AX7: 5722269 | AY7: 0 | AZ7: 485400 | BA7: 487440 | BB7: 245760 | BC7: 492240 | BD7: 0 | BE7: 247140 | BF7: 2569280 | BG7: 745920 | BH7: 10853613 | BI7: 1754239 | BJ7: 490200 | BK7: 243120 | BL7: 243900 | BM7: 18626742 | BN7: 247080 | BO7: 0 | BP7: 248040
B8: 3 | C8: ប្រាក់រំដោះពន្ធលើប្រាក់ចំណូល | D8: =SUM(E8:DX8) | E8: 192817612 | F8: 199205236 | G8: 213459441 | H8: 214831696 | I8: 207199569 | J8: 203295976 | K8: 209104864 | L8: 212996842 | M8: 219946420 | N8: 203910493 | O8: 224554542 | P8: 211184630 | Q8: 220656751 | R8: 215684056 | S8: 231055168 | T8: - | U8: 445254999 | V8: 219590496 | W8: 222987537 | X8: 225931525 | Y8: 236337458 | Z8: 179294781 | AA8: 118401935 | AB8: 17701491 | AC8: 30317318 | AD8: 44993575 | AE8: 60845527 | AF8: 43606075 | AG8: 42833590 | AH8: 53266106 | AI8: 56200505 | AJ8: 55433490 | AK8: 52063788 | AL8: 41956654 | AM8: 54831011 | AN8: 57810716 | AO8: 45570594 | AP8: 40833356 | AQ8: 42566016 | AR8: 42652046 | AS8: 42329966 | AT8: 49668834 | AU8: 50888337 | AV8: 60797447 | AW8: 59746671 | AX8: 59496546 | AY8: 74800861 | AZ8: 82227934 | BA8: 96846840 | BB8: 113331098 | BC8: 129812629 | BD8: 126045267 | BE8: 118803691 | BF8: 128534047 | BG8: 132094582 | BH8: 138702860 | BI8: 137825101 | BJ8: 127339702 | BK8: 144876441 | BL8: 141937805 | BM8: 148917956 | BN8: 149243308 | BO8: 164417257 | BP8: 162543595
B9: 4 | C9: ពន្ធលើប្រាក់ចំណូលប្រចាំឆ្នាំ | D9: =SUM(E9:DX9) | E9: - | F9: 275642423 | G9: - | H9: - | I9: - | J9: - | K9: - | L9: - | M9: - | N9: - | O9: 16926483457 | P9: - | Q9: - | R9: 1797397128 | S9: - | T9: - | U9: - | V9: - | W9: - | X9: - | Y9: - | Z9: - | AA9: 122652470 | AB9: 1733033592 | AC9: - | AD9: - | AE9: - | AF9: - | AG9: - | AH9: - | AI9: - | AJ9: - | AW9: - | AX9: - | AY9: 3098369034 | AZ9: - | BA9: - | BB9: - | BC9: - | BD9: - | BE9: - | BF9: - | BG9: - | BH9: - | BI9: - | BJ9: - | BK9: 9753892963 | BL9: - | BM9: - | BN9: - | BO9: - | BP9: -
B10: 5 | C10: ពន្ធកាត់ទុកលើសេវាកម្ម ១៥% | D10: =SUM(E10:DX10) | E10: 3222531 | F10: 3228884 | G10: 3793557 | H10: 66557412 | I10: 3466166 | J10: 3236031 | K10: 3209825 | L10: 3196325 | M10: 3079802 | N10: 2546256 | O10: 3828453 | P10: 2720925 | Q10: 2846610 | R10: 2748600 | S10: 2752650 | T10: - | U10: 5522175 | V10: 2806230 | W10: 2825086 | X10: 2829960 | Y10: 3645000 | Z10: 3878470 | AA10: 4708029 | AB10: 20581821 | AC10: 6173994 | AD10: 4156798 | AE10: 3978437 | AF10: 3984260 | AG10: 3979407 | AH10: 3940584 | AI10: 3928936 | AJ10: 3926024 | AK10: 4160641 | AL10: 3949318 | AM10: 3926024 | AN10: 3306969 | AO10: 2924327 | AP10: 2121392 | AQ10: 2119830 | AR10: 2123995 | AS10: 2123474 | AT10: 2406586 | AU10: 2408362 | AV10: 2411321 | AW10: 2334837 | AX10: 2119579 | AY10: 2111239 | AZ10: 2169843 | BA10: 2117494 | BB10: 2136782 | BC10: 2197864 | BD10: 3015799 | BE10: 2151378 | BF10: 3547127 | BG10: 2148772 | BH10: 6164701 | BI10: 3986189 | BJ10: 4704621 | BK10: 5869241 | BL10: 4105799 | BM10: 3997844 | BN10: 4215512 | BO10: 4063920 | BP10: 4038638
B11: 6 | C11: ពន្ធកាត់ទុកលើអនិវាសនជន(ការប្រាក់) | D11: =SUM(E11:DX11)
B12: 7 | C12: ពន្ធកាត់ទុកលើអនិវាសនជន(សេវាគ្រប់គ្រង បច្ចេកទេស) | D12: =SUM(E12:DX12) | E12: 207619454 | F12: 231597516 | G12: 164328840 | H12: 156670200 | I12: 180754541 | J12: 195185980 | K12: 161418480 | L12: 202136820 | M12: 140587965 | N12: 137082553 | O12: 126668325 | P12: 161099177 | Q12: 128656437 | R12: 132602489 | S12: 130597950 | T12: 100014829 | U12: 641536432 | V12: 295198706 | W12: 168433377 | X12: 140806830 | Y12: 88582293 | Z12: 87810250 | AA12: 163811912 | AB12: 201210084 | AC12: 141891691 | AD12: 116179898 | AE12: 88435925 | AF12: 92427359 | AG12: 107646320 | AH12: 226923692 | AI12: 110640260 | AJ12: 133748826 | AK12: 87702375 | AL12: 101367779 | AM12: 87270875 | AN12: 87335600 | AO12: 115583812 | AP12: 87918125 | AQ12: 153154924 | AR12: 88194567 | AS12: 102553224 | AT12: 167148869 | AU12: 248493344 | AV12: 102564070 | AW12: 87723950 | AX12: 97615064 | AY12: 87378750 | AZ12: 140679420 | BA12: 118421089 | BB12: 88435925 | BC12: 88565375 | BD12: 88759550 | BE12: 89040025 | BF12: 185963897 | BG12: 158352202 | BH12: 107414077 | BI12: 91755533 | BJ12: 105714193 | BK12: 99001059 | BL12: 89686829 | BM12: 116811370 | BN12: 98702870 | BO12: 89104750 | BP12: 91355371
B13: 8 | C13: ពន្ធកាត់ទុកលើអនិវាសនជន (ភាគលាភ) | D13: =SUM(E13:DX13) | E13: - | F13: - | G13: - | H13: 814400000 | I13: 4910400000 | J13: - | K13: 8084000000 | L13: - | M13: - | N13: - | O13: - | P13: - | Q13: - | R13: 3257600000 | S13: - | T13: - | U13: - | V13: - | W13: - | X13: - | Y13: - | Z13: - | AA13: - | AB13: 2049500000 | AC13: - | AD13: - | AE13: - | AF13: - | AG13: - | AH13: - | AI13: - | AJ13: - | BI13: - | BJ13: 5660200000 | BK13: - | BL13: - | BM13: - | BN13: - | BO13: - | BP13: -
B14: 9 | C14: ពន្ធកាត់ទុកលើថ្លៃឈ្នួល (រូបវន្តបុគ្គល) | D14: =SUM(E14:DX14) | E14: 662809 | F14: 799652 | G14: 797686 | H14: 665096 | I14: 804766 | J14: 665586 | K14: 727564 | L14: 724504 | M14: 722164 | N14: 610109 | O14: 608739 | P14: 492838 | Q14: 1067824 | R14: 2465804 | S14: 838253 | T14: - | U14: 1681645 | V14: 835992 | W14: 834142 | X14: 835581 | Y14: 12338997 | Z14: 610496 | AA14: 610496 | AB14: 614846 | AC14: 617396 | AD14: 613946 | AE14: 560198 | AF14: 561018 | AG14: 560335 | AH14: 554868 | AI14: 553228 | AJ14: 552818 | AK14: 555551 | AL14: 556098 | AM14: 552818 | AN14: 553228 | AO14: 556508 | AP14: 556918 | AQ14: 556508 | AR14: 68001 | AS14: 67985 | AT14: 176135 | AU14: 357157 | AV14: 357595 | AW14: 356893 | AX14: 356893 | AY14: 355489 | AZ14: 355138 | BA14: 356542 | BB14: 359790 | BC14: 360316 | BD14: 361106 | BE14: 362247 | BF14: 363476 | BG14: 361809 | BH14: 327059 | BI14: 360229 | BJ14: 354874 | BK14: 355840 | BL14: 361194 | BM14: 361282 | BN14: 362511 | BO14: 362511 | BP14: 364969
B15: 10 | C15: ពន្ធកាត់ទុកលើថ្លៃឈ្នួល (នីតិបុគ្គល) | D15: =SUM(E15:DX15) | M15: 962880 | N15: 10701204 | O15: - | P15: - | Q15: - | R15: - | S15: - | T15: - | U15: - | V15: - | W15: - | X15: - | AW15: 0 | AX15: 0 | AY15: 0 | AZ15: 0 | BA15: 0 | BB15: 0 | BC15: 113363680 | BD15: 99632595 | BE15: 99279628 | BF15: 162936085 | BG15: 101020644 | BH15: 89882776
B16: 11 | C16: ពន្ធលើផ្ទាំងផ្សព្វផ្សាយ - ផ្ទាំងផ្សាយពាណិជ្ជកម្ម | D16: =SUM(E16:DX16) | E16: - | F16: - | G16: - | H16: - | I16: 1610000 | J16: - | K16: - | L16: - | M16: - | N16: - | O16: - | P16: - | Q16: - | R16: - | S16: 1867600 | T16: - | U16: - | V16: - | W16: - | X16: - | Y16: - | Z16: - | AA16: 1610000 | AB16: - | AC16: - | AD16: - | AE16: - | AF16: - | AG16: - | AH16: - | AI16: - | AJ16: - | AK16: - | AL16: - | AM16: 1610000 | AN16: - | AO16: - | AP16: - | AQ16: - | AR16: - | AS16: - | AT16: - | AU16: - | AV16: - | AW16: - | AX16: - | AY16: 1610000 | AZ16: - | BA16: - | BB16: - | BC16: - | BD16: - | BE16: - | BF16: - | BG16: - | BH16: - | BI16: - | BJ16: 1610000 | BK16: - | BL16: - | BM16: -
B17: 12 | C17: អាករលើតម្លៃបន្ថែម | D17: =SUM(E17:DX17) | BI17: 88543800 | BJ17: 96274341 | BK17: 87465050 | BL17: 89428055 | BM17: 425958232 | BN17: 95960550 | BO17: 89104750 | BP17: 89851145
B18: 12 | C18: ពន្ធពិន័យលើការយឺតយ៉ាវ | D18: =SUM(E18:DX18) | BI18: - | BJ18: - | BK18: - | BL18: - | BM18: 11766607 | BN18: - | BO18: -
B19: 13 | C19: កម្រៃសេវាចុះបញ្ជី ឬបច្ចុប្បន្នភាព | D19: =SUM(E19:DX19)
B20: 14 | C20: ពន្ធប៉ាតង់ | D20: =SUM(E20:DX20) | M20: - | N20: 5000000 | O20: - | P20: - | Q20: - | R20: - | S20: - | T20: - | U20: - | V20: - | W20: - | X20: - | Y20: - | Z20: 5000000 | AA20: - | AB20: - | AC20: - | AD20: - | AE20: - | AF20: - | AG20: - | AH20: - | AI20: - | AJ20: - | AK20: 5000000 | AL20: - | AM20: - | AN20: - | AO20: - | AP20: - | AQ20: - | AR20: - | AS20: - | AT20: - | AU20: - | AV20: - | AW20: 5000000 | AX20: - | AY20: - | AZ20: - | BA20: - | BB20: - | BC20: - | BD20: - | BE20: - | BF20: - | BG20: - | BH20: - | BI20: 5000000 | BJ20: - | BK20: - | BL20: - | BM20: - | BN20: - | BO20: - | BP20: -
C21: សរុបទឹកប្រាក់ពន្ធបានបង់ចូលរដ្ឋ | D21: =SUM(D6:D20)

Sheet Damco
A1: តារាងឧបសម្ព័ន្ឋ
A2: តារាងប្រៀធៀបវិក្ក័យប័ត្រស្នើសុំបង្វិលសងអាករលើតំលៃបន្ថែម ( Cross checking )
A3: ='Annex I-IM State Charge'!#REF!
A4: ='Annex I-IM State Charge'!#REF!
A5: ល.រ | B5: ក្រុមហ៊ុនស្នើសុំបង្វិលសង | E5: អ្នកផ្គត់ផ្គង់ | J5: ផ្សេងៗ
B6: វិក្កយបត្រ | E6: សហគ្រាស | F6: លេខអតប | G6: វិក្កយបត្រ
B7: លេខ | C7: ថ្ងៃទី ខែ ឆ្នាំ | D7: ប្រាក់អាករ | G7: លេខ | H7: ថ្ងៃទី ខែ ឆ្នាំ | I7: ប្រាក់អាករ
A8: 1 | B8: 030209 | C8: 41246 | D8: 58.25 | E8: A P L Logistics | F8: 100046460 | G8: 030209 | H8: 41246 | I8: 58.25 | J8: បានបង់
A9: 2 | B9: 030231 | C9: 41248 | D9: 4 | E9: A P L Logistics | F9: 100046460 | G9: 030231 | H9: 41248 | I9: 4 | J9: បានបង់
A10: 3 | B10: 030241 | C10: 41254 | D10: 49.75 | E10: A P L Logistics | F10: 100046460 | G10: 030241 | H10: 41254 | I10: 49.75 | J10: បានបង់
A11: 4 | B11: 030262 | C11: 41254 | D11: 181.79 | E11: A P L Logistics | F11: 100046460 | G11: 030262 | H11: 41254 | I11: 181.79 | J11: បានបង់
A12: 5 | B12: 030302 | C12: 41260 | D12: 46.69 | E12: A P L Logistics | F12: 100046460 | G12: 030302 | H12: 41260 | I12: 46.69 | J12: បានបង់
A13: 6 | B13: 030328 | C13: 41260 | D13: 236.64 | E13: A P L Logistics | F13: 100046460 | G13: 030328 | H13: 41260 | I13: 236.64 | J13: បានបង់
A14: 7 | B14: 030343 | C14: 41261 | D14: 4 | E14: A P L Logistics | F14: 100046460 | G14: 030343 | H14: 41261 | I14: 4 | J14: បានបង់
A15: 8 | B15: 030353 | C15: 41261 | D15: 10 | E15: A P L Logistics | F15: 100046460 | G15: 030353 | H15: 41261 | I15: 10 | J15: បានបង់
A16: 9 | B16: 030450 | C16: 41274 | D16: 87.52 | E16: A P L Logistics | F16: 100046460 | G16: 030450 | H16: 41274 | I16: 87.52 | J16: បានបង់
A17: 10 | B17: 030469 | C17: 41274 | D17: 39.29 | E17: A P L Logistics | F17: 100046460 | G17: 030469 | H17: 41274 | I17: 39.29 | J17: បានបង់
A18: Total 12/2012 | D18: =SUM(D8:D17) | H18: USD | I18: =SUM(I8:I17)
A19: Total 12/2012 | G19: 3995 | H19: RIEL | I19: =I18*G19
A20: 1 | B20: 029920 | C20: 41218 | D20: 77 | E20: A P L Logistics | F20: 100046460 | G20: 029920 | H20: 41218 | I20: 77 | J20: បានបង់
A21: 2 | B21: 029981 | C21: 41225 | D21: 115.89 | E21: A P L Logistics | F21: 100046460 | G21: 029981 | H21: 41225 | I21: 115.89 | J21: បានបង់
A22: 3 | B22: 030003 | C22: 41225 | D22: 82.91 | E22: A P L Logistics | F22: 100046460 | G22: 030003 | H22: 41225 | I22: 82.91 | J22: បានបង់
A23: 4 | B23: 030044 | C23: 41232 | D23: 55.32 | E23: A P L Logistics | F23: 100046460 | G23: 030044 | H23: 41232 | I23: 55.32 | J23: បានបង់
A24: 5 | B24: 030062 | C24: 41232 | D24: 32.03 | E24: A P L Logistics | F24: 100046460 | G24: 030062 | H24: 41232 | I24: 32.03 | J24: បានបង់
A25: Total 11/2012 | D25: =SUM(D20:D24) | H25: USD | I25: =SUM(I20:I24)
A26: Total 11/2012 | G26: 3999 | H26: RIEL | I26: =I25*G26
A27: 1 | B27: 029638 | C27: 41183 | D27: 89.93 | E27: A P L Logistics | F27: 100046460 | G27: 029638 | H27: 41183 | I27: 89.93 | J27: បានបង់
A28: 2 | B28: 029716 | C28: 41190 | D28: 49.63 | E28: A P L Logistics | F28: 100046460 | G28: 029716 | H28: 41190 | I28: 49.63 | J28: បានបង់
A29: 3 | B29: 029766 | C29: 41197 | D29: 115.81 | E29: A P L Logistics | F29: 100046460 | G29: 029766 | H29: 41197 | I29: 115.81 | J29: បានបង់
A30: 4 | B30: 029816 | C30: 41204 | D30: 101.98 | E30: A P L Logistics | F30: 100046460 | G30: 029816 | H30: 41204 | I30: 101.98 | J30: បានបង់
A31: 5 | B31: 029869 | C31: 41211 | D31: 67.28 | E31: A P L Logistics | F31: 100046460 | G31: 029869 | H31: 41211 | I31: 67.28 | J31: បានបង់
A32: Total 10/2012 | D32: =SUM(D27:D31) | H32: USD | I32: =SUM(I27:I31)
A33: Total 10/2012 | G33: 4028 | H33: RIEL | I33: =I32*G33
A34: 1 | B34: 029426 | C34: 41162 | D34: 206.96 | E34: A P L Logistics | F34: 100046460 | G34: 029426 | H34: 41162 | I34: 206.96 | J34: បានបង់
A35: 2 | B35: 029501 | C35: 41169 | D35: 69.7 | E35: A P L Logistics | F35: 100046460 | G35: 029501 | H35: 41169 | I35: 69.7 | J35: បានបង់
A36: 3 | B36: 029565 | C36: 41176 | D36: 46.66 | E36: A P L Logistics | F36: 100046460 | G36: 029565 | H36: 41176 | I36: 46.66 | J36: បានបង់
A37: Total 09/2012 | D37: =SUM(D34:D36) | H37: USD | I37: =SUM(I34:I36)
A38: Total 09/2012 | G38: 4044 | H38: RIEL | I38: =I37*G38
A39: 1 | B39: 029026 | C39: 41127 | D39: 37.84 | E39: A P L Logistics | F39: 100046460 | G39: 029026 | H39: 41127 | I39: 37.84 | J39: បានបង់
A40: 2 | B40: 029107 | C40: 41134 | D40: 95.46 | E40: A P L Logistics | F40: 100046460 | G40: 029107 | H40: 41134 | I40: 95.46 | J40: បានបង់
...

Sheet Chea Fat
A1: តារាងឧបសម្ព័ន្ឋ
A2: តារាងប្រៀធៀបវិក្ក័យប័ត្រស្នើសុំបង្វិលសងអាករលើតំលៃបន្ថែម ( Cross checking )
A3: នាមករណ៏សហគ្រាស : Maurea Garments Corp
A4: VAT TIN : 1 0 0 0 5 2 9 6 7
A5: ល.រ | B5: ក្រុមហ៊ុនស្នើសុំបង្វិលសង | E5: អ្នកផ្គត់ផ្គង់ | J5: ផ្សេងៗ
B6: វិក័យបត្រ័ | E6: សហគ្រាស | F6: លេខអតប | G6: វិក័យបត្រ័
B7: លេខ | C7: ថ្ងៃទី ខែ ឆ្នាំ | D7: ប្រាក់អាករ | G7: លេខ | H7: ថ្ងៃទី ខែ ឆ្នាំ | I7: ប្រាក់អាករ
A8: 1 | B8: 07-0360 | C8: 41842 | D8: 41.5 | E8: YUSEN LOGISTICS | F8: 104015799 | G8: 07-0360 | H8: 41842 | I8: 41.5
A9: 2 | B9: 07-0367 | C9: 41842 | D9: 64.57 | E9: YUSEN LOGISTICS | F9: 104015799 | G9: 07-0367 | H9: 41842 | I9: 64.57
A10: 3 | B10: 07-0368 | C10: 41842 | D10: 59.11 | E10: YUSEN LOGISTICS | F10: 104015799 | G10: 07-0368 | H10: 41842 | I10: 59.11
A11: 4 | B11: 07-0517 | C11: 41849 | D11: 75.93 | E11: YUSEN LOGISTICS | F11: 104015799 | G11: 07-0517 | H11: 41849 | I11: 75.93
A12: 5 | B12: 08-0039 | C12: 41856 | D12: 46.05 | E12: YUSEN LOGISTICS | F12: 104015799 | G12: 08-0039 | H12: 41856 | I12: 46.05
A13: 6 | B13: 08-0044 | C13: 41856 | D13: 41.5 | E13: YUSEN LOGISTICS | F13: 104015799 | G13: 08-0044 | H13: 41856 | I13: 41.5
A14: 7 | B14: 08-0185 | C14: 41864 | D14: 27.9 | E14: YUSEN LOGISTICS | F14: 104015799 | G14: 08-0185 | H14: 41864 | I14: 27.9
A15: 8 | B15: 08-0677 | C15: 41882 | D15: 143 | E15: YUSEN LOGISTICS | F15: 104015799 | G15: 08-0677 | H15: 41882 | I15: 143
A16: 9 | B16: 08-0685 | C16: 41882 | D16: 60.33 | E16: YUSEN LOGISTICS | F16: 104015799 | G16: 08-0685 | H16: 41882 | I16: 60.33
A17: 10 | B17: 09-0111 | C17: 41892 | D17: 27.53 | E17: YUSEN LOGISTICS | F17: 104015799 | G17: 09-0111 | H17: 41892 | I17: 27.53
A18: 11 | B18: 09-0117 | C18: 41892 | D18: 53.64 | E18: YUSEN LOGISTICS | F18: 104015799 | G18: 09-0117 | H18: 41892 | I18: 53.64
A19: 12 | B19: 09-0199 | C19: 41898 | D19: 34.77 | E19: YUSEN LOGISTICS | F19: 104015799 | G19: 09-0199 | H19: 41898 | I19: 34.77
... A40: 33 | B40: 502-0531 | C40: 42059 | D40: 102.92 | E40: YUSEN LOGISTICS | F40: 104015799 | G40: 502-0531 | H40: 42059 | I40: 102.92
A41: TOTAL 7/2012-02/2015 | D41: =SUM(D8:D40) | I41: =SUM(I8:I40)
E44: YUSEN LOGISTICS | F44: 104015799 | G44: 2-00309 | H44: 41619 | I44: 5

Sheet S G L CAMBODIA
A1: តារាងឧបសម្ព័ន្ឋ
A2: តារាងប្រៀធៀបវិក្ក័យប័ត្រស្នើសុំបង្វិលសងអាករលើតំលៃបន្ថែម ( Cross checking )
A3: នាមករណ៏សហគ្រាស : Maurea Garments Corp
A4: VAT TIN : 1 0 0 0 5 2 9 6 7
A5: ល.រ | B5: ក្រុមហ៊ុនស្នើសុំបង្វិលសង | E5: អ្នកផ្គត់ផ្គង់ | J5: ផ្សេងៗ
B6: វិក័យបត្រ័ | E6: សហគ្រាស | F6: លេខអតប | G6: វិក័យបត្រ័
B7: លេខ | C7: ថ្ងៃទី ខែ ឆ្នាំ | D7: ប្រាក់អាករ | G7: លេខ | H7: ថ្ងៃទី ខែ ឆ្នាំ | I7: ប្រាក់អាករ
A8: 1 | B8: 227231 | C8: 41246 | D8: 8.5 | E8: S G L CAMBODIA | F8: 100119816 | G8: 227231 | H8: 41246 | I8: 8.5
A9: 2 | B9: 227288 | C9: 41246 | D9: 52.36 | E9: S G L CAMBODIA | F9: 100119816 | G9: 227288 | H9: 41246 | I9: 52.36
A10: 3 | B10: 227430 | C10: 41255 | D10: 21.2 | E10: S G L CAMBODIA | F10: 100119816 | G10: 227430 | H10: 41255 | I10: 21.2
A11: 4 | B11: 227461 | C11: 41255 | D11: 29.57 | E11: S G L CAMBODIA | F11: 100119816 | G11: 227461 | H11: 41255 | I11: 29.57
A12: 5 | B12: 227539 | C12: 41260 | D12: 34.24 | E12: S G L CAMBODIA | F12: 100119816 | G12: 227539 | H12: 41260 | I12: 34.24
A13: 6 | B13: 227543 | C13: 41260 | D13: 8.93 | E13: S G L CAMBODIA | F13: 100119816 | G13: 227543 | H13: 41260 | I13: 8.93
A14: 7 | B14: 227552 | C14: 41260 | D14: 27.62 | E14: S G L CAMBODIA | F14: 100119816 | G14: 227552 | H14: 41260 | I14: 27.62
A15: 8 | B15: 227583 | C15: 41261 | D15: 57.77 | E15: S G L CAMBODIA | F15: 100119816 | G15: 227583 | H15: 41261 | I15: 57.77
A16: 9 | B16: 227586 | C16: 41261 | D16: 24 | E16: S G L CAMBODIA | F16: 100119816 | G16: 227586 | H16: 41261 | I16: 24
A17: 10 | B17: 227605 | C17: 41261 | D17: 28.88 | E17: S G L CAMBODIA | F17: 100119816 | G17: 227605 | H17: 41261 | I17: 28.88
A18: 11 | B18: 227826 | C18: 41274 | D18: 24 | E18: S G L CAMBODIA | F18: 100119816 | G18: 227826 | H18: 41274 | I18: 24
A19: 12 | B19: 227862 | C19: 41274 | D19: 36.26 | E19: S G L CAMBODIA | F19: 100119816 | G19: 227862 | H19: 41274 | I19: 36.26
... A458: 455 | B458: 443954 | C458: 42002 | D458: 44.24 | E458: S G L CAMBODIA | F458: 100119816 | G458: 443954 | H458: 42002 | I458: 44.24
A459: TOTAL 7/2012-02/2015 | D459: =SUM(D8:D458) | I459: =SUM(I8:I458)

Sheet Sheet3
A1: តារាងឧបសម្ព័ន្ឋ
A2: តារាងប្រៀធៀបវិក្ក័យប័ត្រស្នើសុំបង្វិលសងអាករលើតំលៃបន្ថែម ( Cross checking )
A3: នាមករណ៏សហគ្រាស : Maurea Garments Corp
A4: VAT TIN : 1 0 0 0 5 2 9 6 7
A5: ល.រ | B5: ក្រុមហ៊ុនស្នើសុំបង្វិលសង | E5: អ្នកផ្គត់ផ្គង់ | J5: ផ្សេងៗ
B6: វិក័យបត្រ័ | E6: សហគ្រាស | F6: លេខអតប | G6: វិក័យបត្រ័
B7: លេខ | C7: ថ្ងៃទី ខែ ឆ្នាំ | D7: ប្រាក់អាករ | G7: លេខ | H7: ថ្ងៃទី ខែ ឆ្នាំ | I7: ប្រាក់អាករ

Sheet Sale - June
A1: សៀវភៅទិនានុប្បវត្តិលក់- នាំចេញ
A2: ខែ​​ មិថុនា ឆ្នាំ ២០១៥
A3: ជី អេវើរហ្រ្គីន( ខេមបូឌា​ ) នីតធីង | K3: Vat:100193102
A4: ភូមិជ្រៃកោង សង្កាត់ចោមចៅ ខណ្ឌ ពោធិសែនជ័យ ក្រុង ភ្នំពេញ | K4: Average: | L4: 4088
A5: វិក្ក័យប័ត្រ | I5: ការផ្គត់ផ្គង់
A6: កាលបរិចេ្ឆទ | B6: វិក្ក័យប័ត្រ | C6: អ្នកទិញ | D6: លេខ អតប | E6: បរិយាយ | F6: បរិមាណ | I6: karlk;Cab;Gakr | M6: សរុបថ្លៃទិញ
D7: TIN | G7: ការផ្គត់ផ្គង់ | H7: ការនាំចេញ | I7: lk;;»übuKþlCab;Gakr | K7: lk;;»üGñkeRbIR)as; | M7: រួមទាំអាករ
G8: មិនជាប់អាករ | H8: អត្រា​​ 0 % | I8: តំលៃជាប់អាករ | J8: អាករ | K8: តំលៃជាប់អាករ | L8: អាករ
A9: 42160 | B9: E 55119 | C9: LPP S.A | E9: Men's Top | F9: 137 CT | H9: 41519138 | M9: =G9+H9
A10: 42160 | B10: E 53624 | C10: PRIMARK | E10: See Val Note | F10: 655 CT | H10: 157610622 | M10: =G10+H10
A11: 42160 | B11: E 9812 | C11: SMYK SP Z.O.O | E11: Girls Knitted Dress | F11: 518 CT | H11: 75926121 | M11: =G11+H11
A12: 42164 | B12: E 10122 | C12: SMYK SP Z.O.O | E12: Girls Knitted Sweat Shirt | F12: 404 CT | H12: 109260590 | M12: =G12+H12
A13: 42167 | B13: E 57854 | C13: PRIMARK | E13: Men's Long Sleeve Hoodie | F13: 550 CT | H13: 136860570 | M13: =G13+H13
A14: 42167 | B14: E 57078 | C14: LPP S.A | E14: Men's Top | F14: 1094 CT | H14: 189450332 | M14: =G14+H14
A15: 42174 | B15: E 60607 | C15: CAPRI SRL | E15: Men's Hoody | F15: 827 CT | H15: 267888456 | M15: =G15+H15
A16: 42174 | B16: E 59730 | C16: LPP S.A | E16: Men's Jogging Top | F16: 815 CT | H16: 233561904 | M16: =G16+H16
A17: 42174 | B17: E 60079 | C17: LPP S.A | E17: Men's Sweater +Top | F17: 400 CT | H17: 106100285 | M17: =G17+H17
A18: 42175 | B18: E 61426 | C18: VISAGE LIMITED | E18: Men's Pari / Monica / Leyton Crew | F18: 556 CT | H18: 145296432 | M18: =G18+H18
A19: 42175 | B19: E 61432 | C19: PRIMARK STORES LIMITED | E19: See Val Note | F19: 1220 CT | H19: 299682480 | M19: =G19+H19
A20: 42181 | B20: E 63424 | C20: PRIMARK US CORP | E20: Men Chest Print Zip | F20: 37 CT | H20: 6493691 | M20: =G20+H20
... A22: 42181 | B22: E 63568 | C22: VISAGE LIMITED | E22: Men's Morgan Crew + Connect Crew+ Leyton | F22: 338 CT | H22: 94840834 | M22: =G22+H22
A23: =L4 | E23: Riel | F23: =SUM(F9:F22) | H23: =SUM(H9:H22) | M23: =SUM(M9:M22)
A24: Total USD | E24: USD | G24: =G23/L4 | H24: =H23/L4 | I24: =I23*4034 | J24: =J23*4034 | K24: =K23*4034 | L24: =L23*4034 | M24: =M23/L4
G25: Box 12 | H25: Box 13 | I25: Box 14 | J25: Box 15 | K25: Box 14 | L25: Box 15
H26: Approved By :
N27: =H23*1%
H28: =H24*1%
G29: Sales
G30: July | H30: ='Sale - Jul'!H30 | I30: 21 invoices
G31: Aug | H31: ='Sale - Aug'!I47 | I31: 38 invoices
G32: June | H32: =H23 | I32: 14 invoices
G33: Total: | H33: =SUM(H30:H32) | I33: =14+38+21
H37: =H24*1%

Sheet Sale - Jul
A1: សៀវភៅទិនានុប្បវត្តិលក់- នាំចេញ
A2: ខែ​​ កក្កដា ឆ្នាំ ២០១៥
A3: ជី អេវើរហ្រ្គីន( ខេមបូឌា​ ) នីតធីង | K3: Vat:100193102
A4: ភូមិជ្រៃកោង សង្កាត់ចោមចៅ ខណ្ឌ ពោធិសែនជ័យ ក្រុង ភ្នំពេញ | K4: Average: | L4: 4099
A5: វិក្ក័យប័ត្រ | I5: ការផ្គត់ផ្គង់
A6: កាលបរិចេ្ឆទ | B6: វិក្ក័យប័ត្រ | C6: អ្នកទិញ | D6: លេខ អតប | E6: បរិយាយ | F6: បរិមាណ | I6: karlk;Cab;Gakr | M6: សរុបថ្លៃទិញ
D7: TIN | G7: ការផ្គត់ផ្គង់ | H7: ការនាំចេញ | I7: lk;;»übuKþlCab;Gakr | K7: lk;;»üGñkeRbIR)as; | M7: រួមទាំអាករ
G8: មិនជាប់អាករ | H8: អត្រា​​ 0 % | I8: តំលៃជាប់អាករ | J8: អាករ | K8: តំលៃជាប់អាករ | L8: អាករ
A9: 42188 | B9: E 65884 | C9: LPP S.A | E9: Men's Jogging Top | F9: 1841 CT | H9: 469164366 | M9: =G9+H9
A10: 42188 | B10: E 65884 | C10: LPP S.A | E10: Men's Knit Trousers | F10: 631 CT | H10: 224637197 | M10: =G10+H10
A11: 42188 | B11: E 65484 | C11: Primark Tiendas Slu | E11: Men's Zip Thru Hoody | F11: 343 CT | H11: 88553682 | M11: =G11+H11
A12: 42189 | B12: E 67494 | C12: PRIMARK | E12: Men's Long Sleeve Zip Thru Hoodie | F12: 1093 CT | H12: 282184182 | M12: =G12+H12
A13: 42194 | B13: E 68109 | C13: PRIMARK STORES LIMITED | E13: 7B (Boy) Core Hoody | F13: 600 CT | H13: 137692800 | M13: =G13+H13
A14: 42194 | B14: E 68146 | C14: PRIMARK | E14: Men's Zip Thru Hoody | F14: 772 CT | H14: 199310328 | M14: =G14+H14
A15: 42195 | B15: E 69396 | C15: LPP S.A | E15: Men's Knit Sweater + Jogging Top | F15: 1133 CT | H15: 222232983 | M15: =G15+H15
A16: 42195 | B16: E 69396 | C16: LPP S.A | E16: Men's Knit Trousers | F16: 39 CT | H16: 15787217 | M16: =G16+H16
A17: 42195 | B17: E 69549 | C17: PRIMARK STORES LIMITED | E17: Men + Boy Hoodies | F17: 638 CT | H17: 147298512 | M17: =G17+H17
A18: 42196 | B18: E 70637 | C18: LPP S.A | E18: Ladies Jogging Top | F18: 490 CT | H18: 108300780 | M18: =G18+H18
A19: 42196 | B19: E 70637 | C19: LPP S.A | E19: Men's Knit Trousers | F19: 99 CT | H19: 39649873 | M19: =G19+H19
A20: 42196 | B20: E 70627 | C20: Primark Tiendas Slu | E20: Men's Zip Thru Hoody | F20: 2066 CT | H20: 532736694 | M20: =G20+H20
... A29: 42203 | B29: E 73524 | C29: VDR FASHION GROUP BV | E29: Ladies Knitted Blazer | F29: 191 CT | H29: 114575606 | M29: =G29+H29
A30: =L4 | E30: Riel | F30: =SUM(F9:F29) | H30: =SUM(H9:H29) | M30: =SUM(M9:M29)
A31: Total USD | E31: USD | G31: =G30/L4 | H31: =H30/L4 | I31: =I30*4034 | J31: =J30*4034 | K31: =K30*4034 | L31: =L30*4034 | M31: =M30/L4
G32: Box 12 | H32: Box 13 | I32: Box 14 | J32: Box 15 | K32: Box 14 | L32: Box 15
H33: Approved By :
H35: =H31*1%
H44: =H31*1%

Sheet Sale - Aug
A1: សៀវភៅទិនានុប្បវត្តិលក់- នាំចេញ
A2: ខែ​​ សីហា ឆ្នាំ ២០១៥
A3: ជី អេវើរហ្រ្គីន( ខេមបូឌា​ ) នីតធីង | L3: Vat:100193102
A4: ភូមិជ្រៃកោង សង្កាត់ចោមចៅ ខណ្ឌ ពោធិសែនជ័យ ក្រុង ភ្នំពេញ | L4: Average: | M4: 4095
A5: វិក្ក័យប័ត្រ | J5: ការផ្គត់ផ្គង់
A6: កាលបរិចេ្ឆទ | B6: វិក្ក័យប័ត្រ | C6: អ្នកទិញ | D6: លេខ អតប | E6: បរិយាយ | F6: បរិមាណ | J6: karlk;Cab;Gakr | N6: សរុបថ្លៃទិញ
D7: TIN | F7: ការផ្គត់ផ្គង់ | I7: ការនាំចេញ | J7: lk;;»übuKþlCab;Gakr | L7: lk;;»üGñkeRbIR)as; | N7: រួមទាំអាករ
F8: មិនជាប់អាករ | I8: អត្រា​​ 0 % | J8: តំលៃជាប់អាករ | K8: អាករ | L8: តំលៃជាប់អាករ | M8: អាករ
A9: 42202 | B9: E 72202 | C9: Primark Us Corp | E9: Men Zip Thru Hoody | F9: 65 | G9: CT | I9: 16764930 | N9: =H9+I9
A10: 42203 | B10: E 13027 | C10: LPP S.A | E10: Ladies Knit Jogging Top | F10: 64 | G10: CT | I10: 26424115 | N10: =H10+I10
A11: 42208 | B11: E 13359 | C11: VDR Fashion Group BV | E11: Ladies Knit Shirt | F11: 36 | G11: CT | I11: 29192000 | N11: =H11+I11
A12: 42209 | B12: E 74804 | C12: Primark Us Corp | E12: Boy Hoody | F12: 305 | G12: CT | I12: 70028000 | N12: =H12+I12
A13: 42209 | B13: E 74578 | C13: LPP S.A | E13: Men's Jogging Top | F13: 904 | G13: CT | I13: 242980473 | N13: =H13+I13
A14: 42210 | B14: E 76431 | C14: Primark | E14: Men Zip Thru Hoody | F14: 700 | G14: CT | I14: 180986400 | N14: =H14+I14
A15: 42210 | B15: E 76547 | C15: Primark Stores Limited | E15: 7/2Boy Core Hoody | F15: 800 | G15: CT | I15: 174420000 | N15: =H15+I15
A16: 42210 | B16: E 65557 | C16: LPP S.A | E16: Ladies Jogging Top | F16: 680 | G16: CT | I16: 178829338 | N16: =H16+I16
A17: 42210 | B17: E 65557 | C17: LPP S.A | E17: Men's Knit Trousers | F17: 93 | G17: CT | I17: 36022203 | N17: =H17+I17
A18: 42215 | B18: E 76966 | C18: Primark | E18: See Val Note | F18: 355 | G18: CT | I18: 89531330 | N18: =H18+I18
A19: 42215 | B19: E 76966 | C19: Primark | E19: Ladies Nylon Zip Back Fl Legging | F19: 267 | G19: CT | I19: 191743220 | N19: =H19+I19
A20: 42216 | B20: E 78298 | C20: Primark Us Corp | E20: Mens Hoody | F20: 70 | G20: CT | I20: 18116280 | N20: =H20+I20
... A41: 42237 | B41: E 87246 | C41: Primark Stores Limited | E41: Boy's Hoody | F41: 200 | G41: CT | I41: 41197900 | N41: =H41+I41
A42: 42237 | B42: E 87199 | C42: Primakr Tiendas S.l.u. | E42: Men's Knit Chest Print Zip Thru | F42: 250 | G42: CT | I42: =15750*4079 | N42: =H42+I42
A43: 42237 | B43: E 87074 | C43: Primark 47 Mary Street Dublin1. | E43: Men's Knit Chest Print Zip Thru | F43: 192 | G43: CT | I43: 49339584 | N43: =H43+I43
A44: 42237 | B44: E 86097 | C44: Primark Stores Limited | E44: See Val Note | F44: 756 | G44: CT | I44: 178378749 | N44: =H44+I44
A45: 42237 | B45: E 86347 | C45: LPP S.A | E45: Men's Jogging Top | F45: 725 | G45: CT | I45: 162100480 | N45: =H45+I45
A46: 42237 | B46: E 86347 | C46: LPP S.A | E46: Men's Knit Trousers | F46: 531 | G46: CT | I46: 203679970 | N46: =H46+I46
A47: =M4 | E47: Riel | I47: =SUM(I9:I46) | N47: =SUM(N9:N46)
A48: Total USD | E48: USD | H48: =H47/M4 | I48: =I47/M4 | J48: =J47*4034 | K48: =K47*4034 | L48: =L47*4034 | M48: =M47*4034 | N48: =N47/M4
H49: Box 12 | J49: Box 14 | K49: Box 15 | L49: Box 14 | M49: Box 15
I50: Approved By :
I52: =I48*1%
I61: =I48*1%
